LAST SEEN   TYPE      REASON                   OBJECT                                                       MESSAGE
52m         Warning   FailedScheduling         pod/fio-smallfile-lifecycle-7                                0/3 nodes are available: pod has unbound immediate PersistentVolumeClaims. not found
52m         Normal    Scheduled                pod/fio-smallfile-lifecycle-3                                Successfully assigned fio-tests/fio-smallfile-lifecycle-3 to s1
95m         Normal    Scheduled                pod/fio-low-qd-latency-0                                     Successfully assigned fio-tests/fio-low-qd-latency-0 to s1
13m         Normal    Scheduled                pod/fio-test2-10pods-30k-5050-32kb-9                         Successfully assigned fio-tests/fio-test2-10pods-30k-5050-32kb-9 to s3
13m         Warning   FailedScheduling         pod/fio-test2-10pods-30k-5050-32kb-9                         0/3 nodes are available: pod has unbound immediate PersistentVolumeClaims. not found
14m         Warning   FailedScheduling         pod/fio-test2-10pods-30k-5050-32kb-9                         0/3 nodes are available: pod has unbound immediate PersistentVolumeClaims. not found
14m         Normal    Scheduled                pod/fio-test2-10pods-30k-5050-32kb-8                         Successfully assigned fio-tests/fio-test2-10pods-30k-5050-32kb-8 to s1
14m         Warning   FailedScheduling         pod/fio-test2-10pods-30k-5050-32kb-8                         0/3 nodes are available: pod has unbound immediate PersistentVolumeClaims. not found
97m         Warning   FailedScheduling         pod/fio-low-qd-latency-1                                     0/3 nodes are available: pod has unbound immediate PersistentVolumeClaims. not found
96m         Warning   FailedScheduling         pod/fio-low-qd-latency-1                                     0/3 nodes are available: pod has unbound immediate PersistentVolumeClaims. not found
96m         Normal    Scheduled                pod/fio-low-qd-latency-1                                     Successfully assigned fio-tests/fio-low-qd-latency-1 to s1
14m         Warning   FailedScheduling         pod/fio-test2-10pods-30k-5050-32kb-8                         0/3 nodes are available: pod has unbound immediate PersistentVolumeClaims. not found
97m         Warning   FailedScheduling         pod/fio-low-qd-latency-0                                     0/3 nodes are available: pod has unbound immediate PersistentVolumeClaims. not found
14m         Normal    Scheduled                pod/fio-test2-10pods-30k-5050-32kb-7                         Successfully assigned fio-tests/fio-test2-10pods-30k-5050-32kb-7 to s2
14m         Warning   FailedScheduling         pod/fio-test2-10pods-30k-5050-32kb-7                         0/3 nodes are available: pod has unbound immediate PersistentVolumeClaims. not found
14m         Warning   FailedScheduling         pod/fio-test2-10pods-30k-5050-32kb-7                         0/3 nodes are available: pod has unbound immediate PersistentVolumeClaims. not found
97m         Warning   FailedScheduling         pod/fio-low-qd-latency-2                                     0/3 nodes are available: pod has unbound immediate PersistentVolumeClaims. not found
96m         Warning   FailedScheduling         pod/fio-low-qd-latency-2                                     0/3 nodes are available: pod has unbound immediate PersistentVolumeClaims. not found
96m         Normal    Scheduled                pod/fio-low-qd-latency-2                                     Successfully assigned fio-tests/fio-low-qd-latency-2 to s3
14m         Normal    Scheduled                pod/fio-test2-10pods-30k-5050-32kb-6                         Successfully assigned fio-tests/fio-test2-10pods-30k-5050-32kb-6 to s1
14m         Warning   FailedScheduling         pod/fio-test2-10pods-30k-5050-32kb-6                         0/3 nodes are available: pod has unbound immediate PersistentVolumeClaims. not found
14m         Warning   FailedScheduling         pod/fio-test2-10pods-30k-5050-32kb-6                         0/3 nodes are available: pod has unbound immediate PersistentVolumeClaims. not found
14m         Normal    Scheduled                pod/fio-test2-10pods-30k-5050-32kb-5                         Successfully assigned fio-tests/fio-test2-10pods-30k-5050-32kb-5 to s3
14m         Warning   FailedScheduling         pod/fio-test2-10pods-30k-5050-32kb-5                         0/3 nodes are available: pod has unbound immediate PersistentVolumeClaims. not found
97m         Warning   FailedScheduling         pod/fio-low-qd-latency-3                                     0/3 nodes are available: pod has unbound immediate PersistentVolumeClaims. not found
96m         Warning   FailedScheduling         pod/fio-low-qd-latency-3                                     0/3 nodes are available: pod has unbound immediate PersistentVolumeClaims. not found
96m         Normal    Scheduled                pod/fio-low-qd-latency-3                                     Successfully assigned fio-tests/fio-low-qd-latency-3 to s1
52m         Normal    Scheduled                pod/fio-smallfile-lifecycle-7                                Successfully assigned fio-tests/fio-smallfile-lifecycle-7 to s3
14m         Normal    Scheduled                pod/fio-test2-10pods-30k-5050-32kb-4                         Successfully assigned fio-tests/fio-test2-10pods-30k-5050-32kb-4 to s2
14m         Warning   FailedScheduling         pod/fio-test2-10pods-30k-5050-32kb-4                         0/3 nodes are available: pod has unbound immediate PersistentVolumeClaims. not found
14m         Warning   FailedScheduling         pod/fio-test2-10pods-30k-5050-32kb-4                         0/3 nodes are available: pod has unbound immediate PersistentVolumeClaims. not found
14m         Normal    Scheduled                pod/fio-test2-10pods-30k-5050-32kb-3                         Successfully assigned fio-tests/fio-test2-10pods-30k-5050-32kb-3 to s2
97m         Warning   FailedScheduling         pod/fio-low-qd-latency-4                                     0/3 nodes are available: pod has unbound immediate PersistentVolumeClaims. not found
96m         Warning   FailedScheduling         pod/fio-low-qd-latency-4                                     0/3 nodes are available: pod has unbound immediate PersistentVolumeClaims. not found
96m         Normal    Scheduled                pod/fio-low-qd-latency-4                                     Successfully assigned fio-tests/fio-low-qd-latency-4 to s3
14m         Warning   FailedScheduling         pod/fio-test2-10pods-30k-5050-32kb-3                         0/3 nodes are available: pod has unbound immediate PersistentVolumeClaims. not found
14m         Warning   FailedScheduling         pod/fio-test2-10pods-30k-5050-32kb-3                         0/3 nodes are available: pod has unbound immediate PersistentVolumeClaims. not found
14m         Normal    Scheduled                pod/fio-test2-10pods-30k-5050-32kb-2                         Successfully assigned fio-tests/fio-test2-10pods-30k-5050-32kb-2 to s1
14m         Warning   FailedScheduling         pod/fio-test2-10pods-30k-5050-32kb-2                         0/3 nodes are available: pod has unbound immediate PersistentVolumeClaims. not found
14m         Warning   FailedScheduling         pod/fio-test2-10pods-30k-5050-32kb-2                         0/3 nodes are available: pod has unbound immediate PersistentVolumeClaims. not found
97m         Warning   FailedScheduling         pod/fio-low-qd-latency-5                                     0/3 nodes are available: pod has unbound immediate PersistentVolumeClaims. not found
96m         Warning   FailedScheduling         pod/fio-low-qd-latency-5                                     0/3 nodes are available: pod has unbound immediate PersistentVolumeClaims. not found
96m         Normal    Scheduled                pod/fio-low-qd-latency-5                                     Successfully assigned fio-tests/fio-low-qd-latency-5 to s1
13m         Normal    Scheduled                pod/fio-test2-10pods-30k-5050-32kb-1                         Successfully assigned fio-tests/fio-test2-10pods-30k-5050-32kb-1 to s1
13m         Warning   FailedScheduling         pod/fio-test2-10pods-30k-5050-32kb-1                         0/3 nodes are available: pod has unbound immediate PersistentVolumeClaims. not found
14m         Warning   FailedScheduling         pod/fio-test2-10pods-30k-5050-32kb-1                         0/3 nodes are available: pod has unbound immediate PersistentVolumeClaims. not found
14m         Normal    Scheduled                pod/fio-test2-10pods-30k-5050-32kb-0                         Successfully assigned fio-tests/fio-test2-10pods-30k-5050-32kb-0 to s3
14m         Warning   FailedScheduling         pod/fio-test2-10pods-30k-5050-32kb-0                         0/3 nodes are available: pod has unbound immediate PersistentVolumeClaims. not found
97m         Warning   FailedScheduling         pod/fio-low-qd-latency-6                                     0/3 nodes are available: pod has unbound immediate PersistentVolumeClaims. not found
96m         Warning   FailedScheduling         pod/fio-low-qd-latency-6                                     0/3 nodes are available: pod has unbound immediate PersistentVolumeClaims. not found
96m         Normal    Scheduled                pod/fio-low-qd-latency-6                                     Successfully assigned fio-tests/fio-low-qd-latency-6 to s2
14m         Warning   FailedScheduling         pod/fio-test2-10pods-30k-5050-32kb-0                         0/3 nodes are available: pod has unbound immediate PersistentVolumeClaims. not found
68m         Normal    Scheduled                pod/fio-sync-write-9                                         Successfully assigned fio-tests/fio-sync-write-9 to s1
68m         Warning   FailedScheduling         pod/fio-sync-write-9                                         0/3 nodes are available: pod has unbound immediate PersistentVolumeClaims. not found
68m         Warning   FailedScheduling         pod/fio-sync-write-9                                         0/3 nodes are available: pod has unbound immediate PersistentVolumeClaims. not found
66m         Normal    Scheduled                pod/fio-sync-write-8                                         Successfully assigned fio-tests/fio-sync-write-8 to s3
97m         Warning   FailedScheduling         pod/fio-low-qd-latency-7                                     0/3 nodes are available: pod has unbound immediate PersistentVolumeClaims. not found
96m         Warning   FailedScheduling         pod/fio-low-qd-latency-7                                     0/3 nodes are available: pod has unbound immediate PersistentVolumeClaims. not found
96m         Normal    Scheduled                pod/fio-low-qd-latency-7                                     Successfully assigned fio-tests/fio-low-qd-latency-7 to s2
66m         Warning   FailedScheduling         pod/fio-sync-write-8                                         0/3 nodes are available: pod has unbound immediate PersistentVolumeClaims. not found
68m         Warning   FailedScheduling         pod/fio-sync-write-8                                         0/3 nodes are available: pod has unbound immediate PersistentVolumeClaims. not found
67m         Normal    Scheduled                pod/fio-sync-write-7                                         Successfully assigned fio-tests/fio-sync-write-7 to s3
67m         Warning   FailedScheduling         pod/fio-sync-write-7                                         0/3 nodes are available: pod has unbound immediate PersistentVolumeClaims. not found
68m         Warning   FailedScheduling         pod/fio-sync-write-7                                         0/3 nodes are available: pod has unbound immediate PersistentVolumeClaims. not found
97m         Warning   FailedScheduling         pod/fio-low-qd-latency-8                                     0/3 nodes are available: pod has unbound immediate PersistentVolumeClaims. not found
96m         Warning   FailedScheduling         pod/fio-low-qd-latency-8                                     0/3 nodes are available: pod has unbound immediate PersistentVolumeClaims. not found
96m         Normal    Scheduled                pod/fio-low-qd-latency-8                                     Successfully assigned fio-tests/fio-low-qd-latency-8 to s3
67m         Normal    Scheduled                pod/fio-sync-write-6                                         Successfully assigned fio-tests/fio-sync-write-6 to s2
67m         Warning   FailedScheduling         pod/fio-sync-write-6                                         0/3 nodes are available: pod has unbound immediate PersistentVolumeClaims. not found
68m         Warning   FailedScheduling         pod/fio-sync-write-6                                         0/3 nodes are available: pod has unbound immediate PersistentVolumeClaims. not found
67m         Normal    Scheduled                pod/fio-sync-write-5                                         Successfully assigned fio-tests/fio-sync-write-5 to s2
67m         Warning   FailedScheduling         pod/fio-sync-write-5                                         0/3 nodes are available: pod has unbound immediate PersistentVolumeClaims. not found
97m         Warning   FailedScheduling         pod/fio-low-qd-latency-9                                     0/3 nodes are available: pod has unbound immediate PersistentVolumeClaims. not found
96m         Warning   FailedScheduling         pod/fio-low-qd-latency-9                                     0/3 nodes are available: pod has unbound immediate PersistentVolumeClaims. not found
96m         Normal    Scheduled                pod/fio-low-qd-latency-9                                     Successfully assigned fio-tests/fio-low-qd-latency-9 to s2
68m         Warning   FailedScheduling         pod/fio-sync-write-5                                         0/3 nodes are available: pod has unbound immediate PersistentVolumeClaims. not found
66m         Normal    Scheduled                pod/fio-sync-write-4                                         Successfully assigned fio-tests/fio-sync-write-4 to s1
66m         Warning   FailedScheduling         pod/fio-sync-write-4                                         0/3 nodes are available: pod has unbound immediate PersistentVolumeClaims. not found
68m         Warning   FailedScheduling         pod/fio-sync-write-4                                         0/3 nodes are available: pod has unbound immediate PersistentVolumeClaims. not found
67m         Normal    Scheduled                pod/fio-sync-write-3                                         Successfully assigned fio-tests/fio-sync-write-3 to s3
67m         Warning   FailedScheduling         pod/fio-sync-write-3                                         0/3 nodes are available: pod has unbound immediate PersistentVolumeClaims. not found
68m         Warning   FailedScheduling         pod/fio-sync-write-3                                         0/3 nodes are available: pod has unbound immediate PersistentVolumeClaims. not found
67m         Normal    Scheduled                pod/fio-sync-write-2                                         Successfully assigned fio-tests/fio-sync-write-2 to s1
67m         Warning   FailedScheduling         pod/fio-sync-write-2                                         0/3 nodes are available: pod has unbound immediate PersistentVolumeClaims. not found
68m         Warning   FailedScheduling         pod/fio-sync-write-2                                         0/3 nodes are available: pod has unbound immediate PersistentVolumeClaims. not found
67m         Normal    Scheduled                pod/fio-sync-write-1                                         Successfully assigned fio-tests/fio-sync-write-1 to s2
67m         Warning   FailedScheduling         pod/fio-sync-write-1                                         0/3 nodes are available: pod has unbound immediate PersistentVolumeClaims. not found
68m         Warning   FailedScheduling         pod/fio-sync-write-1                                         0/3 nodes are available: pod has unbound immediate PersistentVolumeClaims. not found
67m         Normal    Scheduled                pod/fio-sync-write-0                                         Successfully assigned fio-tests/fio-sync-write-0 to s1
67m         Warning   FailedScheduling         pod/fio-sync-write-0                                         0/3 nodes are available: pod has unbound immediate PersistentVolumeClaims. not found
68m         Warning   FailedScheduling         pod/fio-sync-write-0                                         0/3 nodes are available: pod has unbound immediate PersistentVolumeClaims. not found
52m         Normal    Scheduled                pod/fio-smallfile-lifecycle-9                                Successfully assigned fio-tests/fio-smallfile-lifecycle-9 to s3
52m         Warning   FailedScheduling         pod/fio-smallfile-lifecycle-9                                0/3 nodes are available: pod has unbound immediate PersistentVolumeClaims. not found
53m         Warning   FailedScheduling         pod/fio-smallfile-lifecycle-9                                0/3 nodes are available: pod has unbound immediate PersistentVolumeClaims. not found
52m         Normal    Scheduled                pod/fio-smallfile-lifecycle-8                                Successfully assigned fio-tests/fio-smallfile-lifecycle-8 to s2
52m         Warning   FailedScheduling         pod/fio-smallfile-lifecycle-8                                0/3 nodes are available: pod has unbound immediate PersistentVolumeClaims. not found
53m         Warning   FailedScheduling         pod/fio-smallfile-lifecycle-8                                0/3 nodes are available: pod has unbound immediate PersistentVolumeClaims. not found
95m         Warning   FailedScheduling         pod/fio-low-qd-latency-0                                     0/3 nodes are available: pod has unbound immediate PersistentVolumeClaims. not found
14m         Warning   FailedScheduling         pod/fio-test2-10pods-30k-5050-32kb-5                         0/3 nodes are available: pod has unbound immediate PersistentVolumeClaims. not found
53m         Warning   FailedScheduling         pod/fio-smallfile-lifecycle-7                                0/3 nodes are available: pod has unbound immediate PersistentVolumeClaims. not found
52m         Normal    Scheduled                pod/fio-smallfile-lifecycle-6                                Successfully assigned fio-tests/fio-smallfile-lifecycle-6 to s2
52m         Warning   FailedScheduling         pod/fio-smallfile-lifecycle-6                                0/3 nodes are available: pod has unbound immediate PersistentVolumeClaims. not found
53m         Warning   FailedScheduling         pod/fio-smallfile-lifecycle-6                                0/3 nodes are available: pod has unbound immediate PersistentVolumeClaims. not found
52m         Normal    Scheduled                pod/fio-smallfile-lifecycle-5                                Successfully assigned fio-tests/fio-smallfile-lifecycle-5 to s3
52m         Warning   FailedScheduling         pod/fio-smallfile-lifecycle-5                                0/3 nodes are available: pod has unbound immediate PersistentVolumeClaims. not found
53m         Warning   FailedScheduling         pod/fio-smallfile-lifecycle-5                                0/3 nodes are available: pod has unbound immediate PersistentVolumeClaims. not found
52m         Normal    Scheduled                pod/fio-smallfile-lifecycle-4                                Successfully assigned fio-tests/fio-smallfile-lifecycle-4 to s1
52m         Warning   FailedScheduling         pod/fio-smallfile-lifecycle-4                                0/3 nodes are available: pod has unbound immediate PersistentVolumeClaims. not found
53m         Warning   FailedScheduling         pod/fio-smallfile-lifecycle-4                                0/3 nodes are available: pod has unbound immediate PersistentVolumeClaims. not found
52m         Warning   FailedScheduling         pod/fio-smallfile-lifecycle-3                                0/3 nodes are available: pod has unbound immediate PersistentVolumeClaims. not found
53m         Warning   FailedScheduling         pod/fio-smallfile-lifecycle-3                                0/3 nodes are available: pod has unbound immediate PersistentVolumeClaims. not found
52m         Normal    Scheduled                pod/fio-smallfile-lifecycle-2                                Successfully assigned fio-tests/fio-smallfile-lifecycle-2 to s1
52m         Warning   FailedScheduling         pod/fio-smallfile-lifecycle-2                                0/3 nodes are available: pod has unbound immediate PersistentVolumeClaims. not found
53m         Warning   FailedScheduling         pod/fio-smallfile-lifecycle-2                                0/3 nodes are available: pod has unbound immediate PersistentVolumeClaims. not found
52m         Normal    Scheduled                pod/fio-smallfile-lifecycle-1                                Successfully assigned fio-tests/fio-smallfile-lifecycle-1 to s1
52m         Warning   FailedScheduling         pod/fio-smallfile-lifecycle-1                                0/3 nodes are available: pod has unbound immediate PersistentVolumeClaims. not found
53m         Warning   FailedScheduling         pod/fio-smallfile-lifecycle-1                                0/3 nodes are available: pod has unbound immediate PersistentVolumeClaims. not found
52m         Normal    Scheduled                pod/fio-smallfile-lifecycle-0                                Successfully assigned fio-tests/fio-smallfile-lifecycle-0 to s2
52m         Warning   FailedScheduling         pod/fio-smallfile-lifecycle-0                                0/3 nodes are available: pod has unbound immediate PersistentVolumeClaims. not found
53m         Warning   FailedScheduling         pod/fio-smallfile-lifecycle-0                                0/3 nodes are available: pod has unbound immediate PersistentVolumeClaims. not found
87m         Warning   FailedScheduling         pod/fio-max-throughput-0                                     0/3 nodes are available: pod has unbound immediate PersistentVolumeClaims. not found
86m         Warning   FailedScheduling         pod/fio-max-throughput-0                                     0/3 nodes are available: pod has unbound immediate PersistentVolumeClaims. not found
86m         Normal    Scheduled                pod/fio-max-throughput-0                                     Successfully assigned fio-tests/fio-max-throughput-0 to s1
86m         Normal    Scheduled                pod/fio-max-throughput-9                                     Successfully assigned fio-tests/fio-max-throughput-9 to s3
86m         Warning   FailedScheduling         pod/fio-max-throughput-9                                     0/3 nodes are available: pod has unbound immediate PersistentVolumeClaims. not found
87m         Warning   FailedScheduling         pod/fio-max-throughput-9                                     0/3 nodes are available: pod has unbound immediate PersistentVolumeClaims. not found
86m         Normal    Scheduled                pod/fio-max-throughput-8                                     Successfully assigned fio-tests/fio-max-throughput-8 to s3
86m         Warning   FailedScheduling         pod/fio-max-throughput-8                                     0/3 nodes are available: pod has unbound immediate PersistentVolumeClaims. not found
87m         Warning   FailedScheduling         pod/fio-max-throughput-1                                     0/3 nodes are available: pod has unbound immediate PersistentVolumeClaims. not found
86m         Warning   FailedScheduling         pod/fio-max-throughput-1                                     0/3 nodes are available: pod has unbound immediate PersistentVolumeClaims. not found
86m         Normal    Scheduled                pod/fio-max-throughput-1                                     Successfully assigned fio-tests/fio-max-throughput-1 to s2
87m         Warning   FailedScheduling         pod/fio-max-throughput-8                                     0/3 nodes are available: pod has unbound immediate PersistentVolumeClaims. not found
86m         Normal    Scheduled                pod/fio-max-throughput-7                                     Successfully assigned fio-tests/fio-max-throughput-7 to s2
86m         Warning   FailedScheduling         pod/fio-max-throughput-7                                     0/3 nodes are available: pod has unbound immediate PersistentVolumeClaims. not found
87m         Warning   FailedScheduling         pod/fio-max-throughput-7                                     0/3 nodes are available: pod has unbound immediate PersistentVolumeClaims. not found
86m         Normal    Scheduled                pod/fio-max-throughput-6                                     Successfully assigned fio-tests/fio-max-throughput-6 to s3
87m         Warning   FailedScheduling         pod/fio-max-throughput-2                                     0/3 nodes are available: pod has unbound immediate PersistentVolumeClaims. not found
86m         Warning   FailedScheduling         pod/fio-max-throughput-2                                     0/3 nodes are available: pod has unbound immediate PersistentVolumeClaims. not found
86m         Normal    Scheduled                pod/fio-max-throughput-2                                     Successfully assigned fio-tests/fio-max-throughput-2 to s2
86m         Warning   FailedScheduling         pod/fio-max-throughput-6                                     0/3 nodes are available: pod has unbound immediate PersistentVolumeClaims. not found
87m         Warning   FailedScheduling         pod/fio-max-throughput-6                                     0/3 nodes are available: pod has unbound immediate PersistentVolumeClaims. not found
86m         Normal    Scheduled                pod/fio-max-throughput-5                                     Successfully assigned fio-tests/fio-max-throughput-5 to s1
86m         Warning   FailedScheduling         pod/fio-max-throughput-5                                     0/3 nodes are available: pod has unbound immediate PersistentVolumeClaims. not found
87m         Warning   FailedScheduling         pod/fio-max-throughput-5                                     0/3 nodes are available: pod has unbound immediate PersistentVolumeClaims. not found
87m         Warning   FailedScheduling         pod/fio-max-throughput-3                                     0/3 nodes are available: pod has unbound immediate PersistentVolumeClaims. not found
87m         Warning   FailedScheduling         pod/fio-max-throughput-3                                     0/3 nodes are available: pod has unbound immediate PersistentVolumeClaims. not found
87m         Normal    Scheduled                pod/fio-max-throughput-3                                     Successfully assigned fio-tests/fio-max-throughput-3 to s1
86m         Normal    Scheduled                pod/fio-max-throughput-4                                     Successfully assigned fio-tests/fio-max-throughput-4 to s2
86m         Warning   FailedScheduling         pod/fio-max-throughput-4                                     0/3 nodes are available: pod has unbound immediate PersistentVolumeClaims. not found
87m         Warning   FailedScheduling         pod/fio-max-throughput-4                                     0/3 nodes are available: pod has unbound immediate PersistentVolumeClaims. not found
97m         Normal    Provisioning             persistentvolumeclaim/fio-low-qd-latency-pvc-0               External provisioner is provisioning volume for claim "fio-tests/fio-low-qd-latency-pvc-0"
97m         Normal    Provisioning             persistentvolumeclaim/fio-low-qd-latency-pvc-1               External provisioner is provisioning volume for claim "fio-tests/fio-low-qd-latency-pvc-1"
97m         Normal    Provisioning             persistentvolumeclaim/fio-low-qd-latency-pvc-5               External provisioner is provisioning volume for claim "fio-tests/fio-low-qd-latency-pvc-5"
97m         Normal    Provisioning             persistentvolumeclaim/fio-low-qd-latency-pvc-6               External provisioner is provisioning volume for claim "fio-tests/fio-low-qd-latency-pvc-6"
97m         Normal    Provisioning             persistentvolumeclaim/fio-low-qd-latency-pvc-9               External provisioner is provisioning volume for claim "fio-tests/fio-low-qd-latency-pvc-9"
97m         Normal    Provisioning             persistentvolumeclaim/fio-low-qd-latency-pvc-8               External provisioner is provisioning volume for claim "fio-tests/fio-low-qd-latency-pvc-8"
97m         Normal    Provisioning             persistentvolumeclaim/fio-low-qd-latency-pvc-2               External provisioner is provisioning volume for claim "fio-tests/fio-low-qd-latency-pvc-2"
97m         Normal    Provisioning             persistentvolumeclaim/fio-low-qd-latency-pvc-4               External provisioner is provisioning volume for claim "fio-tests/fio-low-qd-latency-pvc-4"
97m         Normal    Provisioning             persistentvolumeclaim/fio-low-qd-latency-pvc-7               External provisioner is provisioning volume for claim "fio-tests/fio-low-qd-latency-pvc-7"
97m         Normal    Provisioning             persistentvolumeclaim/fio-low-qd-latency-pvc-3               External provisioner is provisioning volume for claim "fio-tests/fio-low-qd-latency-pvc-3"
97m         Normal    ExternalProvisioning     persistentvolumeclaim/fio-low-qd-latency-pvc-3               Waiting for a volume to be created either by the external provisioner 'csi.trident.netapp.io' or manually by the system administrator. If volume creation is delayed, please verify that the provisioner is running and correctly registered.
97m         Normal    ExternalProvisioning     persistentvolumeclaim/fio-low-qd-latency-pvc-7               Waiting for a volume to be created either by the external provisioner 'csi.trident.netapp.io' or manually by the system administrator. If volume creation is delayed, please verify that the provisioner is running and correctly registered.
96m         Normal    ProvisioningSucceeded    persistentvolumeclaim/fio-low-qd-latency-pvc-3               Successfully provisioned volume pvc-f1b5da56-b226-427c-b95f-22e4a488cfda
96m         Normal    ProvisioningSuccess      persistentvolumeclaim/fio-low-qd-latency-pvc-3               provisioned a volume
96m         Normal    ProvisioningSuccess      persistentvolumeclaim/fio-low-qd-latency-pvc-7               provisioned a volume
96m         Normal    ProvisioningSucceeded    persistentvolumeclaim/fio-low-qd-latency-pvc-7               Successfully provisioned volume pvc-c55c6bf6-b757-42e5-8524-aeaa81d51434
96m         Normal    ExternalProvisioning     persistentvolumeclaim/fio-low-qd-latency-pvc-5               Waiting for a volume to be created either by the external provisioner 'csi.trident.netapp.io' or manually by the system administrator. If volume creation is delayed, please verify that the provisioner is running and correctly registered.
96m         Normal    ExternalProvisioning     persistentvolumeclaim/fio-low-qd-latency-pvc-8               Waiting for a volume to be created either by the external provisioner 'csi.trident.netapp.io' or manually by the system administrator. If volume creation is delayed, please verify that the provisioner is running and correctly registered.
96m         Normal    ProvisioningSucceeded    persistentvolumeclaim/fio-low-qd-latency-pvc-8               Successfully provisioned volume pvc-79b5bc2c-6481-4764-9837-5fcaba43b2ce
96m         Normal    ProvisioningSuccess      persistentvolumeclaim/fio-low-qd-latency-pvc-8               provisioned a volume
96m         Normal    ProvisioningSucceeded    persistentvolumeclaim/fio-low-qd-latency-pvc-5               Successfully provisioned volume pvc-65063084-e48d-4245-9991-06787555f747
96m         Normal    ProvisioningSuccess      persistentvolumeclaim/fio-low-qd-latency-pvc-5               provisioned a volume
96m         Normal    ExternalProvisioning     persistentvolumeclaim/fio-low-qd-latency-pvc-4               Waiting for a volume to be created either by the external provisioner 'csi.trident.netapp.io' or manually by the system administrator. If volume creation is delayed, please verify that the provisioner is running and correctly registered.
96m         Normal    ExternalProvisioning     persistentvolumeclaim/fio-low-qd-latency-pvc-9               Waiting for a volume to be created either by the external provisioner 'csi.trident.netapp.io' or manually by the system administrator. If volume creation is delayed, please verify that the provisioner is running and correctly registered.
96m         Normal    ExternalProvisioning     persistentvolumeclaim/fio-low-qd-latency-pvc-1               Waiting for a volume to be created either by the external provisioner 'csi.trident.netapp.io' or manually by the system administrator. If volume creation is delayed, please verify that the provisioner is running and correctly registered.
96m         Normal    ProvisioningSuccess      persistentvolumeclaim/fio-low-qd-latency-pvc-4               provisioned a volume
96m         Normal    ProvisioningSucceeded    persistentvolumeclaim/fio-low-qd-latency-pvc-4               Successfully provisioned volume pvc-5145e34e-0563-4162-b1b2-37d9ccd217a7
96m         Normal    ProvisioningSuccess      persistentvolumeclaim/fio-low-qd-latency-pvc-9               provisioned a volume
96m         Normal    ProvisioningSucceeded    persistentvolumeclaim/fio-low-qd-latency-pvc-9               Successfully provisioned volume pvc-ac2e529f-149a-4c4e-907d-c3203cb4dcd7
96m         Normal    ProvisioningSucceeded    persistentvolumeclaim/fio-low-qd-latency-pvc-1               Successfully provisioned volume pvc-6bcf35de-e58e-4cbb-960c-3ba29943ead1
96m         Normal    ProvisioningSuccess      persistentvolumeclaim/fio-low-qd-latency-pvc-1               provisioned a volume
96m         Normal    ExternalProvisioning     persistentvolumeclaim/fio-low-qd-latency-pvc-2               Waiting for a volume to be created either by the external provisioner 'csi.trident.netapp.io' or manually by the system administrator. If volume creation is delayed, please verify that the provisioner is running and correctly registered.
96m         Normal    ExternalProvisioning     persistentvolumeclaim/fio-low-qd-latency-pvc-6               Waiting for a volume to be created either by the external provisioner 'csi.trident.netapp.io' or manually by the system administrator. If volume creation is delayed, please verify that the provisioner is running and correctly registered.
96m         Normal    SuccessfulAttachVolume   pod/fio-low-qd-latency-3                                     AttachVolume.Attach succeeded for volume "pvc-f1b5da56-b226-427c-b95f-22e4a488cfda"
96m         Normal    ProvisioningSuccess      persistentvolumeclaim/fio-low-qd-latency-pvc-6               provisioned a volume
96m         Normal    ProvisioningSucceeded    persistentvolumeclaim/fio-low-qd-latency-pvc-6               Successfully provisioned volume pvc-34bbfb88-bc9d-4335-808b-549a4289fd01
96m         Normal    Created                  pod/fio-low-qd-latency-3                                     Container created
96m         Normal    Started                  pod/fio-low-qd-latency-3                                     Container started
96m         Normal    Pulled                   pod/fio-low-qd-latency-3                                     Container image "rafmoshe2500/fio:3.41" already present on machine and can be accessed by the pod
96m         Normal    AddedInterface           pod/fio-low-qd-latency-3                                     Add eth0 [10.130.0.86/23] from ovn-kubernetes
96m         Normal    ProvisioningSuccess      persistentvolumeclaim/fio-low-qd-latency-pvc-2               provisioned a volume
96m         Normal    ProvisioningSucceeded    persistentvolumeclaim/fio-low-qd-latency-pvc-2               Successfully provisioned volume pvc-88d7526f-6bf2-4050-ac26-58c77a1197cd
96m         Normal    ExternalProvisioning     persistentvolumeclaim/fio-low-qd-latency-pvc-0               Waiting for a volume to be created either by the external provisioner 'csi.trident.netapp.io' or manually by the system administrator. If volume creation is delayed, please verify that the provisioner is running and correctly registered.
95m         Normal    ProvisioningSuccess      persistentvolumeclaim/fio-low-qd-latency-pvc-0               provisioned a volume
95m         Normal    ProvisioningSucceeded    persistentvolumeclaim/fio-low-qd-latency-pvc-0               Successfully provisioned volume pvc-d87dc904-0647-469e-aa49-a69c13c3a9a2
95m         Normal    Started                  pod/fio-low-qd-latency-7                                     Container started
95m         Normal    AddedInterface           pod/fio-low-qd-latency-5                                     Add eth0 [10.130.0.87/23] from ovn-kubernetes
95m         Normal    Created                  pod/fio-low-qd-latency-5                                     Container created
95m         Normal    Started                  pod/fio-low-qd-latency-5                                     Container started
95m         Normal    SuccessfulAttachVolume   pod/fio-low-qd-latency-1                                     AttachVolume.Attach succeeded for volume "pvc-6bcf35de-e58e-4cbb-960c-3ba29943ead1"
95m         Normal    SuccessfulAttachVolume   pod/fio-low-qd-latency-5                                     AttachVolume.Attach succeeded for volume "pvc-65063084-e48d-4245-9991-06787555f747"
95m         Normal    SuccessfulAttachVolume   pod/fio-low-qd-latency-7                                     AttachVolume.Attach succeeded for volume "pvc-c55c6bf6-b757-42e5-8524-aeaa81d51434"
95m         Normal    AddedInterface           pod/fio-low-qd-latency-7                                     Add eth0 [10.129.0.208/23] from ovn-kubernetes
95m         Normal    Pulled                   pod/fio-low-qd-latency-7                                     Container image "rafmoshe2500/fio:3.41" already present on machine and can be accessed by the pod
95m         Normal    Created                  pod/fio-low-qd-latency-7                                     Container created
95m         Normal    Pulled                   pod/fio-low-qd-latency-5                                     Container image "rafmoshe2500/fio:3.41" already present on machine and can be accessed by the pod
95m         Normal    Pulled                   pod/fio-low-qd-latency-8                                     Container image "rafmoshe2500/fio:3.41" already present on machine and can be accessed by the pod
95m         Normal    Created                  pod/fio-low-qd-latency-6                                     Container created
95m         Normal    SuccessfulAttachVolume   pod/fio-low-qd-latency-0                                     AttachVolume.Attach succeeded for volume "pvc-d87dc904-0647-469e-aa49-a69c13c3a9a2"
95m         Normal    Created                  pod/fio-low-qd-latency-2                                     Container created
95m         Normal    SuccessfulAttachVolume   pod/fio-low-qd-latency-4                                     AttachVolume.Attach succeeded for volume "pvc-5145e34e-0563-4162-b1b2-37d9ccd217a7"
95m         Normal    SuccessfulAttachVolume   pod/fio-low-qd-latency-9                                     AttachVolume.Attach succeeded for volume "pvc-ac2e529f-149a-4c4e-907d-c3203cb4dcd7"
95m         Normal    SuccessfulAttachVolume   pod/fio-low-qd-latency-6                                     AttachVolume.Attach succeeded for volume "pvc-34bbfb88-bc9d-4335-808b-549a4289fd01"
95m         Normal    AddedInterface           pod/fio-low-qd-latency-6                                     Add eth0 [10.129.0.210/23] from ovn-kubernetes
95m         Normal    Pulled                   pod/fio-low-qd-latency-6                                     Container image "rafmoshe2500/fio:3.41" already present on machine and can be accessed by the pod
95m         Normal    AddedInterface           pod/fio-low-qd-latency-1                                     Add eth0 [10.130.0.88/23] from ovn-kubernetes
95m         Normal    Pulled                   pod/fio-low-qd-latency-1                                     Container image "rafmoshe2500/fio:3.41" already present on machine and can be accessed by the pod
95m         Normal    Started                  pod/fio-low-qd-latency-6                                     Container started
95m         Normal    Created                  pod/fio-low-qd-latency-1                                     Container created
95m         Normal    SuccessfulAttachVolume   pod/fio-low-qd-latency-8                                     AttachVolume.Attach succeeded for volume "pvc-79b5bc2c-6481-4764-9837-5fcaba43b2ce"
95m         Normal    Started                  pod/fio-low-qd-latency-8                                     Container started
95m         Normal    Started                  pod/fio-low-qd-latency-1                                     Container started
95m         Normal    Pulled                   pod/fio-low-qd-latency-2                                     Container image "rafmoshe2500/fio:3.41" already present on machine and can be accessed by the pod
95m         Normal    Created                  pod/fio-low-qd-latency-8                                     Container created
95m         Normal    SuccessfulAttachVolume   pod/fio-low-qd-latency-2                                     AttachVolume.Attach succeeded for volume "pvc-88d7526f-6bf2-4050-ac26-58c77a1197cd"
95m         Normal    AddedInterface           pod/fio-low-qd-latency-2                                     Add eth0 [10.128.0.181/23] from ovn-kubernetes
95m         Normal    AddedInterface           pod/fio-low-qd-latency-8                                     Add eth0 [10.128.0.179/23] from ovn-kubernetes
95m         Normal    Started                  pod/fio-low-qd-latency-4                                     Container started
95m         Normal    Pulled                   pod/fio-low-qd-latency-4                                     Container image "rafmoshe2500/fio:3.41" already present on machine and can be accessed by the pod
95m         Normal    AddedInterface           pod/fio-low-qd-latency-9                                     Add eth0 [10.129.0.209/23] from ovn-kubernetes
95m         Normal    Created                  pod/fio-low-qd-latency-4                                     Container created
95m         Normal    Pulled                   pod/fio-low-qd-latency-9                                     Container image "rafmoshe2500/fio:3.41" already present on machine and can be accessed by the pod
95m         Normal    Created                  pod/fio-low-qd-latency-9                                     Container created
95m         Normal    Started                  pod/fio-low-qd-latency-2                                     Container started
95m         Normal    AddedInterface           pod/fio-low-qd-latency-4                                     Add eth0 [10.128.0.180/23] from ovn-kubernetes
95m         Normal    Started                  pod/fio-low-qd-latency-9                                     Container started
95m         Normal    Created                  pod/fio-low-qd-latency-0                                     Container created
95m         Normal    Pulled                   pod/fio-low-qd-latency-0                                     Container image "rafmoshe2500/fio:3.41" already present on machine and can be accessed by the pod
95m         Normal    AddedInterface           pod/fio-low-qd-latency-0                                     Add eth0 [10.130.0.89/23] from ovn-kubernetes
95m         Normal    Started                  pod/fio-low-qd-latency-0                                     Container started
87m         Normal    Provisioning             persistentvolumeclaim/fio-max-throughput-pvc-0               External provisioner is provisioning volume for claim "fio-tests/fio-max-throughput-pvc-0"
87m         Normal    Provisioning             persistentvolumeclaim/fio-max-throughput-pvc-2               External provisioner is provisioning volume for claim "fio-tests/fio-max-throughput-pvc-2"
87m         Normal    Provisioning             persistentvolumeclaim/fio-max-throughput-pvc-7               External provisioner is provisioning volume for claim "fio-tests/fio-max-throughput-pvc-7"
87m         Normal    Provisioning             persistentvolumeclaim/fio-max-throughput-pvc-9               External provisioner is provisioning volume for claim "fio-tests/fio-max-throughput-pvc-9"
87m         Normal    Provisioning             persistentvolumeclaim/fio-max-throughput-pvc-4               External provisioner is provisioning volume for claim "fio-tests/fio-max-throughput-pvc-4"
87m         Normal    Provisioning             persistentvolumeclaim/fio-max-throughput-pvc-6               External provisioner is provisioning volume for claim "fio-tests/fio-max-throughput-pvc-6"
87m         Normal    Provisioning             persistentvolumeclaim/fio-max-throughput-pvc-1               External provisioner is provisioning volume for claim "fio-tests/fio-max-throughput-pvc-1"
87m         Normal    Provisioning             persistentvolumeclaim/fio-max-throughput-pvc-5               External provisioner is provisioning volume for claim "fio-tests/fio-max-throughput-pvc-5"
87m         Normal    ExternalProvisioning     persistentvolumeclaim/fio-max-throughput-pvc-3               Waiting for a volume to be created either by the external provisioner 'csi.trident.netapp.io' or manually by the system administrator. If volume creation is delayed, please verify that the provisioner is running and correctly registered.
87m         Normal    Provisioning             persistentvolumeclaim/fio-max-throughput-pvc-3               External provisioner is provisioning volume for claim "fio-tests/fio-max-throughput-pvc-3"
87m         Normal    Provisioning             persistentvolumeclaim/fio-max-throughput-pvc-8               External provisioner is provisioning volume for claim "fio-tests/fio-max-throughput-pvc-8"
87m         Normal    ProvisioningSuccess      persistentvolumeclaim/fio-max-throughput-pvc-3               provisioned a volume
87m         Normal    ProvisioningSucceeded    persistentvolumeclaim/fio-max-throughput-pvc-3               Successfully provisioned volume pvc-0d345341-ed23-415c-bbf0-f42647949c9b
87m         Normal    ExternalProvisioning     persistentvolumeclaim/fio-max-throughput-pvc-8               Waiting for a volume to be created either by the external provisioner 'csi.trident.netapp.io' or manually by the system administrator. If volume creation is delayed, please verify that the provisioner is running and correctly registered.
87m         Normal    ExternalProvisioning     persistentvolumeclaim/fio-max-throughput-pvc-4               Waiting for a volume to be created either by the external provisioner 'csi.trident.netapp.io' or manually by the system administrator. If volume creation is delayed, please verify that the provisioner is running and correctly registered.
86m         Normal    ProvisioningSucceeded    persistentvolumeclaim/fio-max-throughput-pvc-4               Successfully provisioned volume pvc-3a931b50-0bd5-4021-b61a-405b8072d6e1
86m         Normal    ProvisioningSuccess      persistentvolumeclaim/fio-max-throughput-pvc-4               provisioned a volume
86m         Normal    ProvisioningSucceeded    persistentvolumeclaim/fio-max-throughput-pvc-8               Successfully provisioned volume pvc-9c571b84-e262-4ccc-af3b-29321191d43d
86m         Normal    ProvisioningSuccess      persistentvolumeclaim/fio-max-throughput-pvc-8               provisioned a volume
86m         Normal    ExternalProvisioning     persistentvolumeclaim/fio-max-throughput-pvc-0               Waiting for a volume to be created either by the external provisioner 'csi.trident.netapp.io' or manually by the system administrator. If volume creation is delayed, please verify that the provisioner is running and correctly registered.
86m         Normal    ExternalProvisioning     persistentvolumeclaim/fio-max-throughput-pvc-1               Waiting for a volume to be created either by the external provisioner 'csi.trident.netapp.io' or manually by the system administrator. If volume creation is delayed, please verify that the provisioner is running and correctly registered.
86m         Normal    ExternalProvisioning     persistentvolumeclaim/fio-max-throughput-pvc-9               Waiting for a volume to be created either by the external provisioner 'csi.trident.netapp.io' or manually by the system administrator. If volume creation is delayed, please verify that the provisioner is running and correctly registered.
86m         Normal    ProvisioningSuccess      persistentvolumeclaim/fio-max-throughput-pvc-0               provisioned a volume
86m         Normal    ProvisioningSucceeded    persistentvolumeclaim/fio-max-throughput-pvc-0               Successfully provisioned volume pvc-3973fefe-46b5-4fa6-82ef-1080fde7f021
86m         Normal    ProvisioningSucceeded    persistentvolumeclaim/fio-max-throughput-pvc-9               Successfully provisioned volume pvc-ea17bb6a-624f-47f4-918a-ff0c56b261e8
86m         Normal    ProvisioningSuccess      persistentvolumeclaim/fio-max-throughput-pvc-9               provisioned a volume
86m         Normal    ProvisioningSuccess      persistentvolumeclaim/fio-max-throughput-pvc-1               provisioned a volume
86m         Normal    ProvisioningSucceeded    persistentvolumeclaim/fio-max-throughput-pvc-1               Successfully provisioned volume pvc-163776e0-07f5-4569-a86b-6d1b5736238f
86m         Normal    ExternalProvisioning     persistentvolumeclaim/fio-max-throughput-pvc-5               Waiting for a volume to be created either by the external provisioner 'csi.trident.netapp.io' or manually by the system administrator. If volume creation is delayed, please verify that the provisioner is running and correctly registered.
86m         Normal    ExternalProvisioning     persistentvolumeclaim/fio-max-throughput-pvc-6               Waiting for a volume to be created either by the external provisioner 'csi.trident.netapp.io' or manually by the system administrator. If volume creation is delayed, please verify that the provisioner is running and correctly registered.
86m         Normal    ExternalProvisioning     persistentvolumeclaim/fio-max-throughput-pvc-2               Waiting for a volume to be created either by the external provisioner 'csi.trident.netapp.io' or manually by the system administrator. If volume creation is delayed, please verify that the provisioner is running and correctly registered.
86m         Normal    ProvisioningSuccess      persistentvolumeclaim/fio-max-throughput-pvc-5               provisioned a volume
86m         Normal    ProvisioningSucceeded    persistentvolumeclaim/fio-max-throughput-pvc-5               Successfully provisioned volume pvc-89442f44-8e08-4eeb-a3f9-cf7a22da6537
86m         Normal    ProvisioningSucceeded    persistentvolumeclaim/fio-max-throughput-pvc-2               Successfully provisioned volume pvc-30119b2d-e0cb-4fb0-8479-ef18f3bc1043
86m         Normal    ProvisioningSuccess      persistentvolumeclaim/fio-max-throughput-pvc-2               provisioned a volume
86m         Normal    ProvisioningSuccess      persistentvolumeclaim/fio-max-throughput-pvc-6               provisioned a volume
86m         Normal    ProvisioningSucceeded    persistentvolumeclaim/fio-max-throughput-pvc-6               Successfully provisioned volume pvc-4df648b1-6874-4a0b-bed0-aef4bce7b1fe
86m         Normal    ExternalProvisioning     persistentvolumeclaim/fio-max-throughput-pvc-7               Waiting for a volume to be created either by the external provisioner 'csi.trident.netapp.io' or manually by the system administrator. If volume creation is delayed, please verify that the provisioner is running and correctly registered.
86m         Normal    SuccessfulAttachVolume   pod/fio-max-throughput-5                                     AttachVolume.Attach succeeded for volume "pvc-89442f44-8e08-4eeb-a3f9-cf7a22da6537"
86m         Normal    ProvisioningSucceeded    persistentvolumeclaim/fio-max-throughput-pvc-7               Successfully provisioned volume pvc-7b9edd08-5ad8-4aa1-b2c2-9b1a115c752c
86m         Normal    SuccessfulAttachVolume   pod/fio-max-throughput-6                                     AttachVolume.Attach succeeded for volume "pvc-4df648b1-6874-4a0b-bed0-aef4bce7b1fe"
86m         Normal    SuccessfulAttachVolume   pod/fio-max-throughput-8                                     AttachVolume.Attach succeeded for volume "pvc-9c571b84-e262-4ccc-af3b-29321191d43d"
86m         Normal    ProvisioningSuccess      persistentvolumeclaim/fio-max-throughput-pvc-7               provisioned a volume
86m         Normal    AddedInterface           pod/fio-max-throughput-2                                     Add eth0 [10.129.0.213/23] from ovn-kubernetes
86m         Normal    Created                  pod/fio-max-throughput-6                                     Container created
86m         Normal    Started                  pod/fio-max-throughput-5                                     Container started
86m         Normal    Pulled                   pod/fio-max-throughput-5                                     Container image "rafmoshe2500/fio:3.41" already present on machine and can be accessed by the pod
86m         Normal    SuccessfulAttachVolume   pod/fio-max-throughput-2                                     AttachVolume.Attach succeeded for volume "pvc-30119b2d-e0cb-4fb0-8479-ef18f3bc1043"
86m         Normal    Pulled                   pod/fio-max-throughput-2                                     Container image "rafmoshe2500/fio:3.41" already present on machine and can be accessed by the pod
86m         Normal    Created                  pod/fio-max-throughput-2                                     Container created
86m         Normal    Started                  pod/fio-max-throughput-2                                     Container started
86m         Normal    Pulled                   pod/fio-max-throughput-9                                     Container image "rafmoshe2500/fio:3.41" already present on machine and can be accessed by the pod
86m         Normal    AddedInterface           pod/fio-max-throughput-8                                     Add eth0 [10.128.0.182/23] from ovn-kubernetes
86m         Normal    AddedInterface           pod/fio-max-throughput-5                                     Add eth0 [10.130.0.92/23] from ovn-kubernetes
86m         Normal    AddedInterface           pod/fio-max-throughput-6                                     Add eth0 [10.128.0.184/23] from ovn-kubernetes
86m         Normal    Pulled                   pod/fio-max-throughput-6                                     Container image "rafmoshe2500/fio:3.41" already present on machine and can be accessed by the pod
86m         Normal    Created                  pod/fio-max-throughput-5                                     Container created
86m         Normal    Pulled                   pod/fio-max-throughput-8                                     Container image "rafmoshe2500/fio:3.41" already present on machine and can be accessed by the pod
86m         Normal    Created                  pod/fio-max-throughput-8                                     Container created
86m         Normal    SuccessfulAttachVolume   pod/fio-max-throughput-1                                     AttachVolume.Attach succeeded for volume "pvc-163776e0-07f5-4569-a86b-6d1b5736238f"
86m         Normal    Started                  pod/fio-max-throughput-7                                     Container started
86m         Normal    Created                  pod/fio-max-throughput-7                                     Container created
86m         Normal    Started                  pod/fio-max-throughput-6                                     Container started
86m         Normal    Pulled                   pod/fio-max-throughput-7                                     Container image "rafmoshe2500/fio:3.41" already present on machine and can be accessed by the pod
86m         Normal    AddedInterface           pod/fio-max-throughput-7                                     Add eth0 [10.129.0.214/23] from ovn-kubernetes
86m         Normal    SuccessfulAttachVolume   pod/fio-max-throughput-7                                     AttachVolume.Attach succeeded for volume "pvc-7b9edd08-5ad8-4aa1-b2c2-9b1a115c752c"
86m         Normal    Started                  pod/fio-max-throughput-8                                     Container started
86m         Normal    SuccessfulAttachVolume   pod/fio-max-throughput-9                                     AttachVolume.Attach succeeded for volume "pvc-ea17bb6a-624f-47f4-918a-ff0c56b261e8"
86m         Normal    AddedInterface           pod/fio-max-throughput-9                                     Add eth0 [10.128.0.183/23] from ovn-kubernetes
86m         Normal    Pulled                   pod/fio-max-throughput-0                                     Container image "rafmoshe2500/fio:3.41" already present on machine and can be accessed by the pod
86m         Normal    Started                  pod/fio-max-throughput-9                                     Container started
86m         Normal    Created                  pod/fio-max-throughput-0                                     Container created
86m         Normal    AddedInterface           pod/fio-max-throughput-1                                     Add eth0 [10.129.0.212/23] from ovn-kubernetes
86m         Normal    SuccessfulAttachVolume   pod/fio-max-throughput-0                                     AttachVolume.Attach succeeded for volume "pvc-3973fefe-46b5-4fa6-82ef-1080fde7f021"
86m         Normal    AddedInterface           pod/fio-max-throughput-0                                     Add eth0 [10.130.0.91/23] from ovn-kubernetes
86m         Normal    Created                  pod/fio-max-throughput-9                                     Container created
86m         Normal    Pulled                   pod/fio-max-throughput-1                                     Container image "rafmoshe2500/fio:3.41" already present on machine and can be accessed by the pod
86m         Normal    Created                  pod/fio-max-throughput-1                                     Container created
86m         Normal    Started                  pod/fio-max-throughput-0                                     Container started
86m         Normal    SuccessfulAttachVolume   pod/fio-max-throughput-3                                     AttachVolume.Attach succeeded for volume "pvc-0d345341-ed23-415c-bbf0-f42647949c9b"
86m         Normal    Started                  pod/fio-max-throughput-1                                     Container started
86m         Normal    Created                  pod/fio-max-throughput-3                                     Container created
86m         Normal    SuccessfulAttachVolume   pod/fio-max-throughput-4                                     AttachVolume.Attach succeeded for volume "pvc-3a931b50-0bd5-4021-b61a-405b8072d6e1"
86m         Normal    AddedInterface           pod/fio-max-throughput-3                                     Add eth0 [10.130.0.90/23] from ovn-kubernetes
86m         Normal    Pulled                   pod/fio-max-throughput-4                                     Container image "rafmoshe2500/fio:3.41" already present on machine and can be accessed by the pod
86m         Normal    AddedInterface           pod/fio-max-throughput-4                                     Add eth0 [10.129.0.211/23] from ovn-kubernetes
86m         Normal    Pulled                   pod/fio-max-throughput-3                                     Container image "rafmoshe2500/fio:3.41" already present on machine and can be accessed by the pod
86m         Normal    Started                  pod/fio-max-throughput-3                                     Container started
86m         Normal    Started                  pod/fio-max-throughput-4                                     Container started
86m         Normal    Created                  pod/fio-max-throughput-4                                     Container created
68m         Normal    Provisioning             persistentvolumeclaim/fio-sync-write-pvc-6                   External provisioner is provisioning volume for claim "fio-tests/fio-sync-write-pvc-6"
68m         Normal    Provisioning             persistentvolumeclaim/fio-sync-write-pvc-5                   External provisioner is provisioning volume for claim "fio-tests/fio-sync-write-pvc-5"
68m         Normal    Provisioning             persistentvolumeclaim/fio-sync-write-pvc-2                   External provisioner is provisioning volume for claim "fio-tests/fio-sync-write-pvc-2"
68m         Normal    Provisioning             persistentvolumeclaim/fio-sync-write-pvc-9                   External provisioner is provisioning volume for claim "fio-tests/fio-sync-write-pvc-9"
68m         Normal    ExternalProvisioning     persistentvolumeclaim/fio-sync-write-pvc-9                   Waiting for a volume to be created either by the external provisioner 'csi.trident.netapp.io' or manually by the system administrator. If volume creation is delayed, please verify that the provisioner is running and correctly registered.
68m         Normal    Provisioning             persistentvolumeclaim/fio-sync-write-pvc-7                   External provisioner is provisioning volume for claim "fio-tests/fio-sync-write-pvc-7"
68m         Normal    Provisioning             persistentvolumeclaim/fio-sync-write-pvc-1                   External provisioner is provisioning volume for claim "fio-tests/fio-sync-write-pvc-1"
68m         Normal    Provisioning             persistentvolumeclaim/fio-sync-write-pvc-8                   External provisioner is provisioning volume for claim "fio-tests/fio-sync-write-pvc-8"
68m         Normal    Provisioning             persistentvolumeclaim/fio-sync-write-pvc-3                   External provisioner is provisioning volume for claim "fio-tests/fio-sync-write-pvc-3"
68m         Normal    Provisioning             persistentvolumeclaim/fio-sync-write-pvc-4                   External provisioner is provisioning volume for claim "fio-tests/fio-sync-write-pvc-4"
68m         Normal    Provisioning             persistentvolumeclaim/fio-sync-write-pvc-0                   External provisioner is provisioning volume for claim "fio-tests/fio-sync-write-pvc-0"
68m         Normal    ProvisioningSucceeded    persistentvolumeclaim/fio-sync-write-pvc-9                   Successfully provisioned volume pvc-54b9ad5c-48c3-4106-8b58-3ad78ad8a319
68m         Normal    ProvisioningSuccess      persistentvolumeclaim/fio-sync-write-pvc-9                   provisioned a volume
68m         Normal    ExternalProvisioning     persistentvolumeclaim/fio-sync-write-pvc-1                   Waiting for a volume to be created either by the external provisioner 'csi.trident.netapp.io' or manually by the system administrator. If volume creation is delayed, please verify that the provisioner is running and correctly registered.
67m         Normal    ProvisioningSucceeded    persistentvolumeclaim/fio-sync-write-pvc-1                   Successfully provisioned volume pvc-4d2d6380-40d1-4c58-b459-c8cf27271455
67m         Normal    ProvisioningSuccess      persistentvolumeclaim/fio-sync-write-pvc-1                   provisioned a volume
67m         Normal    ExternalProvisioning     persistentvolumeclaim/fio-sync-write-pvc-0                   Waiting for a volume to be created either by the external provisioner 'csi.trident.netapp.io' or manually by the system administrator. If volume creation is delayed, please verify that the provisioner is running and correctly registered.
67m         Normal    ExternalProvisioning     persistentvolumeclaim/fio-sync-write-pvc-3                   Waiting for a volume to be created either by the external provisioner 'csi.trident.netapp.io' or manually by the system administrator. If volume creation is delayed, please verify that the provisioner is running and correctly registered.
67m         Normal    ProvisioningSucceeded    persistentvolumeclaim/fio-sync-write-pvc-3                   Successfully provisioned volume pvc-68281b68-cfd3-4469-a690-64f824381e97
67m         Normal    ProvisioningSuccess      persistentvolumeclaim/fio-sync-write-pvc-3                   provisioned a volume
67m         Normal    ProvisioningSuccess      persistentvolumeclaim/fio-sync-write-pvc-0                   provisioned a volume
67m         Normal    ProvisioningSucceeded    persistentvolumeclaim/fio-sync-write-pvc-0                   Successfully provisioned volume pvc-a5c3605c-0166-4140-8116-1cde037c91c2
67m         Normal    ExternalProvisioning     persistentvolumeclaim/fio-sync-write-pvc-6                   Waiting for a volume to be created either by the external provisioner 'csi.trident.netapp.io' or manually by the system administrator. If volume creation is delayed, please verify that the provisioner is running and correctly registered.
67m         Normal    ExternalProvisioning     persistentvolumeclaim/fio-sync-write-pvc-7                   Waiting for a volume to be created either by the external provisioner 'csi.trident.netapp.io' or manually by the system administrator. If volume creation is delayed, please verify that the provisioner is running and correctly registered.
67m         Normal    ProvisioningSuccess      persistentvolumeclaim/fio-sync-write-pvc-7                   provisioned a volume
67m         Normal    ProvisioningSucceeded    persistentvolumeclaim/fio-sync-write-pvc-7                   Successfully provisioned volume pvc-8a36a31c-a527-403b-ac0a-99a799f3747a
67m         Normal    ProvisioningSucceeded    persistentvolumeclaim/fio-sync-write-pvc-6                   Successfully provisioned volume pvc-76cc302f-3f1b-4a80-a580-1d498e3451b0
67m         Normal    ProvisioningSuccess      persistentvolumeclaim/fio-sync-write-pvc-6                   provisioned a volume
67m         Normal    ExternalProvisioning     persistentvolumeclaim/fio-sync-write-pvc-2                   Waiting for a volume to be created either by the external provisioner 'csi.trident.netapp.io' or manually by the system administrator. If volume creation is delayed, please verify that the provisioner is running and correctly registered.
67m         Normal    ExternalProvisioning     persistentvolumeclaim/fio-sync-write-pvc-5                   Waiting for a volume to be created either by the external provisioner 'csi.trident.netapp.io' or manually by the system administrator. If volume creation is delayed, please verify that the provisioner is running and correctly registered.
67m         Normal    ProvisioningSucceeded    persistentvolumeclaim/fio-sync-write-pvc-2                   Successfully provisioned volume pvc-ccc6267f-75cd-45be-87e6-45c0f90d4df9
67m         Normal    ProvisioningSuccess      persistentvolumeclaim/fio-sync-write-pvc-2                   provisioned a volume
67m         Normal    ProvisioningSucceeded    persistentvolumeclaim/fio-sync-write-pvc-5                   Successfully provisioned volume pvc-eecd9f7e-76f9-4336-8b21-58ff661c8a88
67m         Normal    ProvisioningSuccess      persistentvolumeclaim/fio-sync-write-pvc-5                   provisioned a volume
67m         Normal    ExternalProvisioning     persistentvolumeclaim/fio-sync-write-pvc-8                   Waiting for a volume to be created either by the external provisioner 'csi.trident.netapp.io' or manually by the system administrator. If volume creation is delayed, please verify that the provisioner is running and correctly registered.
67m         Normal    ExternalProvisioning     persistentvolumeclaim/fio-sync-write-pvc-4                   Waiting for a volume to be created either by the external provisioner 'csi.trident.netapp.io' or manually by the system administrator. If volume creation is delayed, please verify that the provisioner is running and correctly registered.
66m         Normal    ProvisioningSuccess      persistentvolumeclaim/fio-sync-write-pvc-8                   provisioned a volume
66m         Normal    ProvisioningSucceeded    persistentvolumeclaim/fio-sync-write-pvc-8                   Successfully provisioned volume pvc-d142ed21-7f81-4eb4-986c-99be872f5f85
66m         Normal    SuccessfulAttachVolume   pod/fio-sync-write-1                                         AttachVolume.Attach succeeded for volume "pvc-4d2d6380-40d1-4c58-b459-c8cf27271455"
66m         Normal    ProvisioningSucceeded    persistentvolumeclaim/fio-sync-write-pvc-4                   Successfully provisioned volume pvc-d83d4d16-2334-41bb-baea-bbd1597c901e
66m         Normal    ProvisioningSuccess      persistentvolumeclaim/fio-sync-write-pvc-4                   provisioned a volume
66m         Normal    SuccessfulAttachVolume   pod/fio-sync-write-3                                         AttachVolume.Attach succeeded for volume "pvc-68281b68-cfd3-4469-a690-64f824381e97"
66m         Normal    Pulled                   pod/fio-sync-write-5                                         Container image "rafmoshe2500/fio:3.41" already present on machine and can be accessed by the pod
66m         Normal    SuccessfulAttachVolume   pod/fio-sync-write-0                                         AttachVolume.Attach succeeded for volume "pvc-a5c3605c-0166-4140-8116-1cde037c91c2"
66m         Normal    SuccessfulAttachVolume   pod/fio-sync-write-8                                         AttachVolume.Attach succeeded for volume "pvc-d142ed21-7f81-4eb4-986c-99be872f5f85"
66m         Normal    SuccessfulAttachVolume   pod/fio-sync-write-2                                         AttachVolume.Attach succeeded for volume "pvc-ccc6267f-75cd-45be-87e6-45c0f90d4df9"
66m         Normal    SuccessfulAttachVolume   pod/fio-sync-write-6                                         AttachVolume.Attach succeeded for volume "pvc-76cc302f-3f1b-4a80-a580-1d498e3451b0"
66m         Normal    Started                  pod/fio-sync-write-1                                         Container started
66m         Normal    SuccessfulAttachVolume   pod/fio-sync-write-7                                         AttachVolume.Attach succeeded for volume "pvc-8a36a31c-a527-403b-ac0a-99a799f3747a"
66m         Normal    AddedInterface           pod/fio-sync-write-5                                         Add eth0 [10.129.0.217/23] from ovn-kubernetes
66m         Normal    Created                  pod/fio-sync-write-1                                         Container created
66m         Normal    SuccessfulAttachVolume   pod/fio-sync-write-5                                         AttachVolume.Attach succeeded for volume "pvc-eecd9f7e-76f9-4336-8b21-58ff661c8a88"
66m         Normal    AddedInterface           pod/fio-sync-write-1                                         Add eth0 [10.129.0.215/23] from ovn-kubernetes
66m         Normal    Pulled                   pod/fio-sync-write-1                                         Container image "rafmoshe2500/fio:3.41" already present on machine and can be accessed by the pod
66m         Normal    SuccessfulAttachVolume   pod/fio-sync-write-4                                         AttachVolume.Attach succeeded for volume "pvc-d83d4d16-2334-41bb-baea-bbd1597c901e"
66m         Normal    Created                  pod/fio-sync-write-0                                         Container created
66m         Normal    AddedInterface           pod/fio-sync-write-8                                         Add eth0 [10.128.0.187/23] from ovn-kubernetes
66m         Normal    Started                  pod/fio-sync-write-0                                         Container started
66m         Normal    Pulled                   pod/fio-sync-write-6                                         Container image "rafmoshe2500/fio:3.41" already present on machine and can be accessed by the pod
66m         Normal    Pulled                   pod/fio-sync-write-0                                         Container image "rafmoshe2500/fio:3.41" already present on machine and can be accessed by the pod
66m         Normal    AddedInterface           pod/fio-sync-write-2                                         Add eth0 [10.130.0.95/23] from ovn-kubernetes
66m         Normal    Pulled                   pod/fio-sync-write-2                                         Container image "rafmoshe2500/fio:3.41" already present on machine and can be accessed by the pod
66m         Normal    Created                  pod/fio-sync-write-2                                         Container created
66m         Normal    Started                  pod/fio-sync-write-2                                         Container started
66m         Normal    AddedInterface           pod/fio-sync-write-0                                         Add eth0 [10.130.0.94/23] from ovn-kubernetes
66m         Normal    Created                  pod/fio-sync-write-6                                         Container created
66m         Normal    Started                  pod/fio-sync-write-5                                         Container started
66m         Normal    Created                  pod/fio-sync-write-5                                         Container created
66m         Normal    AddedInterface           pod/fio-sync-write-3                                         Add eth0 [10.128.0.185/23] from ovn-kubernetes
66m         Normal    Pulled                   pod/fio-sync-write-3                                         Container image "rafmoshe2500/fio:3.41" already present on machine and can be accessed by the pod
66m         Normal    Created                  pod/fio-sync-write-3                                         Container created
66m         Normal    Started                  pod/fio-sync-write-3                                         Container started
66m         Normal    Started                  pod/fio-sync-write-6                                         Container started
66m         Normal    Started                  pod/fio-sync-write-8                                         Container started
66m         Normal    Created                  pod/fio-sync-write-8                                         Container created
66m         Normal    Pulled                   pod/fio-sync-write-8                                         Container image "rafmoshe2500/fio:3.41" already present on machine and can be accessed by the pod
66m         Normal    AddedInterface           pod/fio-sync-write-7                                         Add eth0 [10.128.0.186/23] from ovn-kubernetes
66m         Normal    Pulled                   pod/fio-sync-write-7                                         Container image "rafmoshe2500/fio:3.41" already present on machine and can be accessed by the pod
66m         Normal    Created                  pod/fio-sync-write-7                                         Container created
66m         Normal    Started                  pod/fio-sync-write-7                                         Container started
66m         Normal    AddedInterface           pod/fio-sync-write-6                                         Add eth0 [10.129.0.216/23] from ovn-kubernetes
66m         Normal    SuccessfulAttachVolume   pod/fio-sync-write-9                                         AttachVolume.Attach succeeded for volume "pvc-54b9ad5c-48c3-4106-8b58-3ad78ad8a319"
66m         Normal    AddedInterface           pod/fio-sync-write-9                                         Add eth0 [10.130.0.93/23] from ovn-kubernetes
66m         Normal    Pulled                   pod/fio-sync-write-9                                         Container image "rafmoshe2500/fio:3.41" already present on machine and can be accessed by the pod
66m         Normal    Created                  pod/fio-sync-write-9                                         Container created
66m         Normal    Started                  pod/fio-sync-write-9                                         Container started
66m         Normal    Started                  pod/fio-sync-write-4                                         Container started
66m         Normal    Created                  pod/fio-sync-write-4                                         Container created
66m         Normal    Pulled                   pod/fio-sync-write-4                                         Container image "rafmoshe2500/fio:3.41" already present on machine and can be accessed by the pod
66m         Normal    AddedInterface           pod/fio-sync-write-4                                         Add eth0 [10.130.0.96/23] from ovn-kubernetes
53m         Normal    Provisioning             persistentvolumeclaim/fio-smallfile-lifecycle-pvc-4          External provisioner is provisioning volume for claim "fio-tests/fio-smallfile-lifecycle-pvc-4"
53m         Normal    Provisioning             persistentvolumeclaim/fio-smallfile-lifecycle-pvc-3          External provisioner is provisioning volume for claim "fio-tests/fio-smallfile-lifecycle-pvc-3"
53m         Normal    Provisioning             persistentvolumeclaim/fio-smallfile-lifecycle-pvc-0          External provisioner is provisioning volume for claim "fio-tests/fio-smallfile-lifecycle-pvc-0"
53m         Normal    Provisioning             persistentvolumeclaim/fio-smallfile-lifecycle-pvc-2          External provisioner is provisioning volume for claim "fio-tests/fio-smallfile-lifecycle-pvc-2"
53m         Normal    Provisioning             persistentvolumeclaim/fio-smallfile-lifecycle-pvc-6          External provisioner is provisioning volume for claim "fio-tests/fio-smallfile-lifecycle-pvc-6"
53m         Normal    Provisioning             persistentvolumeclaim/fio-smallfile-lifecycle-pvc-1          External provisioner is provisioning volume for claim "fio-tests/fio-smallfile-lifecycle-pvc-1"
53m         Normal    ExternalProvisioning     persistentvolumeclaim/fio-smallfile-lifecycle-pvc-8          Waiting for a volume to be created either by the external provisioner 'csi.trident.netapp.io' or manually by the system administrator. If volume creation is delayed, please verify that the provisioner is running and correctly registered.
53m         Normal    Provisioning             persistentvolumeclaim/fio-smallfile-lifecycle-pvc-5          External provisioner is provisioning volume for claim "fio-tests/fio-smallfile-lifecycle-pvc-5"
53m         Normal    Provisioning             persistentvolumeclaim/fio-smallfile-lifecycle-pvc-8          External provisioner is provisioning volume for claim "fio-tests/fio-smallfile-lifecycle-pvc-8"
53m         Normal    ExternalProvisioning     persistentvolumeclaim/fio-smallfile-lifecycle-pvc-3          Waiting for a volume to be created either by the external provisioner 'csi.trident.netapp.io' or manually by the system administrator. If volume creation is delayed, please verify that the provisioner is running and correctly registered.
53m         Normal    Provisioning             persistentvolumeclaim/fio-smallfile-lifecycle-pvc-7          External provisioner is provisioning volume for claim "fio-tests/fio-smallfile-lifecycle-pvc-7"
53m         Normal    Provisioning             persistentvolumeclaim/fio-smallfile-lifecycle-pvc-9          External provisioner is provisioning volume for claim "fio-tests/fio-smallfile-lifecycle-pvc-9"
52m         Normal    ProvisioningSucceeded    persistentvolumeclaim/fio-smallfile-lifecycle-pvc-3          Successfully provisioned volume pvc-655081cc-fc2d-4cd6-8075-cba4c17ed37b
52m         Normal    ProvisioningSuccess      persistentvolumeclaim/fio-smallfile-lifecycle-pvc-3          provisioned a volume
52m         Normal    ProvisioningSucceeded    persistentvolumeclaim/fio-smallfile-lifecycle-pvc-8          Successfully provisioned volume pvc-0f2c76c6-b527-4d31-8820-cc043099cec0
52m         Normal    ProvisioningSuccess      persistentvolumeclaim/fio-smallfile-lifecycle-pvc-8          provisioned a volume
52m         Normal    ExternalProvisioning     persistentvolumeclaim/fio-smallfile-lifecycle-pvc-9          Waiting for a volume to be created either by the external provisioner 'csi.trident.netapp.io' or manually by the system administrator. If volume creation is delayed, please verify that the provisioner is running and correctly registered.
52m         Normal    ExternalProvisioning     persistentvolumeclaim/fio-smallfile-lifecycle-pvc-4          Waiting for a volume to be created either by the external provisioner 'csi.trident.netapp.io' or manually by the system administrator. If volume creation is delayed, please verify that the provisioner is running and correctly registered.
52m         Normal    ExternalProvisioning     persistentvolumeclaim/fio-smallfile-lifecycle-pvc-5          Waiting for a volume to be created either by the external provisioner 'csi.trident.netapp.io' or manually by the system administrator. If volume creation is delayed, please verify that the provisioner is running and correctly registered.
52m         Normal    ProvisioningSuccess      persistentvolumeclaim/fio-smallfile-lifecycle-pvc-9          provisioned a volume
52m         Normal    ProvisioningSucceeded    persistentvolumeclaim/fio-smallfile-lifecycle-pvc-9          Successfully provisioned volume pvc-600ff259-9d00-4607-81eb-2325a268f76f
52m         Normal    ProvisioningSucceeded    persistentvolumeclaim/fio-smallfile-lifecycle-pvc-4          Successfully provisioned volume pvc-5f303ecf-3d4f-4df9-b50c-f7dac8b3f413
52m         Normal    ProvisioningSuccess      persistentvolumeclaim/fio-smallfile-lifecycle-pvc-4          provisioned a volume
52m         Normal    ProvisioningSuccess      persistentvolumeclaim/fio-smallfile-lifecycle-pvc-5          provisioned a volume
52m         Normal    ProvisioningSucceeded    persistentvolumeclaim/fio-smallfile-lifecycle-pvc-5          Successfully provisioned volume pvc-bb6b15e5-907b-4d27-bd35-e97834a0b5ea
52m         Normal    ExternalProvisioning     persistentvolumeclaim/fio-smallfile-lifecycle-pvc-2          Waiting for a volume to be created either by the external provisioner 'csi.trident.netapp.io' or manually by the system administrator. If volume creation is delayed, please verify that the provisioner is running and correctly registered.
52m         Normal    ExternalProvisioning     persistentvolumeclaim/fio-smallfile-lifecycle-pvc-0          Waiting for a volume to be created either by the external provisioner 'csi.trident.netapp.io' or manually by the system administrator. If volume creation is delayed, please verify that the provisioner is running and correctly registered.
52m         Normal    ProvisioningSuccess      persistentvolumeclaim/fio-smallfile-lifecycle-pvc-0          provisioned a volume
52m         Normal    ProvisioningSucceeded    persistentvolumeclaim/fio-smallfile-lifecycle-pvc-0          Successfully provisioned volume pvc-fb1d96da-3669-4cc8-a689-da8f25857312
52m         Normal    ProvisioningSucceeded    persistentvolumeclaim/fio-smallfile-lifecycle-pvc-2          Successfully provisioned volume pvc-410f068c-3a2e-49e4-8903-bb2f68a16087
52m         Normal    ProvisioningSuccess      persistentvolumeclaim/fio-smallfile-lifecycle-pvc-2          provisioned a volume
52m         Normal    ExternalProvisioning     persistentvolumeclaim/fio-smallfile-lifecycle-pvc-7          Waiting for a volume to be created either by the external provisioner 'csi.trident.netapp.io' or manually by the system administrator. If volume creation is delayed, please verify that the provisioner is running and correctly registered.
52m         Normal    ExternalProvisioning     persistentvolumeclaim/fio-smallfile-lifecycle-pvc-6          Waiting for a volume to be created either by the external provisioner 'csi.trident.netapp.io' or manually by the system administrator. If volume creation is delayed, please verify that the provisioner is running and correctly registered.
52m         Normal    ProvisioningSucceeded    persistentvolumeclaim/fio-smallfile-lifecycle-pvc-6          Successfully provisioned volume pvc-deb228cb-82f5-4829-9945-3e62f4a9dead
52m         Normal    ProvisioningSuccess      persistentvolumeclaim/fio-smallfile-lifecycle-pvc-6          provisioned a volume
52m         Normal    SuccessfulAttachVolume   pod/fio-smallfile-lifecycle-3                                AttachVolume.Attach succeeded for volume "pvc-655081cc-fc2d-4cd6-8075-cba4c17ed37b"
52m         Normal    ProvisioningSuccess      persistentvolumeclaim/fio-smallfile-lifecycle-pvc-7          provisioned a volume
52m         Normal    ProvisioningSucceeded    persistentvolumeclaim/fio-smallfile-lifecycle-pvc-7          Successfully provisioned volume pvc-cbd2af23-0467-4c01-a059-a18e9c850055
52m         Normal    Started                  pod/fio-smallfile-lifecycle-3                                Container started
52m         Normal    Created                  pod/fio-smallfile-lifecycle-3                                Container created
52m         Normal    Pulled                   pod/fio-smallfile-lifecycle-3                                Container image "rafmoshe2500/fio:3.41" already present on machine and can be accessed by the pod
52m         Normal    AddedInterface           pod/fio-smallfile-lifecycle-3                                Add eth0 [10.130.0.98/23] from ovn-kubernetes
52m         Normal    SuccessfulAttachVolume   pod/fio-smallfile-lifecycle-8                                AttachVolume.Attach succeeded for volume "pvc-0f2c76c6-b527-4d31-8820-cc043099cec0"
52m         Normal    Pulled                   pod/fio-smallfile-lifecycle-8                                Container image "rafmoshe2500/fio:3.41" already present on machine and can be accessed by the pod
52m         Normal    Started                  pod/fio-smallfile-lifecycle-8                                Container started
52m         Normal    Created                  pod/fio-smallfile-lifecycle-8                                Container created
52m         Normal    AddedInterface           pod/fio-smallfile-lifecycle-8                                Add eth0 [10.129.0.218/23] from ovn-kubernetes
52m         Normal    ExternalProvisioning     persistentvolumeclaim/fio-smallfile-lifecycle-pvc-1          Waiting for a volume to be created either by the external provisioner 'csi.trident.netapp.io' or manually by the system administrator. If volume creation is delayed, please verify that the provisioner is running and correctly registered.
52m         Normal    SuccessfulAttachVolume   pod/fio-smallfile-lifecycle-0                                AttachVolume.Attach succeeded for volume "pvc-fb1d96da-3669-4cc8-a689-da8f25857312"
52m         Normal    ProvisioningSuccess      persistentvolumeclaim/fio-smallfile-lifecycle-pvc-1          provisioned a volume
52m         Normal    ProvisioningSucceeded    persistentvolumeclaim/fio-smallfile-lifecycle-pvc-1          Successfully provisioned volume pvc-e9e4cf6c-173b-46c0-8cbb-9cbc27ffaa14
52m         Normal    SuccessfulAttachVolume   pod/fio-smallfile-lifecycle-1                                AttachVolume.Attach succeeded for volume "pvc-e9e4cf6c-173b-46c0-8cbb-9cbc27ffaa14"
52m         Normal    SuccessfulAttachVolume   pod/fio-smallfile-lifecycle-5                                AttachVolume.Attach succeeded for volume "pvc-bb6b15e5-907b-4d27-bd35-e97834a0b5ea"
51m         Normal    AddedInterface           pod/fio-smallfile-lifecycle-9                                Add eth0 [10.128.0.188/23] from ovn-kubernetes
51m         Normal    Created                  pod/fio-smallfile-lifecycle-5                                Container created
51m         Normal    Pulled                   pod/fio-smallfile-lifecycle-5                                Container image "rafmoshe2500/fio:3.41" already present on machine and can be accessed by the pod
51m         Normal    AddedInterface           pod/fio-smallfile-lifecycle-5                                Add eth0 [10.128.0.189/23] from ovn-kubernetes
51m         Normal    Started                  pod/fio-smallfile-lifecycle-5                                Container started
51m         Normal    Pulled                   pod/fio-smallfile-lifecycle-4                                Container image "rafmoshe2500/fio:3.41" already present on machine and can be accessed by the pod
51m         Normal    AddedInterface           pod/fio-smallfile-lifecycle-4                                Add eth0 [10.130.0.99/23] from ovn-kubernetes
51m         Normal    SuccessfulAttachVolume   pod/fio-smallfile-lifecycle-4                                AttachVolume.Attach succeeded for volume "pvc-5f303ecf-3d4f-4df9-b50c-f7dac8b3f413"
51m         Normal    SuccessfulAttachVolume   pod/fio-smallfile-lifecycle-6                                AttachVolume.Attach succeeded for volume "pvc-deb228cb-82f5-4829-9945-3e62f4a9dead"
51m         Normal    AddedInterface           pod/fio-smallfile-lifecycle-6                                Add eth0 [10.129.0.220/23] from ovn-kubernetes
51m         Normal    AddedInterface           pod/fio-smallfile-lifecycle-7                                Add eth0 [10.128.0.190/23] from ovn-kubernetes
51m         Normal    Pulled                   pod/fio-smallfile-lifecycle-7                                Container image "rafmoshe2500/fio:3.41" already present on machine and can be accessed by the pod
51m         Normal    SuccessfulAttachVolume   pod/fio-smallfile-lifecycle-9                                AttachVolume.Attach succeeded for volume "pvc-600ff259-9d00-4607-81eb-2325a268f76f"
51m         Normal    SuccessfulAttachVolume   pod/fio-smallfile-lifecycle-7                                AttachVolume.Attach succeeded for volume "pvc-cbd2af23-0467-4c01-a059-a18e9c850055"
51m         Normal    Pulled                   pod/fio-smallfile-lifecycle-9                                Container image "rafmoshe2500/fio:3.41" already present on machine and can be accessed by the pod
51m         Normal    AddedInterface           pod/fio-smallfile-lifecycle-0                                Add eth0 [10.129.0.219/23] from ovn-kubernetes
51m         Normal    Pulled                   pod/fio-smallfile-lifecycle-0                                Container image "rafmoshe2500/fio:3.41" already present on machine and can be accessed by the pod
51m         Normal    Created                  pod/fio-smallfile-lifecycle-0                                Container created
51m         Normal    AddedInterface           pod/fio-smallfile-lifecycle-2                                Add eth0 [10.130.0.100/23] from ovn-kubernetes
51m         Normal    SuccessfulAttachVolume   pod/fio-smallfile-lifecycle-2                                AttachVolume.Attach succeeded for volume "pvc-410f068c-3a2e-49e4-8903-bb2f68a16087"
51m         Normal    Started                  pod/fio-smallfile-lifecycle-0                                Container started
51m         Normal    Started                  pod/fio-smallfile-lifecycle-2                                Container started
51m         Normal    Created                  pod/fio-smallfile-lifecycle-2                                Container created
51m         Normal    Created                  pod/fio-smallfile-lifecycle-6                                Container created
51m         Normal    Pulled                   pod/fio-smallfile-lifecycle-6                                Container image "rafmoshe2500/fio:3.41" already present on machine and can be accessed by the pod
51m         Normal    Started                  pod/fio-smallfile-lifecycle-4                                Container started
51m         Normal    Created                  pod/fio-smallfile-lifecycle-4                                Container created
51m         Normal    Created                  pod/fio-smallfile-lifecycle-7                                Container created
51m         Normal    Started                  pod/fio-smallfile-lifecycle-6                                Container started
51m         Normal    Pulled                   pod/fio-smallfile-lifecycle-2                                Container image "rafmoshe2500/fio:3.41" already present on machine and can be accessed by the pod
51m         Normal    Started                  pod/fio-smallfile-lifecycle-7                                Container started
51m         Normal    Started                  pod/fio-smallfile-lifecycle-1                                Container started
51m         Normal    Created                  pod/fio-smallfile-lifecycle-1                                Container created
51m         Normal    Pulled                   pod/fio-smallfile-lifecycle-1                                Container image "rafmoshe2500/fio:3.41" already present on machine and can be accessed by the pod
51m         Normal    Started                  pod/fio-smallfile-lifecycle-9                                Container started
51m         Normal    Created                  pod/fio-smallfile-lifecycle-9                                Container created
51m         Normal    AddedInterface           pod/fio-smallfile-lifecycle-1                                Add eth0 [10.130.0.101/23] from ovn-kubernetes
16m         Normal    Killing                  pod/fio-smallfile-lifecycle-2                                Stopping container fio
16m         Normal    Killing                  pod/fio-smallfile-lifecycle-9                                Stopping container fio
16m         Normal    Killing                  pod/fio-smallfile-lifecycle-5                                Stopping container fio
16m         Normal    Killing                  pod/fio-smallfile-lifecycle-4                                Stopping container fio
16m         Normal    Killing                  pod/fio-smallfile-lifecycle-8                                Stopping container fio
16m         Normal    Killing                  pod/fio-smallfile-lifecycle-7                                Stopping container fio
16m         Normal    Killing                  pod/fio-smallfile-lifecycle-6                                Stopping container fio
16m         Normal    Killing                  pod/fio-smallfile-lifecycle-1                                Stopping container fio
16m         Normal    Killing                  pod/fio-smallfile-lifecycle-0                                Stopping container fio
16m         Normal    Killing                  pod/fio-smallfile-lifecycle-3                                Stopping container fio
14m         Normal    Provisioning             persistentvolumeclaim/fio-test2-10pods-30k-5050-32kb-pvc-5   External provisioner is provisioning volume for claim "fio-tests/fio-test2-10pods-30k-5050-32kb-pvc-5"
14m         Normal    Provisioning             persistentvolumeclaim/fio-test2-10pods-30k-5050-32kb-pvc-4   External provisioner is provisioning volume for claim "fio-tests/fio-test2-10pods-30k-5050-32kb-pvc-4"
14m         Normal    Provisioning             persistentvolumeclaim/fio-test2-10pods-30k-5050-32kb-pvc-0   External provisioner is provisioning volume for claim "fio-tests/fio-test2-10pods-30k-5050-32kb-pvc-0"
14m         Normal    Provisioning             persistentvolumeclaim/fio-test2-10pods-30k-5050-32kb-pvc-6   External provisioner is provisioning volume for claim "fio-tests/fio-test2-10pods-30k-5050-32kb-pvc-6"
14m         Normal    Provisioning             persistentvolumeclaim/fio-test2-10pods-30k-5050-32kb-pvc-3   External provisioner is provisioning volume for claim "fio-tests/fio-test2-10pods-30k-5050-32kb-pvc-3"
14m         Normal    Provisioning             persistentvolumeclaim/fio-test2-10pods-30k-5050-32kb-pvc-7   External provisioner is provisioning volume for claim "fio-tests/fio-test2-10pods-30k-5050-32kb-pvc-7"
14m         Normal    Provisioning             persistentvolumeclaim/fio-test2-10pods-30k-5050-32kb-pvc-2   External provisioner is provisioning volume for claim "fio-tests/fio-test2-10pods-30k-5050-32kb-pvc-2"
14m         Normal    Provisioning             persistentvolumeclaim/fio-test2-10pods-30k-5050-32kb-pvc-1   External provisioner is provisioning volume for claim "fio-tests/fio-test2-10pods-30k-5050-32kb-pvc-1"
14m         Normal    Provisioning             persistentvolumeclaim/fio-test2-10pods-30k-5050-32kb-pvc-8   External provisioner is provisioning volume for claim "fio-tests/fio-test2-10pods-30k-5050-32kb-pvc-8"
14m         Normal    Provisioning             persistentvolumeclaim/fio-test2-10pods-30k-5050-32kb-pvc-9   External provisioner is provisioning volume for claim "fio-tests/fio-test2-10pods-30k-5050-32kb-pvc-9"
14m         Normal    ExternalProvisioning     persistentvolumeclaim/fio-test2-10pods-30k-5050-32kb-pvc-2   Waiting for a volume to be created either by the external provisioner 'csi.trident.netapp.io' or manually by the system administrator. If volume creation is delayed, please verify that the provisioner is running and correctly registered.
14m         Normal    ExternalProvisioning     persistentvolumeclaim/fio-test2-10pods-30k-5050-32kb-pvc-4   Waiting for a volume to be created either by the external provisioner 'csi.trident.netapp.io' or manually by the system administrator. If volume creation is delayed, please verify that the provisioner is running and correctly registered.
14m         Normal    ExternalProvisioning     persistentvolumeclaim/fio-test2-10pods-30k-5050-32kb-pvc-5   Waiting for a volume to be created either by the external provisioner 'csi.trident.netapp.io' or manually by the system administrator. If volume creation is delayed, please verify that the provisioner is running and correctly registered.
14m         Normal    ProvisioningSucceeded    persistentvolumeclaim/fio-test2-10pods-30k-5050-32kb-pvc-2   Successfully provisioned volume pvc-6239c5d5-054a-46fc-8d6b-2056f4d471d9
14m         Normal    ProvisioningSuccess      persistentvolumeclaim/fio-test2-10pods-30k-5050-32kb-pvc-2   provisioned a volume
14m         Normal    ProvisioningSucceeded    persistentvolumeclaim/fio-test2-10pods-30k-5050-32kb-pvc-4   Successfully provisioned volume pvc-48256d73-6d9a-4b73-9eb0-436a53638eb7
14m         Normal    ProvisioningSuccess      persistentvolumeclaim/fio-test2-10pods-30k-5050-32kb-pvc-4   provisioned a volume
14m         Normal    ProvisioningSucceeded    persistentvolumeclaim/fio-test2-10pods-30k-5050-32kb-pvc-5   Successfully provisioned volume pvc-11273b78-496e-44fb-ad61-8886b8561180
14m         Normal    ProvisioningSuccess      persistentvolumeclaim/fio-test2-10pods-30k-5050-32kb-pvc-5   provisioned a volume
14m         Normal    ExternalProvisioning     persistentvolumeclaim/fio-test2-10pods-30k-5050-32kb-pvc-8   Waiting for a volume to be created either by the external provisioner 'csi.trident.netapp.io' or manually by the system administrator. If volume creation is delayed, please verify that the provisioner is running and correctly registered.
14m         Normal    ExternalProvisioning     persistentvolumeclaim/fio-test2-10pods-30k-5050-32kb-pvc-0   Waiting for a volume to be created either by the external provisioner 'csi.trident.netapp.io' or manually by the system administrator. If volume creation is delayed, please verify that the provisioner is running and correctly registered.
14m         Normal    ProvisioningSuccess      persistentvolumeclaim/fio-test2-10pods-30k-5050-32kb-pvc-8   provisioned a volume
14m         Normal    ProvisioningSucceeded    persistentvolumeclaim/fio-test2-10pods-30k-5050-32kb-pvc-8   Successfully provisioned volume pvc-54a0990d-b00d-4f5b-ba11-c8e10b1f7dfd
14m         Normal    ProvisioningSuccess      persistentvolumeclaim/fio-test2-10pods-30k-5050-32kb-pvc-0   provisioned a volume
14m         Normal    ProvisioningSucceeded    persistentvolumeclaim/fio-test2-10pods-30k-5050-32kb-pvc-0   Successfully provisioned volume pvc-226f1b0e-5340-4861-8edf-67711217238c
14m         Normal    ExternalProvisioning     persistentvolumeclaim/fio-test2-10pods-30k-5050-32kb-pvc-6   Waiting for a volume to be created either by the external provisioner 'csi.trident.netapp.io' or manually by the system administrator. If volume creation is delayed, please verify that the provisioner is running and correctly registered.
14m         Normal    ExternalProvisioning     persistentvolumeclaim/fio-test2-10pods-30k-5050-32kb-pvc-7   Waiting for a volume to be created either by the external provisioner 'csi.trident.netapp.io' or manually by the system administrator. If volume creation is delayed, please verify that the provisioner is running and correctly registered.
14m         Normal    ExternalProvisioning     persistentvolumeclaim/fio-test2-10pods-30k-5050-32kb-pvc-3   Waiting for a volume to be created either by the external provisioner 'csi.trident.netapp.io' or manually by the system administrator. If volume creation is delayed, please verify that the provisioner is running and correctly registered.
14m         Normal    ProvisioningSuccess      persistentvolumeclaim/fio-test2-10pods-30k-5050-32kb-pvc-3   provisioned a volume
14m         Normal    ProvisioningSucceeded    persistentvolumeclaim/fio-test2-10pods-30k-5050-32kb-pvc-3   Successfully provisioned volume pvc-36d17130-938b-4f11-a3a6-252c42ac0d75
14m         Normal    ProvisioningSuccess      persistentvolumeclaim/fio-test2-10pods-30k-5050-32kb-pvc-6   provisioned a volume
14m         Normal    ProvisioningSucceeded    persistentvolumeclaim/fio-test2-10pods-30k-5050-32kb-pvc-6   Successfully provisioned volume pvc-59e45520-d059-48b9-b5e3-69c37a2f1645
14m         Normal    ExternalProvisioning     persistentvolumeclaim/fio-test2-10pods-30k-5050-32kb-pvc-9   Waiting for a volume to be created either by the external provisioner 'csi.trident.netapp.io' or manually by the system administrator. If volume creation is delayed, please verify that the provisioner is running and correctly registered.
14m         Normal    ExternalProvisioning     persistentvolumeclaim/fio-test2-10pods-30k-5050-32kb-pvc-1   Waiting for a volume to be created either by the external provisioner 'csi.trident.netapp.io' or manually by the system administrator. If volume creation is delayed, please verify that the provisioner is running and correctly registered.
14m         Normal    ProvisioningSucceeded    persistentvolumeclaim/fio-test2-10pods-30k-5050-32kb-pvc-7   Successfully provisioned volume pvc-6e72926d-4a54-4cdc-b4d6-f8c5b966418a
14m         Normal    ProvisioningSuccess      persistentvolumeclaim/fio-test2-10pods-30k-5050-32kb-pvc-7   provisioned a volume
13m         Normal    ProvisioningSuccess      persistentvolumeclaim/fio-test2-10pods-30k-5050-32kb-pvc-9   provisioned a volume
13m         Normal    ProvisioningSucceeded    persistentvolumeclaim/fio-test2-10pods-30k-5050-32kb-pvc-9   Successfully provisioned volume pvc-5a6486a3-7c80-4b66-ac5d-caf45fe883d3
13m         Normal    ProvisioningSuccess      persistentvolumeclaim/fio-test2-10pods-30k-5050-32kb-pvc-1   provisioned a volume
13m         Normal    ProvisioningSucceeded    persistentvolumeclaim/fio-test2-10pods-30k-5050-32kb-pvc-1   Successfully provisioned volume pvc-5e8d7886-eb4b-4f99-b396-b57a9ff0d377
13m         Normal    SuccessfulAttachVolume   pod/fio-test2-10pods-30k-5050-32kb-4                         AttachVolume.Attach succeeded for volume "pvc-48256d73-6d9a-4b73-9eb0-436a53638eb7"
13m         Normal    SuccessfulAttachVolume   pod/fio-test2-10pods-30k-5050-32kb-8                         AttachVolume.Attach succeeded for volume "pvc-54a0990d-b00d-4f5b-ba11-c8e10b1f7dfd"
13m         Normal    SuccessfulAttachVolume   pod/fio-test2-10pods-30k-5050-32kb-3                         AttachVolume.Attach succeeded for volume "pvc-36d17130-938b-4f11-a3a6-252c42ac0d75"
13m         Normal    SuccessfulAttachVolume   pod/fio-test2-10pods-30k-5050-32kb-1                         AttachVolume.Attach succeeded for volume "pvc-5e8d7886-eb4b-4f99-b396-b57a9ff0d377"
13m         Normal    SuccessfulAttachVolume   pod/fio-test2-10pods-30k-5050-32kb-7                         AttachVolume.Attach succeeded for volume "pvc-6e72926d-4a54-4cdc-b4d6-f8c5b966418a"
13m         Normal    SuccessfulAttachVolume   pod/fio-test2-10pods-30k-5050-32kb-9                         AttachVolume.Attach succeeded for volume "pvc-5a6486a3-7c80-4b66-ac5d-caf45fe883d3"
13m         Normal    SuccessfulAttachVolume   pod/fio-test2-10pods-30k-5050-32kb-6                         AttachVolume.Attach succeeded for volume "pvc-59e45520-d059-48b9-b5e3-69c37a2f1645"
13m         Normal    SuccessfulAttachVolume   pod/fio-test2-10pods-30k-5050-32kb-2                         AttachVolume.Attach succeeded for volume "pvc-6239c5d5-054a-46fc-8d6b-2056f4d471d9"
13m         Normal    Pulled                   pod/fio-test2-10pods-30k-5050-32kb-3                         Container image "rafmoshe2500/fio:3.41" already present on machine and can be accessed by the pod
13m         Normal    AddedInterface           pod/fio-test2-10pods-30k-5050-32kb-0                         Add eth0 [10.128.0.192/23] from ovn-kubernetes
13m         Normal    Created                  pod/fio-test2-10pods-30k-5050-32kb-4                         Container created
13m         Normal    Created                  pod/fio-test2-10pods-30k-5050-32kb-0                         Container created
13m         Normal    Started                  pod/fio-test2-10pods-30k-5050-32kb-0                         Container started
13m         Normal    AddedInterface           pod/fio-test2-10pods-30k-5050-32kb-2                         Add eth0 [10.130.0.102/23] from ovn-kubernetes
13m         Normal    Pulled                   pod/fio-test2-10pods-30k-5050-32kb-2                         Container image "rafmoshe2500/fio:3.41" already present on machine and can be accessed by the pod
13m         Normal    Pulled                   pod/fio-test2-10pods-30k-5050-32kb-4                         Container image "rafmoshe2500/fio:3.41" already present on machine and can be accessed by the pod
13m         Normal    Created                  pod/fio-test2-10pods-30k-5050-32kb-2                         Container created
13m         Normal    Started                  pod/fio-test2-10pods-30k-5050-32kb-8                         Container started
13m         Normal    Pulled                   pod/fio-test2-10pods-30k-5050-32kb-0                         Container image "rafmoshe2500/fio:3.41" already present on machine and can be accessed by the pod
13m         Normal    AddedInterface           pod/fio-test2-10pods-30k-5050-32kb-4                         Add eth0 [10.129.0.221/23] from ovn-kubernetes
13m         Normal    Created                  pod/fio-test2-10pods-30k-5050-32kb-8                         Container created
13m         Normal    Pulled                   pod/fio-test2-10pods-30k-5050-32kb-8                         Container image "rafmoshe2500/fio:3.41" already present on machine and can be accessed by the pod
13m         Normal    AddedInterface           pod/fio-test2-10pods-30k-5050-32kb-6                         Add eth0 [10.130.0.104/23] from ovn-kubernetes
13m         Normal    AddedInterface           pod/fio-test2-10pods-30k-5050-32kb-8                         Add eth0 [10.130.0.103/23] from ovn-kubernetes
13m         Normal    Started                  pod/fio-test2-10pods-30k-5050-32kb-2                         Container started
13m         Normal    AddedInterface           pod/fio-test2-10pods-30k-5050-32kb-3                         Add eth0 [10.129.0.222/23] from ovn-kubernetes
13m         Normal    Started                  pod/fio-test2-10pods-30k-5050-32kb-7                         Container started
13m         Normal    Pulled                   pod/fio-test2-10pods-30k-5050-32kb-6                         Container image "rafmoshe2500/fio:3.41" already present on machine and can be accessed by the pod
13m         Normal    Created                  pod/fio-test2-10pods-30k-5050-32kb-7                         Container created
13m         Normal    Pulled                   pod/fio-test2-10pods-30k-5050-32kb-7                         Container image "rafmoshe2500/fio:3.41" already present on machine and can be accessed by the pod
13m         Normal    Started                  pod/fio-test2-10pods-30k-5050-32kb-4                         Container started
13m         Normal    Created                  pod/fio-test2-10pods-30k-5050-32kb-3                         Container created
13m         Normal    Started                  pod/fio-test2-10pods-30k-5050-32kb-3                         Container started
13m         Normal    AddedInterface           pod/fio-test2-10pods-30k-5050-32kb-7                         Add eth0 [10.129.0.223/23] from ovn-kubernetes
13m         Normal    SuccessfulAttachVolume   pod/fio-test2-10pods-30k-5050-32kb-0                         AttachVolume.Attach succeeded for volume "pvc-226f1b0e-5340-4861-8edf-67711217238c"
13m         Normal    Started                  pod/fio-test2-10pods-30k-5050-32kb-6                         Container started
13m         Normal    Created                  pod/fio-test2-10pods-30k-5050-32kb-6                         Container created
13m         Normal    SuccessfulAttachVolume   pod/fio-test2-10pods-30k-5050-32kb-5                         AttachVolume.Attach succeeded for volume "pvc-11273b78-496e-44fb-ad61-8886b8561180"
13m         Normal    AddedInterface           pod/fio-test2-10pods-30k-5050-32kb-5                         Add eth0 [10.128.0.191/23] from ovn-kubernetes
13m         Normal    Pulled                   pod/fio-test2-10pods-30k-5050-32kb-5                         Container image "rafmoshe2500/fio:3.41" already present on machine and can be accessed by the pod
13m         Normal    Started                  pod/fio-test2-10pods-30k-5050-32kb-5                         Container started
13m         Normal    Created                  pod/fio-test2-10pods-30k-5050-32kb-5                         Container created
13m         Normal    Pulled                   pod/fio-test2-10pods-30k-5050-32kb-9                         Container image "rafmoshe2500/fio:3.41" already present on machine and can be accessed by the pod
13m         Normal    AddedInterface           pod/fio-test2-10pods-30k-5050-32kb-9                         Add eth0 [10.128.0.193/23] from ovn-kubernetes
13m         Normal    Started                  pod/fio-test2-10pods-30k-5050-32kb-9                         Container started
13m         Normal    Created                  pod/fio-test2-10pods-30k-5050-32kb-9                         Container created
13m         Normal    Started                  pod/fio-test2-10pods-30k-5050-32kb-1                         Container started
13m         Normal    Created                  pod/fio-test2-10pods-30k-5050-32kb-1                         Container created
13m         Normal    AddedInterface           pod/fio-test2-10pods-30k-5050-32kb-1                         Add eth0 [10.130.0.105/23] from ovn-kubernetes
13m         Normal    Pulled                   pod/fio-test2-10pods-30k-5050-32kb-1                         Container image "rafmoshe2500/fio:3.41" already present on machine and can be accessed by the pod
