LAST SEEN   TYPE      REASON                   OBJECT                                                       MESSAGE
99m         Warning   FailedScheduling         pod/fio-sync-write-0                                         0/3 nodes are available: pod has unbound immediate PersistentVolumeClaims. not found
46m         Normal    Scheduled                pod/fio-test2-10pods-30k-5050-32kb-8                         Successfully assigned fio-tests/fio-test2-10pods-30k-5050-32kb-8 to s1
128m        Normal    Scheduled                pod/fio-low-qd-latency-0                                     Successfully assigned fio-tests/fio-low-qd-latency-0 to s1
14m         Normal    Scheduled                pod/fio-test7-1pod-max-write-4kb-0                           Successfully assigned fio-tests/fio-test7-1pod-max-write-4kb-0 to s1
14m         Warning   FailedScheduling         pod/fio-test7-1pod-max-write-4kb-0                           0/3 nodes are available: pod has unbound immediate PersistentVolumeClaims. not found
14m         Warning   FailedScheduling         pod/fio-test7-1pod-max-write-4kb-0                           0/3 nodes are available: pod has unbound immediate PersistentVolumeClaims. not found
30m         Normal    Scheduled                pod/fio-test4-10pods-50k-5050-32kb-9                         Successfully assigned fio-tests/fio-test4-10pods-50k-5050-32kb-9 to s3
30m         Warning   FailedScheduling         pod/fio-test4-10pods-50k-5050-32kb-9                         0/3 nodes are available: pod has unbound immediate PersistentVolumeClaims. not found
129m        Warning   FailedScheduling         pod/fio-low-qd-latency-1                                     0/3 nodes are available: pod has unbound immediate PersistentVolumeClaims. not found
128m        Warning   FailedScheduling         pod/fio-low-qd-latency-1                                     0/3 nodes are available: pod has unbound immediate PersistentVolumeClaims. not found
128m        Normal    Scheduled                pod/fio-low-qd-latency-1                                     Successfully assigned fio-tests/fio-low-qd-latency-1 to s1
31m         Warning   FailedScheduling         pod/fio-test4-10pods-50k-5050-32kb-9                         0/3 nodes are available: pod has unbound immediate PersistentVolumeClaims. not found
31m         Normal    Scheduled                pod/fio-test4-10pods-50k-5050-32kb-8                         Successfully assigned fio-tests/fio-test4-10pods-50k-5050-32kb-8 to s1
31m         Warning   FailedScheduling         pod/fio-test4-10pods-50k-5050-32kb-8                         0/3 nodes are available: pod has unbound immediate PersistentVolumeClaims. not found
31m         Warning   FailedScheduling         pod/fio-test4-10pods-50k-5050-32kb-8                         0/3 nodes are available: pod has unbound immediate PersistentVolumeClaims. not found
30m         Normal    Scheduled                pod/fio-test4-10pods-50k-5050-32kb-7                         Successfully assigned fio-tests/fio-test4-10pods-50k-5050-32kb-7 to s1
129m        Warning   FailedScheduling         pod/fio-low-qd-latency-2                                     0/3 nodes are available: pod has unbound immediate PersistentVolumeClaims. not found
128m        Warning   FailedScheduling         pod/fio-low-qd-latency-2                                     0/3 nodes are available: pod has unbound immediate PersistentVolumeClaims. not found
128m        Normal    Scheduled                pod/fio-low-qd-latency-2                                     Successfully assigned fio-tests/fio-low-qd-latency-2 to s3
30m         Warning   FailedScheduling         pod/fio-test4-10pods-50k-5050-32kb-7                         0/3 nodes are available: pod has unbound immediate PersistentVolumeClaims. not found
31m         Warning   FailedScheduling         pod/fio-test4-10pods-50k-5050-32kb-7                         0/3 nodes are available: pod has unbound immediate PersistentVolumeClaims. not found
30m         Normal    Scheduled                pod/fio-test4-10pods-50k-5050-32kb-6                         Successfully assigned fio-tests/fio-test4-10pods-50k-5050-32kb-6 to s1
30m         Warning   FailedScheduling         pod/fio-test4-10pods-50k-5050-32kb-6                         0/3 nodes are available: pod has unbound immediate PersistentVolumeClaims. not found
31m         Warning   FailedScheduling         pod/fio-test4-10pods-50k-5050-32kb-6                         0/3 nodes are available: pod has unbound immediate PersistentVolumeClaims. not found
129m        Warning   FailedScheduling         pod/fio-low-qd-latency-3                                     0/3 nodes are available: pod has unbound immediate PersistentVolumeClaims. not found
129m        Warning   FailedScheduling         pod/fio-low-qd-latency-3                                     0/3 nodes are available: pod has unbound immediate PersistentVolumeClaims. not found
129m        Normal    Scheduled                pod/fio-low-qd-latency-3                                     Successfully assigned fio-tests/fio-low-qd-latency-3 to s1
30m         Normal    Scheduled                pod/fio-test4-10pods-50k-5050-32kb-5                         Successfully assigned fio-tests/fio-test4-10pods-50k-5050-32kb-5 to s1
30m         Warning   FailedScheduling         pod/fio-test4-10pods-50k-5050-32kb-5                         0/3 nodes are available: pod has unbound immediate PersistentVolumeClaims. not found
31m         Warning   FailedScheduling         pod/fio-test4-10pods-50k-5050-32kb-5                         0/3 nodes are available: pod has unbound immediate PersistentVolumeClaims. not found
30m         Normal    Scheduled                pod/fio-test4-10pods-50k-5050-32kb-4                         Successfully assigned fio-tests/fio-test4-10pods-50k-5050-32kb-4 to s2
30m         Warning   FailedScheduling         pod/fio-test4-10pods-50k-5050-32kb-4                         0/3 nodes are available: pod has unbound immediate PersistentVolumeClaims. not found
129m        Warning   FailedScheduling         pod/fio-low-qd-latency-4                                     0/3 nodes are available: pod has unbound immediate PersistentVolumeClaims. not found
128m        Warning   FailedScheduling         pod/fio-low-qd-latency-4                                     0/3 nodes are available: pod has unbound immediate PersistentVolumeClaims. not found
128m        Normal    Scheduled                pod/fio-low-qd-latency-4                                     Successfully assigned fio-tests/fio-low-qd-latency-4 to s3
31m         Warning   FailedScheduling         pod/fio-test4-10pods-50k-5050-32kb-4                         0/3 nodes are available: pod has unbound immediate PersistentVolumeClaims. not found
30m         Normal    Scheduled                pod/fio-test4-10pods-50k-5050-32kb-3                         Successfully assigned fio-tests/fio-test4-10pods-50k-5050-32kb-3 to s3
30m         Warning   FailedScheduling         pod/fio-test4-10pods-50k-5050-32kb-3                         0/3 nodes are available: pod has unbound immediate PersistentVolumeClaims. not found
31m         Warning   FailedScheduling         pod/fio-test4-10pods-50k-5050-32kb-3                         0/3 nodes are available: pod has unbound immediate PersistentVolumeClaims. not found
30m         Normal    Scheduled                pod/fio-test4-10pods-50k-5050-32kb-2                         Successfully assigned fio-tests/fio-test4-10pods-50k-5050-32kb-2 to s2
129m        Warning   FailedScheduling         pod/fio-low-qd-latency-5                                     0/3 nodes are available: pod has unbound immediate PersistentVolumeClaims. not found
128m        Warning   FailedScheduling         pod/fio-low-qd-latency-5                                     0/3 nodes are available: pod has unbound immediate PersistentVolumeClaims. not found
128m        Normal    Scheduled                pod/fio-low-qd-latency-5                                     Successfully assigned fio-tests/fio-low-qd-latency-5 to s1
30m         Warning   FailedScheduling         pod/fio-test4-10pods-50k-5050-32kb-2                         0/3 nodes are available: pod has unbound immediate PersistentVolumeClaims. not found
31m         Warning   FailedScheduling         pod/fio-test4-10pods-50k-5050-32kb-2                         0/3 nodes are available: pod has unbound immediate PersistentVolumeClaims. not found
30m         Normal    Scheduled                pod/fio-test4-10pods-50k-5050-32kb-1                         Successfully assigned fio-tests/fio-test4-10pods-50k-5050-32kb-1 to s3
30m         Warning   FailedScheduling         pod/fio-test4-10pods-50k-5050-32kb-1                         0/3 nodes are available: pod has unbound immediate PersistentVolumeClaims. not found
31m         Warning   FailedScheduling         pod/fio-test4-10pods-50k-5050-32kb-1                         0/3 nodes are available: pod has unbound immediate PersistentVolumeClaims. not found
129m        Warning   FailedScheduling         pod/fio-low-qd-latency-6                                     0/3 nodes are available: pod has unbound immediate PersistentVolumeClaims. not found
128m        Warning   FailedScheduling         pod/fio-low-qd-latency-6                                     0/3 nodes are available: pod has unbound immediate PersistentVolumeClaims. not found
128m        Normal    Scheduled                pod/fio-low-qd-latency-6                                     Successfully assigned fio-tests/fio-low-qd-latency-6 to s2
30m         Normal    Scheduled                pod/fio-test4-10pods-50k-5050-32kb-0                         Successfully assigned fio-tests/fio-test4-10pods-50k-5050-32kb-0 to s2
30m         Warning   FailedScheduling         pod/fio-test4-10pods-50k-5050-32kb-0                         0/3 nodes are available: pod has unbound immediate PersistentVolumeClaims. not found
31m         Warning   FailedScheduling         pod/fio-test4-10pods-50k-5050-32kb-0                         0/3 nodes are available: pod has unbound immediate PersistentVolumeClaims. not found
46m         Normal    Scheduled                pod/fio-test2-10pods-30k-5050-32kb-9                         Successfully assigned fio-tests/fio-test2-10pods-30k-5050-32kb-9 to s3
46m         Warning   FailedScheduling         pod/fio-test2-10pods-30k-5050-32kb-9                         0/3 nodes are available: pod has unbound immediate PersistentVolumeClaims. not found
129m        Warning   FailedScheduling         pod/fio-low-qd-latency-7                                     0/3 nodes are available: pod has unbound immediate PersistentVolumeClaims. not found
129m        Warning   FailedScheduling         pod/fio-low-qd-latency-7                                     0/3 nodes are available: pod has unbound immediate PersistentVolumeClaims. not found
129m        Normal    Scheduled                pod/fio-low-qd-latency-7                                     Successfully assigned fio-tests/fio-low-qd-latency-7 to s2
47m         Warning   FailedScheduling         pod/fio-test2-10pods-30k-5050-32kb-9                         0/3 nodes are available: pod has unbound immediate PersistentVolumeClaims. not found
128m        Warning   FailedScheduling         pod/fio-low-qd-latency-0                                     0/3 nodes are available: pod has unbound immediate PersistentVolumeClaims. not found
46m         Warning   FailedScheduling         pod/fio-test2-10pods-30k-5050-32kb-8                         0/3 nodes are available: pod has unbound immediate PersistentVolumeClaims. not found
47m         Warning   FailedScheduling         pod/fio-test2-10pods-30k-5050-32kb-8                         0/3 nodes are available: pod has unbound immediate PersistentVolumeClaims. not found
46m         Normal    Scheduled                pod/fio-test2-10pods-30k-5050-32kb-7                         Successfully assigned fio-tests/fio-test2-10pods-30k-5050-32kb-7 to s2
129m        Warning   FailedScheduling         pod/fio-low-qd-latency-8                                     0/3 nodes are available: pod has unbound immediate PersistentVolumeClaims. not found
128m        Warning   FailedScheduling         pod/fio-low-qd-latency-8                                     0/3 nodes are available: pod has unbound immediate PersistentVolumeClaims. not found
128m        Normal    Scheduled                pod/fio-low-qd-latency-8                                     Successfully assigned fio-tests/fio-low-qd-latency-8 to s3
46m         Warning   FailedScheduling         pod/fio-test2-10pods-30k-5050-32kb-7                         0/3 nodes are available: pod has unbound immediate PersistentVolumeClaims. not found
47m         Warning   FailedScheduling         pod/fio-test2-10pods-30k-5050-32kb-7                         0/3 nodes are available: pod has unbound immediate PersistentVolumeClaims. not found
46m         Normal    Scheduled                pod/fio-test2-10pods-30k-5050-32kb-6                         Successfully assigned fio-tests/fio-test2-10pods-30k-5050-32kb-6 to s1
46m         Warning   FailedScheduling         pod/fio-test2-10pods-30k-5050-32kb-6                         0/3 nodes are available: pod has unbound immediate PersistentVolumeClaims. not found
47m         Warning   FailedScheduling         pod/fio-test2-10pods-30k-5050-32kb-6                         0/3 nodes are available: pod has unbound immediate PersistentVolumeClaims. not found
129m        Warning   FailedScheduling         pod/fio-low-qd-latency-9                                     0/3 nodes are available: pod has unbound immediate PersistentVolumeClaims. not found
128m        Warning   FailedScheduling         pod/fio-low-qd-latency-9                                     0/3 nodes are available: pod has unbound immediate PersistentVolumeClaims. not found
128m        Normal    Scheduled                pod/fio-low-qd-latency-9                                     Successfully assigned fio-tests/fio-low-qd-latency-9 to s2
46m         Normal    Scheduled                pod/fio-test2-10pods-30k-5050-32kb-5                         Successfully assigned fio-tests/fio-test2-10pods-30k-5050-32kb-5 to s3
46m         Warning   FailedScheduling         pod/fio-test2-10pods-30k-5050-32kb-5                         0/3 nodes are available: pod has unbound immediate PersistentVolumeClaims. not found
47m         Warning   FailedScheduling         pod/fio-test2-10pods-30k-5050-32kb-5                         0/3 nodes are available: pod has unbound immediate PersistentVolumeClaims. not found
46m         Normal    Scheduled                pod/fio-test2-10pods-30k-5050-32kb-4                         Successfully assigned fio-tests/fio-test2-10pods-30k-5050-32kb-4 to s2
46m         Warning   FailedScheduling         pod/fio-test2-10pods-30k-5050-32kb-4                         0/3 nodes are available: pod has unbound immediate PersistentVolumeClaims. not found
47m         Warning   FailedScheduling         pod/fio-test2-10pods-30k-5050-32kb-4                         0/3 nodes are available: pod has unbound immediate PersistentVolumeClaims. not found
46m         Normal    Scheduled                pod/fio-test2-10pods-30k-5050-32kb-3                         Successfully assigned fio-tests/fio-test2-10pods-30k-5050-32kb-3 to s2
46m         Warning   FailedScheduling         pod/fio-test2-10pods-30k-5050-32kb-3                         0/3 nodes are available: pod has unbound immediate PersistentVolumeClaims. not found
47m         Warning   FailedScheduling         pod/fio-test2-10pods-30k-5050-32kb-3                         0/3 nodes are available: pod has unbound immediate PersistentVolumeClaims. not found
47m         Normal    Scheduled                pod/fio-test2-10pods-30k-5050-32kb-2                         Successfully assigned fio-tests/fio-test2-10pods-30k-5050-32kb-2 to s1
47m         Warning   FailedScheduling         pod/fio-test2-10pods-30k-5050-32kb-2                         0/3 nodes are available: pod has unbound immediate PersistentVolumeClaims. not found
47m         Warning   FailedScheduling         pod/fio-test2-10pods-30k-5050-32kb-2                         0/3 nodes are available: pod has unbound immediate PersistentVolumeClaims. not found
46m         Normal    Scheduled                pod/fio-test2-10pods-30k-5050-32kb-1                         Successfully assigned fio-tests/fio-test2-10pods-30k-5050-32kb-1 to s1
46m         Warning   FailedScheduling         pod/fio-test2-10pods-30k-5050-32kb-1                         0/3 nodes are available: pod has unbound immediate PersistentVolumeClaims. not found
47m         Warning   FailedScheduling         pod/fio-test2-10pods-30k-5050-32kb-1                         0/3 nodes are available: pod has unbound immediate PersistentVolumeClaims. not found
46m         Normal    Scheduled                pod/fio-test2-10pods-30k-5050-32kb-0                         Successfully assigned fio-tests/fio-test2-10pods-30k-5050-32kb-0 to s3
46m         Warning   FailedScheduling         pod/fio-test2-10pods-30k-5050-32kb-0                         0/3 nodes are available: pod has unbound immediate PersistentVolumeClaims. not found
47m         Warning   FailedScheduling         pod/fio-test2-10pods-30k-5050-32kb-0                         0/3 nodes are available: pod has unbound immediate PersistentVolumeClaims. not found
100m        Normal    Scheduled                pod/fio-sync-write-9                                         Successfully assigned fio-tests/fio-sync-write-9 to s1
100m        Warning   FailedScheduling         pod/fio-sync-write-9                                         0/3 nodes are available: pod has unbound immediate PersistentVolumeClaims. not found
100m        Warning   FailedScheduling         pod/fio-sync-write-9                                         0/3 nodes are available: pod has unbound immediate PersistentVolumeClaims. not found
99m         Normal    Scheduled                pod/fio-sync-write-8                                         Successfully assigned fio-tests/fio-sync-write-8 to s3
99m         Warning   FailedScheduling         pod/fio-sync-write-8                                         0/3 nodes are available: pod has unbound immediate PersistentVolumeClaims. not found
100m        Warning   FailedScheduling         pod/fio-sync-write-8                                         0/3 nodes are available: pod has unbound immediate PersistentVolumeClaims. not found
99m         Normal    Scheduled                pod/fio-sync-write-7                                         Successfully assigned fio-tests/fio-sync-write-7 to s3
99m         Warning   FailedScheduling         pod/fio-sync-write-7                                         0/3 nodes are available: pod has unbound immediate PersistentVolumeClaims. not found
100m        Warning   FailedScheduling         pod/fio-sync-write-7                                         0/3 nodes are available: pod has unbound immediate PersistentVolumeClaims. not found
99m         Normal    Scheduled                pod/fio-sync-write-6                                         Successfully assigned fio-tests/fio-sync-write-6 to s2
99m         Warning   FailedScheduling         pod/fio-sync-write-6                                         0/3 nodes are available: pod has unbound immediate PersistentVolumeClaims. not found
100m        Warning   FailedScheduling         pod/fio-sync-write-6                                         0/3 nodes are available: pod has unbound immediate PersistentVolumeClaims. not found
99m         Normal    Scheduled                pod/fio-sync-write-5                                         Successfully assigned fio-tests/fio-sync-write-5 to s2
99m         Warning   FailedScheduling         pod/fio-sync-write-5                                         0/3 nodes are available: pod has unbound immediate PersistentVolumeClaims. not found
100m        Warning   FailedScheduling         pod/fio-sync-write-5                                         0/3 nodes are available: pod has unbound immediate PersistentVolumeClaims. not found
99m         Normal    Scheduled                pod/fio-sync-write-4                                         Successfully assigned fio-tests/fio-sync-write-4 to s1
99m         Warning   FailedScheduling         pod/fio-sync-write-4                                         0/3 nodes are available: pod has unbound immediate PersistentVolumeClaims. not found
100m        Warning   FailedScheduling         pod/fio-sync-write-4                                         0/3 nodes are available: pod has unbound immediate PersistentVolumeClaims. not found
99m         Normal    Scheduled                pod/fio-sync-write-3                                         Successfully assigned fio-tests/fio-sync-write-3 to s3
99m         Warning   FailedScheduling         pod/fio-sync-write-3                                         0/3 nodes are available: pod has unbound immediate PersistentVolumeClaims. not found
100m        Warning   FailedScheduling         pod/fio-sync-write-3                                         0/3 nodes are available: pod has unbound immediate PersistentVolumeClaims. not found
99m         Normal    Scheduled                pod/fio-sync-write-2                                         Successfully assigned fio-tests/fio-sync-write-2 to s1
99m         Warning   FailedScheduling         pod/fio-sync-write-2                                         0/3 nodes are available: pod has unbound immediate PersistentVolumeClaims. not found
100m        Warning   FailedScheduling         pod/fio-sync-write-2                                         0/3 nodes are available: pod has unbound immediate PersistentVolumeClaims. not found
100m        Normal    Scheduled                pod/fio-sync-write-1                                         Successfully assigned fio-tests/fio-sync-write-1 to s2
100m        Warning   FailedScheduling         pod/fio-sync-write-1                                         0/3 nodes are available: pod has unbound immediate PersistentVolumeClaims. not found
100m        Warning   FailedScheduling         pod/fio-sync-write-1                                         0/3 nodes are available: pod has unbound immediate PersistentVolumeClaims. not found
119m        Warning   FailedScheduling         pod/fio-max-throughput-0                                     0/3 nodes are available: pod has unbound immediate PersistentVolumeClaims. not found
119m        Warning   FailedScheduling         pod/fio-max-throughput-0                                     0/3 nodes are available: pod has unbound immediate PersistentVolumeClaims. not found
119m        Normal    Scheduled                pod/fio-max-throughput-0                                     Successfully assigned fio-tests/fio-max-throughput-0 to s1
84m         Normal    Scheduled                pod/fio-smallfile-lifecycle-9                                Successfully assigned fio-tests/fio-smallfile-lifecycle-9 to s3
85m         Warning   FailedScheduling         pod/fio-smallfile-lifecycle-9                                0/3 nodes are available: pod has unbound immediate PersistentVolumeClaims. not found
85m         Warning   FailedScheduling         pod/fio-smallfile-lifecycle-9                                0/3 nodes are available: pod has unbound immediate PersistentVolumeClaims. not found
85m         Normal    Scheduled                pod/fio-smallfile-lifecycle-8                                Successfully assigned fio-tests/fio-smallfile-lifecycle-8 to s2
85m         Warning   FailedScheduling         pod/fio-smallfile-lifecycle-8                                0/3 nodes are available: pod has unbound immediate PersistentVolumeClaims. not found
119m        Warning   FailedScheduling         pod/fio-max-throughput-1                                     0/3 nodes are available: pod has unbound immediate PersistentVolumeClaims. not found
118m        Warning   FailedScheduling         pod/fio-max-throughput-1                                     0/3 nodes are available: pod has unbound immediate PersistentVolumeClaims. not found
118m        Normal    Scheduled                pod/fio-max-throughput-1                                     Successfully assigned fio-tests/fio-max-throughput-1 to s2
85m         Warning   FailedScheduling         pod/fio-smallfile-lifecycle-8                                0/3 nodes are available: pod has unbound immediate PersistentVolumeClaims. not found
84m         Normal    Scheduled                pod/fio-smallfile-lifecycle-7                                Successfully assigned fio-tests/fio-smallfile-lifecycle-7 to s3
84m         Warning   FailedScheduling         pod/fio-smallfile-lifecycle-7                                0/3 nodes are available: pod has unbound immediate PersistentVolumeClaims. not found
85m         Warning   FailedScheduling         pod/fio-smallfile-lifecycle-7                                0/3 nodes are available: pod has unbound immediate PersistentVolumeClaims. not found
84m         Normal    Scheduled                pod/fio-smallfile-lifecycle-6                                Successfully assigned fio-tests/fio-smallfile-lifecycle-6 to s2
119m        Warning   FailedScheduling         pod/fio-max-throughput-2                                     0/3 nodes are available: pod has unbound immediate PersistentVolumeClaims. not found
118m        Warning   FailedScheduling         pod/fio-max-throughput-2                                     0/3 nodes are available: pod has unbound immediate PersistentVolumeClaims. not found
118m        Normal    Scheduled                pod/fio-max-throughput-2                                     Successfully assigned fio-tests/fio-max-throughput-2 to s2
84m         Warning   FailedScheduling         pod/fio-smallfile-lifecycle-6                                0/3 nodes are available: pod has unbound immediate PersistentVolumeClaims. not found
85m         Warning   FailedScheduling         pod/fio-smallfile-lifecycle-6                                0/3 nodes are available: pod has unbound immediate PersistentVolumeClaims. not found
84m         Normal    Scheduled                pod/fio-smallfile-lifecycle-5                                Successfully assigned fio-tests/fio-smallfile-lifecycle-5 to s3
84m         Warning   FailedScheduling         pod/fio-smallfile-lifecycle-5                                0/3 nodes are available: pod has unbound immediate PersistentVolumeClaims. not found
85m         Warning   FailedScheduling         pod/fio-smallfile-lifecycle-5                                0/3 nodes are available: pod has unbound immediate PersistentVolumeClaims. not found
119m        Warning   FailedScheduling         pod/fio-max-throughput-3                                     0/3 nodes are available: pod has unbound immediate PersistentVolumeClaims. not found
119m        Warning   FailedScheduling         pod/fio-max-throughput-3                                     0/3 nodes are available: pod has unbound immediate PersistentVolumeClaims. not found
119m        Normal    Scheduled                pod/fio-max-throughput-3                                     Successfully assigned fio-tests/fio-max-throughput-3 to s1
84m         Normal    Scheduled                pod/fio-smallfile-lifecycle-4                                Successfully assigned fio-tests/fio-smallfile-lifecycle-4 to s1
84m         Warning   FailedScheduling         pod/fio-smallfile-lifecycle-4                                0/3 nodes are available: pod has unbound immediate PersistentVolumeClaims. not found
85m         Warning   FailedScheduling         pod/fio-smallfile-lifecycle-4                                0/3 nodes are available: pod has unbound immediate PersistentVolumeClaims. not found
85m         Normal    Scheduled                pod/fio-smallfile-lifecycle-3                                Successfully assigned fio-tests/fio-smallfile-lifecycle-3 to s1
85m         Warning   FailedScheduling         pod/fio-smallfile-lifecycle-3                                0/3 nodes are available: pod has unbound immediate PersistentVolumeClaims. not found
119m        Warning   FailedScheduling         pod/fio-max-throughput-4                                     0/3 nodes are available: pod has unbound immediate PersistentVolumeClaims. not found
119m        Warning   FailedScheduling         pod/fio-max-throughput-4                                     0/3 nodes are available: pod has unbound immediate PersistentVolumeClaims. not found
119m        Normal    Scheduled                pod/fio-max-throughput-4                                     Successfully assigned fio-tests/fio-max-throughput-4 to s2
85m         Warning   FailedScheduling         pod/fio-smallfile-lifecycle-3                                0/3 nodes are available: pod has unbound immediate PersistentVolumeClaims. not found
84m         Normal    Scheduled                pod/fio-smallfile-lifecycle-2                                Successfully assigned fio-tests/fio-smallfile-lifecycle-2 to s1
84m         Warning   FailedScheduling         pod/fio-smallfile-lifecycle-2                                0/3 nodes are available: pod has unbound immediate PersistentVolumeClaims. not found
85m         Warning   FailedScheduling         pod/fio-smallfile-lifecycle-2                                0/3 nodes are available: pod has unbound immediate PersistentVolumeClaims. not found
84m         Normal    Scheduled                pod/fio-smallfile-lifecycle-1                                Successfully assigned fio-tests/fio-smallfile-lifecycle-1 to s1
119m        Warning   FailedScheduling         pod/fio-max-throughput-5                                     0/3 nodes are available: pod has unbound immediate PersistentVolumeClaims. not found
118m        Warning   FailedScheduling         pod/fio-max-throughput-5                                     0/3 nodes are available: pod has unbound immediate PersistentVolumeClaims. not found
118m        Normal    Scheduled                pod/fio-max-throughput-5                                     Successfully assigned fio-tests/fio-max-throughput-5 to s1
84m         Warning   FailedScheduling         pod/fio-smallfile-lifecycle-1                                0/3 nodes are available: pod has unbound immediate PersistentVolumeClaims. not found
85m         Warning   FailedScheduling         pod/fio-smallfile-lifecycle-1                                0/3 nodes are available: pod has unbound immediate PersistentVolumeClaims. not found
84m         Normal    Scheduled                pod/fio-smallfile-lifecycle-0                                Successfully assigned fio-tests/fio-smallfile-lifecycle-0 to s2
84m         Warning   FailedScheduling         pod/fio-smallfile-lifecycle-0                                0/3 nodes are available: pod has unbound immediate PersistentVolumeClaims. not found
85m         Warning   FailedScheduling         pod/fio-smallfile-lifecycle-0                                0/3 nodes are available: pod has unbound immediate PersistentVolumeClaims. not found
119m        Warning   FailedScheduling         pod/fio-max-throughput-6                                     0/3 nodes are available: pod has unbound immediate PersistentVolumeClaims. not found
118m        Warning   FailedScheduling         pod/fio-max-throughput-6                                     0/3 nodes are available: pod has unbound immediate PersistentVolumeClaims. not found
118m        Normal    Scheduled                pod/fio-max-throughput-6                                     Successfully assigned fio-tests/fio-max-throughput-6 to s3
99m         Normal    Scheduled                pod/fio-sync-write-0                                         Successfully assigned fio-tests/fio-sync-write-0 to s1
118m        Normal    Scheduled                pod/fio-max-throughput-9                                     Successfully assigned fio-tests/fio-max-throughput-9 to s3
118m        Warning   FailedScheduling         pod/fio-max-throughput-9                                     0/3 nodes are available: pod has unbound immediate PersistentVolumeClaims. not found
119m        Warning   FailedScheduling         pod/fio-max-throughput-9                                     0/3 nodes are available: pod has unbound immediate PersistentVolumeClaims. not found
100m        Warning   FailedScheduling         pod/fio-sync-write-0                                         0/3 nodes are available: pod has unbound immediate PersistentVolumeClaims. not found
119m        Warning   FailedScheduling         pod/fio-max-throughput-7                                     0/3 nodes are available: pod has unbound immediate PersistentVolumeClaims. not found
118m        Warning   FailedScheduling         pod/fio-max-throughput-7                                     0/3 nodes are available: pod has unbound immediate PersistentVolumeClaims. not found
118m        Normal    Scheduled                pod/fio-max-throughput-7                                     Successfully assigned fio-tests/fio-max-throughput-7 to s2
129m        Warning   FailedScheduling         pod/fio-low-qd-latency-0                                     0/3 nodes are available: pod has unbound immediate PersistentVolumeClaims. not found
119m        Normal    Scheduled                pod/fio-max-throughput-8                                     Successfully assigned fio-tests/fio-max-throughput-8 to s3
119m        Warning   FailedScheduling         pod/fio-max-throughput-8                                     0/3 nodes are available: pod has unbound immediate PersistentVolumeClaims. not found
119m        Warning   FailedScheduling         pod/fio-max-throughput-8                                     0/3 nodes are available: pod has unbound immediate PersistentVolumeClaims. not found
129m        Normal    Provisioning             persistentvolumeclaim/fio-low-qd-latency-pvc-4               External provisioner is provisioning volume for claim "fio-tests/fio-low-qd-latency-pvc-4"
129m        Normal    Provisioning             persistentvolumeclaim/fio-low-qd-latency-pvc-1               External provisioner is provisioning volume for claim "fio-tests/fio-low-qd-latency-pvc-1"
129m        Normal    Provisioning             persistentvolumeclaim/fio-low-qd-latency-pvc-2               External provisioner is provisioning volume for claim "fio-tests/fio-low-qd-latency-pvc-2"
129m        Normal    Provisioning             persistentvolumeclaim/fio-low-qd-latency-pvc-6               External provisioner is provisioning volume for claim "fio-tests/fio-low-qd-latency-pvc-6"
129m        Normal    Provisioning             persistentvolumeclaim/fio-low-qd-latency-pvc-9               External provisioner is provisioning volume for claim "fio-tests/fio-low-qd-latency-pvc-9"
129m        Normal    Provisioning             persistentvolumeclaim/fio-low-qd-latency-pvc-0               External provisioner is provisioning volume for claim "fio-tests/fio-low-qd-latency-pvc-0"
129m        Normal    Provisioning             persistentvolumeclaim/fio-low-qd-latency-pvc-3               External provisioner is provisioning volume for claim "fio-tests/fio-low-qd-latency-pvc-3"
129m        Normal    Provisioning             persistentvolumeclaim/fio-low-qd-latency-pvc-5               External provisioner is provisioning volume for claim "fio-tests/fio-low-qd-latency-pvc-5"
129m        Normal    Provisioning             persistentvolumeclaim/fio-low-qd-latency-pvc-8               External provisioner is provisioning volume for claim "fio-tests/fio-low-qd-latency-pvc-8"
129m        Normal    Provisioning             persistentvolumeclaim/fio-low-qd-latency-pvc-7               External provisioner is provisioning volume for claim "fio-tests/fio-low-qd-latency-pvc-7"
129m        Normal    ExternalProvisioning     persistentvolumeclaim/fio-low-qd-latency-pvc-3               Waiting for a volume to be created either by the external provisioner 'csi.trident.netapp.io' or manually by the system administrator. If volume creation is delayed, please verify that the provisioner is running and correctly registered.
129m        Normal    ExternalProvisioning     persistentvolumeclaim/fio-low-qd-latency-pvc-7               Waiting for a volume to be created either by the external provisioner 'csi.trident.netapp.io' or manually by the system administrator. If volume creation is delayed, please verify that the provisioner is running and correctly registered.
129m        Normal    ProvisioningSucceeded    persistentvolumeclaim/fio-low-qd-latency-pvc-3               Successfully provisioned volume pvc-f1b5da56-b226-427c-b95f-22e4a488cfda
129m        Normal    ProvisioningSuccess      persistentvolumeclaim/fio-low-qd-latency-pvc-3               provisioned a volume
129m        Normal    ProvisioningSucceeded    persistentvolumeclaim/fio-low-qd-latency-pvc-7               Successfully provisioned volume pvc-c55c6bf6-b757-42e5-8524-aeaa81d51434
129m        Normal    ProvisioningSuccess      persistentvolumeclaim/fio-low-qd-latency-pvc-7               provisioned a volume
129m        Normal    ExternalProvisioning     persistentvolumeclaim/fio-low-qd-latency-pvc-5               Waiting for a volume to be created either by the external provisioner 'csi.trident.netapp.io' or manually by the system administrator. If volume creation is delayed, please verify that the provisioner is running and correctly registered.
129m        Normal    ExternalProvisioning     persistentvolumeclaim/fio-low-qd-latency-pvc-8               Waiting for a volume to be created either by the external provisioner 'csi.trident.netapp.io' or manually by the system administrator. If volume creation is delayed, please verify that the provisioner is running and correctly registered.
128m        Normal    ProvisioningSuccess      persistentvolumeclaim/fio-low-qd-latency-pvc-8               provisioned a volume
128m        Normal    ProvisioningSucceeded    persistentvolumeclaim/fio-low-qd-latency-pvc-8               Successfully provisioned volume pvc-79b5bc2c-6481-4764-9837-5fcaba43b2ce
128m        Normal    ProvisioningSucceeded    persistentvolumeclaim/fio-low-qd-latency-pvc-5               Successfully provisioned volume pvc-65063084-e48d-4245-9991-06787555f747
128m        Normal    ProvisioningSuccess      persistentvolumeclaim/fio-low-qd-latency-pvc-5               provisioned a volume
128m        Normal    ExternalProvisioning     persistentvolumeclaim/fio-low-qd-latency-pvc-1               Waiting for a volume to be created either by the external provisioner 'csi.trident.netapp.io' or manually by the system administrator. If volume creation is delayed, please verify that the provisioner is running and correctly registered.
128m        Normal    ExternalProvisioning     persistentvolumeclaim/fio-low-qd-latency-pvc-4               Waiting for a volume to be created either by the external provisioner 'csi.trident.netapp.io' or manually by the system administrator. If volume creation is delayed, please verify that the provisioner is running and correctly registered.
128m        Normal    ExternalProvisioning     persistentvolumeclaim/fio-low-qd-latency-pvc-9               Waiting for a volume to be created either by the external provisioner 'csi.trident.netapp.io' or manually by the system administrator. If volume creation is delayed, please verify that the provisioner is running and correctly registered.
128m        Normal    ProvisioningSuccess      persistentvolumeclaim/fio-low-qd-latency-pvc-4               provisioned a volume
128m        Normal    ProvisioningSucceeded    persistentvolumeclaim/fio-low-qd-latency-pvc-4               Successfully provisioned volume pvc-5145e34e-0563-4162-b1b2-37d9ccd217a7
128m        Normal    ProvisioningSucceeded    persistentvolumeclaim/fio-low-qd-latency-pvc-9               Successfully provisioned volume pvc-ac2e529f-149a-4c4e-907d-c3203cb4dcd7
128m        Normal    ProvisioningSuccess      persistentvolumeclaim/fio-low-qd-latency-pvc-9               provisioned a volume
128m        Normal    ProvisioningSuccess      persistentvolumeclaim/fio-low-qd-latency-pvc-1               provisioned a volume
128m        Normal    ProvisioningSucceeded    persistentvolumeclaim/fio-low-qd-latency-pvc-1               Successfully provisioned volume pvc-6bcf35de-e58e-4cbb-960c-3ba29943ead1
128m        Normal    ExternalProvisioning     persistentvolumeclaim/fio-low-qd-latency-pvc-6               Waiting for a volume to be created either by the external provisioner 'csi.trident.netapp.io' or manually by the system administrator. If volume creation is delayed, please verify that the provisioner is running and correctly registered.
128m        Normal    ExternalProvisioning     persistentvolumeclaim/fio-low-qd-latency-pvc-2               Waiting for a volume to be created either by the external provisioner 'csi.trident.netapp.io' or manually by the system administrator. If volume creation is delayed, please verify that the provisioner is running and correctly registered.
128m        Normal    ProvisioningSucceeded    persistentvolumeclaim/fio-low-qd-latency-pvc-6               Successfully provisioned volume pvc-34bbfb88-bc9d-4335-808b-549a4289fd01
128m        Normal    SuccessfulAttachVolume   pod/fio-low-qd-latency-3                                     AttachVolume.Attach succeeded for volume "pvc-f1b5da56-b226-427c-b95f-22e4a488cfda"
128m        Normal    ProvisioningSuccess      persistentvolumeclaim/fio-low-qd-latency-pvc-6               provisioned a volume
128m        Normal    Started                  pod/fio-low-qd-latency-3                                     Container started
128m        Normal    Created                  pod/fio-low-qd-latency-3                                     Container created
128m        Normal    Pulled                   pod/fio-low-qd-latency-3                                     Container image "rafmoshe2500/fio:3.41" already present on machine and can be accessed by the pod
128m        Normal    AddedInterface           pod/fio-low-qd-latency-3                                     Add eth0 [10.130.0.86/23] from ovn-kubernetes
128m        Normal    ProvisioningSucceeded    persistentvolumeclaim/fio-low-qd-latency-pvc-2               Successfully provisioned volume pvc-88d7526f-6bf2-4050-ac26-58c77a1197cd
128m        Normal    ProvisioningSuccess      persistentvolumeclaim/fio-low-qd-latency-pvc-2               provisioned a volume
128m        Normal    ExternalProvisioning     persistentvolumeclaim/fio-low-qd-latency-pvc-0               Waiting for a volume to be created either by the external provisioner 'csi.trident.netapp.io' or manually by the system administrator. If volume creation is delayed, please verify that the provisioner is running and correctly registered.
128m        Normal    ProvisioningSucceeded    persistentvolumeclaim/fio-low-qd-latency-pvc-0               Successfully provisioned volume pvc-d87dc904-0647-469e-aa49-a69c13c3a9a2
128m        Normal    ProvisioningSuccess      persistentvolumeclaim/fio-low-qd-latency-pvc-0               provisioned a volume
128m        Normal    SuccessfulAttachVolume   pod/fio-low-qd-latency-5                                     AttachVolume.Attach succeeded for volume "pvc-65063084-e48d-4245-9991-06787555f747"
128m        Normal    AddedInterface           pod/fio-low-qd-latency-5                                     Add eth0 [10.130.0.87/23] from ovn-kubernetes
128m        Normal    Started                  pod/fio-low-qd-latency-5                                     Container started
128m        Normal    SuccessfulAttachVolume   pod/fio-low-qd-latency-1                                     AttachVolume.Attach succeeded for volume "pvc-6bcf35de-e58e-4cbb-960c-3ba29943ead1"
128m        Normal    Pulled                   pod/fio-low-qd-latency-5                                     Container image "rafmoshe2500/fio:3.41" already present on machine and can be accessed by the pod
128m        Normal    Started                  pod/fio-low-qd-latency-7                                     Container started
128m        Normal    Created                  pod/fio-low-qd-latency-7                                     Container created
128m        Normal    Pulled                   pod/fio-low-qd-latency-7                                     Container image "rafmoshe2500/fio:3.41" already present on machine and can be accessed by the pod
128m        Normal    AddedInterface           pod/fio-low-qd-latency-7                                     Add eth0 [10.129.0.208/23] from ovn-kubernetes
128m        Normal    SuccessfulAttachVolume   pod/fio-low-qd-latency-7                                     AttachVolume.Attach succeeded for volume "pvc-c55c6bf6-b757-42e5-8524-aeaa81d51434"
128m        Normal    Created                  pod/fio-low-qd-latency-5                                     Container created
128m        Normal    Pulled                   pod/fio-low-qd-latency-8                                     Container image "rafmoshe2500/fio:3.41" already present on machine and can be accessed by the pod
128m        Normal    Created                  pod/fio-low-qd-latency-8                                     Container created
128m        Normal    AddedInterface           pod/fio-low-qd-latency-6                                     Add eth0 [10.129.0.210/23] from ovn-kubernetes
128m        Normal    SuccessfulAttachVolume   pod/fio-low-qd-latency-6                                     AttachVolume.Attach succeeded for volume "pvc-34bbfb88-bc9d-4335-808b-549a4289fd01"
128m        Normal    Created                  pod/fio-low-qd-latency-6                                     Container created
128m        Normal    Started                  pod/fio-low-qd-latency-6                                     Container started
128m        Normal    SuccessfulAttachVolume   pod/fio-low-qd-latency-8                                     AttachVolume.Attach succeeded for volume "pvc-79b5bc2c-6481-4764-9837-5fcaba43b2ce"
128m        Normal    AddedInterface           pod/fio-low-qd-latency-8                                     Add eth0 [10.128.0.179/23] from ovn-kubernetes
128m        Normal    AddedInterface           pod/fio-low-qd-latency-1                                     Add eth0 [10.130.0.88/23] from ovn-kubernetes
128m        Normal    Pulled                   pod/fio-low-qd-latency-1                                     Container image "rafmoshe2500/fio:3.41" already present on machine and can be accessed by the pod
128m        Normal    Created                  pod/fio-low-qd-latency-1                                     Container created
128m        Normal    Pulled                   pod/fio-low-qd-latency-6                                     Container image "rafmoshe2500/fio:3.41" already present on machine and can be accessed by the pod
128m        Normal    Started                  pod/fio-low-qd-latency-1                                     Container started
128m        Normal    SuccessfulAttachVolume   pod/fio-low-qd-latency-2                                     AttachVolume.Attach succeeded for volume "pvc-88d7526f-6bf2-4050-ac26-58c77a1197cd"
128m        Normal    AddedInterface           pod/fio-low-qd-latency-2                                     Add eth0 [10.128.0.181/23] from ovn-kubernetes
128m        Normal    Pulled                   pod/fio-low-qd-latency-2                                     Container image "rafmoshe2500/fio:3.41" already present on machine and can be accessed by the pod
128m        Normal    Created                  pod/fio-low-qd-latency-2                                     Container created
128m        Normal    SuccessfulAttachVolume   pod/fio-low-qd-latency-0                                     AttachVolume.Attach succeeded for volume "pvc-d87dc904-0647-469e-aa49-a69c13c3a9a2"
128m        Normal    SuccessfulAttachVolume   pod/fio-low-qd-latency-4                                     AttachVolume.Attach succeeded for volume "pvc-5145e34e-0563-4162-b1b2-37d9ccd217a7"
128m        Normal    Started                  pod/fio-low-qd-latency-8                                     Container started
128m        Normal    SuccessfulAttachVolume   pod/fio-low-qd-latency-9                                     AttachVolume.Attach succeeded for volume "pvc-ac2e529f-149a-4c4e-907d-c3203cb4dcd7"
128m        Normal    AddedInterface           pod/fio-low-qd-latency-4                                     Add eth0 [10.128.0.180/23] from ovn-kubernetes
128m        Normal    Started                  pod/fio-low-qd-latency-9                                     Container started
128m        Normal    Started                  pod/fio-low-qd-latency-2                                     Container started
128m        Normal    Pulled                   pod/fio-low-qd-latency-4                                     Container image "rafmoshe2500/fio:3.41" already present on machine and can be accessed by the pod
128m        Normal    Created                  pod/fio-low-qd-latency-4                                     Container created
128m        Normal    Started                  pod/fio-low-qd-latency-4                                     Container started
128m        Normal    Created                  pod/fio-low-qd-latency-9                                     Container created
128m        Normal    Pulled                   pod/fio-low-qd-latency-9                                     Container image "rafmoshe2500/fio:3.41" already present on machine and can be accessed by the pod
128m        Normal    AddedInterface           pod/fio-low-qd-latency-9                                     Add eth0 [10.129.0.209/23] from ovn-kubernetes
128m        Normal    AddedInterface           pod/fio-low-qd-latency-0                                     Add eth0 [10.130.0.89/23] from ovn-kubernetes
128m        Normal    Started                  pod/fio-low-qd-latency-0                                     Container started
128m        Normal    Created                  pod/fio-low-qd-latency-0                                     Container created
128m        Normal    Pulled                   pod/fio-low-qd-latency-0                                     Container image "rafmoshe2500/fio:3.41" already present on machine and can be accessed by the pod
119m        Normal    Provisioning             persistentvolumeclaim/fio-max-throughput-pvc-3               External provisioner is provisioning volume for claim "fio-tests/fio-max-throughput-pvc-3"
119m        Normal    Provisioning             persistentvolumeclaim/fio-max-throughput-pvc-8               External provisioner is provisioning volume for claim "fio-tests/fio-max-throughput-pvc-8"
119m        Normal    Provisioning             persistentvolumeclaim/fio-max-throughput-pvc-7               External provisioner is provisioning volume for claim "fio-tests/fio-max-throughput-pvc-7"
119m        Normal    Provisioning             persistentvolumeclaim/fio-max-throughput-pvc-5               External provisioner is provisioning volume for claim "fio-tests/fio-max-throughput-pvc-5"
119m        Normal    Provisioning             persistentvolumeclaim/fio-max-throughput-pvc-9               External provisioner is provisioning volume for claim "fio-tests/fio-max-throughput-pvc-9"
119m        Normal    Provisioning             persistentvolumeclaim/fio-max-throughput-pvc-4               External provisioner is provisioning volume for claim "fio-tests/fio-max-throughput-pvc-4"
119m        Normal    Provisioning             persistentvolumeclaim/fio-max-throughput-pvc-6               External provisioner is provisioning volume for claim "fio-tests/fio-max-throughput-pvc-6"
119m        Normal    ExternalProvisioning     persistentvolumeclaim/fio-max-throughput-pvc-3               Waiting for a volume to be created either by the external provisioner 'csi.trident.netapp.io' or manually by the system administrator. If volume creation is delayed, please verify that the provisioner is running and correctly registered.
119m        Normal    Provisioning             persistentvolumeclaim/fio-max-throughput-pvc-2               External provisioner is provisioning volume for claim "fio-tests/fio-max-throughput-pvc-2"
119m        Normal    Provisioning             persistentvolumeclaim/fio-max-throughput-pvc-1               External provisioner is provisioning volume for claim "fio-tests/fio-max-throughput-pvc-1"
119m        Normal    Provisioning             persistentvolumeclaim/fio-max-throughput-pvc-0               External provisioner is provisioning volume for claim "fio-tests/fio-max-throughput-pvc-0"
119m        Normal    ProvisioningSucceeded    persistentvolumeclaim/fio-max-throughput-pvc-3               Successfully provisioned volume pvc-0d345341-ed23-415c-bbf0-f42647949c9b
119m        Normal    ProvisioningSuccess      persistentvolumeclaim/fio-max-throughput-pvc-3               provisioned a volume
119m        Normal    ExternalProvisioning     persistentvolumeclaim/fio-max-throughput-pvc-8               Waiting for a volume to be created either by the external provisioner 'csi.trident.netapp.io' or manually by the system administrator. If volume creation is delayed, please verify that the provisioner is running and correctly registered.
119m        Normal    ExternalProvisioning     persistentvolumeclaim/fio-max-throughput-pvc-4               Waiting for a volume to be created either by the external provisioner 'csi.trident.netapp.io' or manually by the system administrator. If volume creation is delayed, please verify that the provisioner is running and correctly registered.
119m        Normal    ProvisioningSucceeded    persistentvolumeclaim/fio-max-throughput-pvc-4               Successfully provisioned volume pvc-3a931b50-0bd5-4021-b61a-405b8072d6e1
119m        Normal    ProvisioningSuccess      persistentvolumeclaim/fio-max-throughput-pvc-4               provisioned a volume
119m        Normal    ProvisioningSuccess      persistentvolumeclaim/fio-max-throughput-pvc-8               provisioned a volume
119m        Normal    ProvisioningSucceeded    persistentvolumeclaim/fio-max-throughput-pvc-8               Successfully provisioned volume pvc-9c571b84-e262-4ccc-af3b-29321191d43d
119m        Normal    ExternalProvisioning     persistentvolumeclaim/fio-max-throughput-pvc-1               Waiting for a volume to be created either by the external provisioner 'csi.trident.netapp.io' or manually by the system administrator. If volume creation is delayed, please verify that the provisioner is running and correctly registered.
119m        Normal    ExternalProvisioning     persistentvolumeclaim/fio-max-throughput-pvc-0               Waiting for a volume to be created either by the external provisioner 'csi.trident.netapp.io' or manually by the system administrator. If volume creation is delayed, please verify that the provisioner is running and correctly registered.
119m        Normal    ExternalProvisioning     persistentvolumeclaim/fio-max-throughput-pvc-9               Waiting for a volume to be created either by the external provisioner 'csi.trident.netapp.io' or manually by the system administrator. If volume creation is delayed, please verify that the provisioner is running and correctly registered.
119m        Normal    ProvisioningSuccess      persistentvolumeclaim/fio-max-throughput-pvc-0               provisioned a volume
119m        Normal    ProvisioningSucceeded    persistentvolumeclaim/fio-max-throughput-pvc-0               Successfully provisioned volume pvc-3973fefe-46b5-4fa6-82ef-1080fde7f021
118m        Normal    ProvisioningSuccess      persistentvolumeclaim/fio-max-throughput-pvc-9               provisioned a volume
118m        Normal    ProvisioningSucceeded    persistentvolumeclaim/fio-max-throughput-pvc-9               Successfully provisioned volume pvc-ea17bb6a-624f-47f4-918a-ff0c56b261e8
118m        Normal    ProvisioningSuccess      persistentvolumeclaim/fio-max-throughput-pvc-1               provisioned a volume
118m        Normal    ProvisioningSucceeded    persistentvolumeclaim/fio-max-throughput-pvc-1               Successfully provisioned volume pvc-163776e0-07f5-4569-a86b-6d1b5736238f
118m        Normal    ExternalProvisioning     persistentvolumeclaim/fio-max-throughput-pvc-6               Waiting for a volume to be created either by the external provisioner 'csi.trident.netapp.io' or manually by the system administrator. If volume creation is delayed, please verify that the provisioner is running and correctly registered.
118m        Normal    ExternalProvisioning     persistentvolumeclaim/fio-max-throughput-pvc-5               Waiting for a volume to be created either by the external provisioner 'csi.trident.netapp.io' or manually by the system administrator. If volume creation is delayed, please verify that the provisioner is running and correctly registered.
118m        Normal    ExternalProvisioning     persistentvolumeclaim/fio-max-throughput-pvc-2               Waiting for a volume to be created either by the external provisioner 'csi.trident.netapp.io' or manually by the system administrator. If volume creation is delayed, please verify that the provisioner is running and correctly registered.
118m        Normal    ProvisioningSuccess      persistentvolumeclaim/fio-max-throughput-pvc-5               provisioned a volume
118m        Normal    ProvisioningSucceeded    persistentvolumeclaim/fio-max-throughput-pvc-5               Successfully provisioned volume pvc-89442f44-8e08-4eeb-a3f9-cf7a22da6537
118m        Normal    ProvisioningSucceeded    persistentvolumeclaim/fio-max-throughput-pvc-2               Successfully provisioned volume pvc-30119b2d-e0cb-4fb0-8479-ef18f3bc1043
118m        Normal    ProvisioningSuccess      persistentvolumeclaim/fio-max-throughput-pvc-2               provisioned a volume
118m        Normal    ProvisioningSuccess      persistentvolumeclaim/fio-max-throughput-pvc-6               provisioned a volume
118m        Normal    ProvisioningSucceeded    persistentvolumeclaim/fio-max-throughput-pvc-6               Successfully provisioned volume pvc-4df648b1-6874-4a0b-bed0-aef4bce7b1fe
118m        Normal    ExternalProvisioning     persistentvolumeclaim/fio-max-throughput-pvc-7               Waiting for a volume to be created either by the external provisioner 'csi.trident.netapp.io' or manually by the system administrator. If volume creation is delayed, please verify that the provisioner is running and correctly registered.
118m        Normal    SuccessfulAttachVolume   pod/fio-max-throughput-5                                     AttachVolume.Attach succeeded for volume "pvc-89442f44-8e08-4eeb-a3f9-cf7a22da6537"
118m        Normal    SuccessfulAttachVolume   pod/fio-max-throughput-6                                     AttachVolume.Attach succeeded for volume "pvc-4df648b1-6874-4a0b-bed0-aef4bce7b1fe"
118m        Normal    SuccessfulAttachVolume   pod/fio-max-throughput-8                                     AttachVolume.Attach succeeded for volume "pvc-9c571b84-e262-4ccc-af3b-29321191d43d"
118m        Normal    ProvisioningSuccess      persistentvolumeclaim/fio-max-throughput-pvc-7               provisioned a volume
118m        Normal    ProvisioningSucceeded    persistentvolumeclaim/fio-max-throughput-pvc-7               Successfully provisioned volume pvc-7b9edd08-5ad8-4aa1-b2c2-9b1a115c752c
118m        Normal    AddedInterface           pod/fio-max-throughput-8                                     Add eth0 [10.128.0.182/23] from ovn-kubernetes
118m        Normal    AddedInterface           pod/fio-max-throughput-6                                     Add eth0 [10.128.0.184/23] from ovn-kubernetes
118m        Normal    Pulled                   pod/fio-max-throughput-5                                     Container image "rafmoshe2500/fio:3.41" already present on machine and can be accessed by the pod
118m        Normal    Created                  pod/fio-max-throughput-5                                     Container created
118m        Normal    Started                  pod/fio-max-throughput-5                                     Container started
118m        Normal    SuccessfulAttachVolume   pod/fio-max-throughput-2                                     AttachVolume.Attach succeeded for volume "pvc-30119b2d-e0cb-4fb0-8479-ef18f3bc1043"
118m        Normal    Started                  pod/fio-max-throughput-7                                     Container started
118m        Normal    Started                  pod/fio-max-throughput-2                                     Container started
118m        Normal    Created                  pod/fio-max-throughput-2                                     Container created
118m        Normal    SuccessfulAttachVolume   pod/fio-max-throughput-1                                     AttachVolume.Attach succeeded for volume "pvc-163776e0-07f5-4569-a86b-6d1b5736238f"
118m        Normal    Pulled                   pod/fio-max-throughput-9                                     Container image "rafmoshe2500/fio:3.41" already present on machine and can be accessed by the pod
118m        Normal    AddedInterface           pod/fio-max-throughput-9                                     Add eth0 [10.128.0.183/23] from ovn-kubernetes
118m        Normal    SuccessfulAttachVolume   pod/fio-max-throughput-9                                     AttachVolume.Attach succeeded for volume "pvc-ea17bb6a-624f-47f4-918a-ff0c56b261e8"
118m        Normal    AddedInterface           pod/fio-max-throughput-5                                     Add eth0 [10.130.0.92/23] from ovn-kubernetes
118m        Normal    Pulled                   pod/fio-max-throughput-6                                     Container image "rafmoshe2500/fio:3.41" already present on machine and can be accessed by the pod
118m        Normal    Created                  pod/fio-max-throughput-6                                     Container created
118m        Normal    Started                  pod/fio-max-throughput-8                                     Container started
118m        Normal    Created                  pod/fio-max-throughput-8                                     Container created
118m        Normal    Pulled                   pod/fio-max-throughput-8                                     Container image "rafmoshe2500/fio:3.41" already present on machine and can be accessed by the pod
118m        Normal    Started                  pod/fio-max-throughput-6                                     Container started
118m        Normal    Pulled                   pod/fio-max-throughput-2                                     Container image "rafmoshe2500/fio:3.41" already present on machine and can be accessed by the pod
118m        Normal    AddedInterface           pod/fio-max-throughput-7                                     Add eth0 [10.129.0.214/23] from ovn-kubernetes
118m        Normal    Pulled                   pod/fio-max-throughput-7                                     Container image "rafmoshe2500/fio:3.41" already present on machine and can be accessed by the pod
118m        Normal    Created                  pod/fio-max-throughput-7                                     Container created
118m        Normal    AddedInterface           pod/fio-max-throughput-2                                     Add eth0 [10.129.0.213/23] from ovn-kubernetes
118m        Normal    SuccessfulAttachVolume   pod/fio-max-throughput-7                                     AttachVolume.Attach succeeded for volume "pvc-7b9edd08-5ad8-4aa1-b2c2-9b1a115c752c"
118m        Normal    AddedInterface           pod/fio-max-throughput-0                                     Add eth0 [10.130.0.91/23] from ovn-kubernetes
118m        Normal    SuccessfulAttachVolume   pod/fio-max-throughput-0                                     AttachVolume.Attach succeeded for volume "pvc-3973fefe-46b5-4fa6-82ef-1080fde7f021"
118m        Normal    Pulled                   pod/fio-max-throughput-0                                     Container image "rafmoshe2500/fio:3.41" already present on machine and can be accessed by the pod
118m        Normal    Started                  pod/fio-max-throughput-9                                     Container started
118m        Normal    SuccessfulAttachVolume   pod/fio-max-throughput-3                                     AttachVolume.Attach succeeded for volume "pvc-0d345341-ed23-415c-bbf0-f42647949c9b"
118m        Normal    Started                  pod/fio-max-throughput-0                                     Container started
118m        Normal    Created                  pod/fio-max-throughput-0                                     Container created
118m        Normal    AddedInterface           pod/fio-max-throughput-1                                     Add eth0 [10.129.0.212/23] from ovn-kubernetes
118m        Normal    Started                  pod/fio-max-throughput-1                                     Container started
118m        Normal    Created                  pod/fio-max-throughput-9                                     Container created
118m        Normal    Pulled                   pod/fio-max-throughput-1                                     Container image "rafmoshe2500/fio:3.41" already present on machine and can be accessed by the pod
118m        Normal    Created                  pod/fio-max-throughput-1                                     Container created
118m        Normal    Started                  pod/fio-max-throughput-3                                     Container started
118m        Normal    Pulled                   pod/fio-max-throughput-4                                     Container image "rafmoshe2500/fio:3.41" already present on machine and can be accessed by the pod
118m        Normal    AddedInterface           pod/fio-max-throughput-4                                     Add eth0 [10.129.0.211/23] from ovn-kubernetes
118m        Normal    SuccessfulAttachVolume   pod/fio-max-throughput-4                                     AttachVolume.Attach succeeded for volume "pvc-3a931b50-0bd5-4021-b61a-405b8072d6e1"
118m        Normal    Created                  pod/fio-max-throughput-3                                     Container created
118m        Normal    AddedInterface           pod/fio-max-throughput-3                                     Add eth0 [10.130.0.90/23] from ovn-kubernetes
118m        Normal    Pulled                   pod/fio-max-throughput-3                                     Container image "rafmoshe2500/fio:3.41" already present on machine and can be accessed by the pod
118m        Normal    Started                  pod/fio-max-throughput-4                                     Container started
118m        Normal    Created                  pod/fio-max-throughput-4                                     Container created
100m        Normal    Provisioning             persistentvolumeclaim/fio-sync-write-pvc-9                   External provisioner is provisioning volume for claim "fio-tests/fio-sync-write-pvc-9"
100m        Normal    Provisioning             persistentvolumeclaim/fio-sync-write-pvc-3                   External provisioner is provisioning volume for claim "fio-tests/fio-sync-write-pvc-3"
100m        Normal    Provisioning             persistentvolumeclaim/fio-sync-write-pvc-5                   External provisioner is provisioning volume for claim "fio-tests/fio-sync-write-pvc-5"
100m        Normal    ExternalProvisioning     persistentvolumeclaim/fio-sync-write-pvc-9                   Waiting for a volume to be created either by the external provisioner 'csi.trident.netapp.io' or manually by the system administrator. If volume creation is delayed, please verify that the provisioner is running and correctly registered.
100m        Normal    Provisioning             persistentvolumeclaim/fio-sync-write-pvc-4                   External provisioner is provisioning volume for claim "fio-tests/fio-sync-write-pvc-4"
100m        Normal    Provisioning             persistentvolumeclaim/fio-sync-write-pvc-6                   External provisioner is provisioning volume for claim "fio-tests/fio-sync-write-pvc-6"
100m        Normal    Provisioning             persistentvolumeclaim/fio-sync-write-pvc-8                   External provisioner is provisioning volume for claim "fio-tests/fio-sync-write-pvc-8"
100m        Normal    Provisioning             persistentvolumeclaim/fio-sync-write-pvc-1                   External provisioner is provisioning volume for claim "fio-tests/fio-sync-write-pvc-1"
100m        Normal    Provisioning             persistentvolumeclaim/fio-sync-write-pvc-2                   External provisioner is provisioning volume for claim "fio-tests/fio-sync-write-pvc-2"
100m        Normal    Provisioning             persistentvolumeclaim/fio-sync-write-pvc-7                   External provisioner is provisioning volume for claim "fio-tests/fio-sync-write-pvc-7"
100m        Normal    Provisioning             persistentvolumeclaim/fio-sync-write-pvc-0                   External provisioner is provisioning volume for claim "fio-tests/fio-sync-write-pvc-0"
100m        Normal    ProvisioningSucceeded    persistentvolumeclaim/fio-sync-write-pvc-9                   Successfully provisioned volume pvc-54b9ad5c-48c3-4106-8b58-3ad78ad8a319
100m        Normal    ProvisioningSuccess      persistentvolumeclaim/fio-sync-write-pvc-9                   provisioned a volume
100m        Normal    ExternalProvisioning     persistentvolumeclaim/fio-sync-write-pvc-1                   Waiting for a volume to be created either by the external provisioner 'csi.trident.netapp.io' or manually by the system administrator. If volume creation is delayed, please verify that the provisioner is running and correctly registered.
100m        Normal    ProvisioningSuccess      persistentvolumeclaim/fio-sync-write-pvc-1                   provisioned a volume
100m        Normal    ProvisioningSucceeded    persistentvolumeclaim/fio-sync-write-pvc-1                   Successfully provisioned volume pvc-4d2d6380-40d1-4c58-b459-c8cf27271455
100m        Normal    ExternalProvisioning     persistentvolumeclaim/fio-sync-write-pvc-3                   Waiting for a volume to be created either by the external provisioner 'csi.trident.netapp.io' or manually by the system administrator. If volume creation is delayed, please verify that the provisioner is running and correctly registered.
100m        Normal    ExternalProvisioning     persistentvolumeclaim/fio-sync-write-pvc-0                   Waiting for a volume to be created either by the external provisioner 'csi.trident.netapp.io' or manually by the system administrator. If volume creation is delayed, please verify that the provisioner is running and correctly registered.
99m         Normal    ProvisioningSuccess      persistentvolumeclaim/fio-sync-write-pvc-3                   provisioned a volume
99m         Normal    ProvisioningSucceeded    persistentvolumeclaim/fio-sync-write-pvc-3                   Successfully provisioned volume pvc-68281b68-cfd3-4469-a690-64f824381e97
99m         Normal    ProvisioningSucceeded    persistentvolumeclaim/fio-sync-write-pvc-0                   Successfully provisioned volume pvc-a5c3605c-0166-4140-8116-1cde037c91c2
99m         Normal    ProvisioningSuccess      persistentvolumeclaim/fio-sync-write-pvc-0                   provisioned a volume
99m         Normal    ExternalProvisioning     persistentvolumeclaim/fio-sync-write-pvc-7                   Waiting for a volume to be created either by the external provisioner 'csi.trident.netapp.io' or manually by the system administrator. If volume creation is delayed, please verify that the provisioner is running and correctly registered.
99m         Normal    ExternalProvisioning     persistentvolumeclaim/fio-sync-write-pvc-6                   Waiting for a volume to be created either by the external provisioner 'csi.trident.netapp.io' or manually by the system administrator. If volume creation is delayed, please verify that the provisioner is running and correctly registered.
99m         Normal    ProvisioningSuccess      persistentvolumeclaim/fio-sync-write-pvc-7                   provisioned a volume
99m         Normal    ProvisioningSucceeded    persistentvolumeclaim/fio-sync-write-pvc-7                   Successfully provisioned volume pvc-8a36a31c-a527-403b-ac0a-99a799f3747a
99m         Normal    ExternalProvisioning     persistentvolumeclaim/fio-sync-write-pvc-5                   Waiting for a volume to be created either by the external provisioner 'csi.trident.netapp.io' or manually by the system administrator. If volume creation is delayed, please verify that the provisioner is running and correctly registered.
99m         Normal    ProvisioningSucceeded    persistentvolumeclaim/fio-sync-write-pvc-6                   Successfully provisioned volume pvc-76cc302f-3f1b-4a80-a580-1d498e3451b0
99m         Normal    ProvisioningSuccess      persistentvolumeclaim/fio-sync-write-pvc-6                   provisioned a volume
99m         Normal    ExternalProvisioning     persistentvolumeclaim/fio-sync-write-pvc-2                   Waiting for a volume to be created either by the external provisioner 'csi.trident.netapp.io' or manually by the system administrator. If volume creation is delayed, please verify that the provisioner is running and correctly registered.
99m         Normal    ProvisioningSuccess      persistentvolumeclaim/fio-sync-write-pvc-2                   provisioned a volume
99m         Normal    ProvisioningSucceeded    persistentvolumeclaim/fio-sync-write-pvc-2                   Successfully provisioned volume pvc-ccc6267f-75cd-45be-87e6-45c0f90d4df9
99m         Normal    ProvisioningSuccess      persistentvolumeclaim/fio-sync-write-pvc-5                   provisioned a volume
99m         Normal    ProvisioningSucceeded    persistentvolumeclaim/fio-sync-write-pvc-5                   Successfully provisioned volume pvc-eecd9f7e-76f9-4336-8b21-58ff661c8a88
99m         Normal    ExternalProvisioning     persistentvolumeclaim/fio-sync-write-pvc-4                   Waiting for a volume to be created either by the external provisioner 'csi.trident.netapp.io' or manually by the system administrator. If volume creation is delayed, please verify that the provisioner is running and correctly registered.
99m         Normal    ExternalProvisioning     persistentvolumeclaim/fio-sync-write-pvc-8                   Waiting for a volume to be created either by the external provisioner 'csi.trident.netapp.io' or manually by the system administrator. If volume creation is delayed, please verify that the provisioner is running and correctly registered.
99m         Normal    ProvisioningSucceeded    persistentvolumeclaim/fio-sync-write-pvc-8                   Successfully provisioned volume pvc-d142ed21-7f81-4eb4-986c-99be872f5f85
99m         Normal    ProvisioningSuccess      persistentvolumeclaim/fio-sync-write-pvc-8                   provisioned a volume
99m         Normal    ProvisioningSuccess      persistentvolumeclaim/fio-sync-write-pvc-4                   provisioned a volume
99m         Normal    SuccessfulAttachVolume   pod/fio-sync-write-1                                         AttachVolume.Attach succeeded for volume "pvc-4d2d6380-40d1-4c58-b459-c8cf27271455"
99m         Normal    ProvisioningSucceeded    persistentvolumeclaim/fio-sync-write-pvc-4                   Successfully provisioned volume pvc-d83d4d16-2334-41bb-baea-bbd1597c901e
99m         Normal    SuccessfulAttachVolume   pod/fio-sync-write-2                                         AttachVolume.Attach succeeded for volume "pvc-ccc6267f-75cd-45be-87e6-45c0f90d4df9"
99m         Normal    SuccessfulAttachVolume   pod/fio-sync-write-6                                         AttachVolume.Attach succeeded for volume "pvc-76cc302f-3f1b-4a80-a580-1d498e3451b0"
99m         Normal    SuccessfulAttachVolume   pod/fio-sync-write-8                                         AttachVolume.Attach succeeded for volume "pvc-d142ed21-7f81-4eb4-986c-99be872f5f85"
99m         Normal    Started                  pod/fio-sync-write-1                                         Container started
99m         Normal    Created                  pod/fio-sync-write-1                                         Container created
99m         Normal    Pulled                   pod/fio-sync-write-1                                         Container image "rafmoshe2500/fio:3.41" already present on machine and can be accessed by the pod
99m         Normal    AddedInterface           pod/fio-sync-write-1                                         Add eth0 [10.129.0.215/23] from ovn-kubernetes
99m         Normal    SuccessfulAttachVolume   pod/fio-sync-write-0                                         AttachVolume.Attach succeeded for volume "pvc-a5c3605c-0166-4140-8116-1cde037c91c2"
99m         Normal    SuccessfulAttachVolume   pod/fio-sync-write-7                                         AttachVolume.Attach succeeded for volume "pvc-8a36a31c-a527-403b-ac0a-99a799f3747a"
99m         Normal    SuccessfulAttachVolume   pod/fio-sync-write-5                                         AttachVolume.Attach succeeded for volume "pvc-eecd9f7e-76f9-4336-8b21-58ff661c8a88"
99m         Normal    AddedInterface           pod/fio-sync-write-5                                         Add eth0 [10.129.0.217/23] from ovn-kubernetes
99m         Normal    Pulled                   pod/fio-sync-write-5                                         Container image "rafmoshe2500/fio:3.41" already present on machine and can be accessed by the pod
99m         Normal    SuccessfulAttachVolume   pod/fio-sync-write-3                                         AttachVolume.Attach succeeded for volume "pvc-68281b68-cfd3-4469-a690-64f824381e97"
99m         Normal    SuccessfulAttachVolume   pod/fio-sync-write-4                                         AttachVolume.Attach succeeded for volume "pvc-d83d4d16-2334-41bb-baea-bbd1597c901e"
99m         Normal    Created                  pod/fio-sync-write-5                                         Container created
99m         Normal    Started                  pod/fio-sync-write-7                                         Container started
99m         Normal    Started                  pod/fio-sync-write-0                                         Container started
99m         Normal    AddedInterface           pod/fio-sync-write-3                                         Add eth0 [10.128.0.185/23] from ovn-kubernetes
99m         Normal    AddedInterface           pod/fio-sync-write-6                                         Add eth0 [10.129.0.216/23] from ovn-kubernetes
99m         Normal    Pulled                   pod/fio-sync-write-6                                         Container image "rafmoshe2500/fio:3.41" already present on machine and can be accessed by the pod
99m         Normal    Created                  pod/fio-sync-write-6                                         Container created
99m         Normal    Started                  pod/fio-sync-write-6                                         Container started
99m         Normal    AddedInterface           pod/fio-sync-write-0                                         Add eth0 [10.130.0.94/23] from ovn-kubernetes
99m         Normal    Created                  pod/fio-sync-write-0                                         Container created
99m         Normal    Started                  pod/fio-sync-write-5                                         Container started
99m         Normal    Started                  pod/fio-sync-write-3                                         Container started
99m         Normal    AddedInterface           pod/fio-sync-write-7                                         Add eth0 [10.128.0.186/23] from ovn-kubernetes
99m         Normal    Pulled                   pod/fio-sync-write-7                                         Container image "rafmoshe2500/fio:3.41" already present on machine and can be accessed by the pod
99m         Normal    Created                  pod/fio-sync-write-7                                         Container created
99m         Normal    Pulled                   pod/fio-sync-write-0                                         Container image "rafmoshe2500/fio:3.41" already present on machine and can be accessed by the pod
99m         Normal    Pulled                   pod/fio-sync-write-3                                         Container image "rafmoshe2500/fio:3.41" already present on machine and can be accessed by the pod
99m         Normal    AddedInterface           pod/fio-sync-write-2                                         Add eth0 [10.130.0.95/23] from ovn-kubernetes
99m         Normal    Pulled                   pod/fio-sync-write-2                                         Container image "rafmoshe2500/fio:3.41" already present on machine and can be accessed by the pod
99m         Normal    Created                  pod/fio-sync-write-3                                         Container created
99m         Normal    AddedInterface           pod/fio-sync-write-8                                         Add eth0 [10.128.0.187/23] from ovn-kubernetes
99m         Normal    Pulled                   pod/fio-sync-write-8                                         Container image "rafmoshe2500/fio:3.41" already present on machine and can be accessed by the pod
99m         Normal    Created                  pod/fio-sync-write-8                                         Container created
99m         Normal    Started                  pod/fio-sync-write-8                                         Container started
99m         Normal    Started                  pod/fio-sync-write-2                                         Container started
99m         Normal    Created                  pod/fio-sync-write-2                                         Container created
99m         Normal    SuccessfulAttachVolume   pod/fio-sync-write-9                                         AttachVolume.Attach succeeded for volume "pvc-54b9ad5c-48c3-4106-8b58-3ad78ad8a319"
99m         Normal    Started                  pod/fio-sync-write-9                                         Container started
99m         Normal    AddedInterface           pod/fio-sync-write-9                                         Add eth0 [10.130.0.93/23] from ovn-kubernetes
99m         Normal    Pulled                   pod/fio-sync-write-9                                         Container image "rafmoshe2500/fio:3.41" already present on machine and can be accessed by the pod
99m         Normal    Created                  pod/fio-sync-write-9                                         Container created
99m         Normal    AddedInterface           pod/fio-sync-write-4                                         Add eth0 [10.130.0.96/23] from ovn-kubernetes
99m         Normal    Started                  pod/fio-sync-write-4                                         Container started
99m         Normal    Pulled                   pod/fio-sync-write-4                                         Container image "rafmoshe2500/fio:3.41" already present on machine and can be accessed by the pod
99m         Normal    Created                  pod/fio-sync-write-4                                         Container created
85m         Normal    Provisioning             persistentvolumeclaim/fio-smallfile-lifecycle-pvc-5          External provisioner is provisioning volume for claim "fio-tests/fio-smallfile-lifecycle-pvc-5"
85m         Normal    Provisioning             persistentvolumeclaim/fio-smallfile-lifecycle-pvc-6          External provisioner is provisioning volume for claim "fio-tests/fio-smallfile-lifecycle-pvc-6"
85m         Normal    Provisioning             persistentvolumeclaim/fio-smallfile-lifecycle-pvc-3          External provisioner is provisioning volume for claim "fio-tests/fio-smallfile-lifecycle-pvc-3"
85m         Normal    Provisioning             persistentvolumeclaim/fio-smallfile-lifecycle-pvc-1          External provisioner is provisioning volume for claim "fio-tests/fio-smallfile-lifecycle-pvc-1"
85m         Normal    Provisioning             persistentvolumeclaim/fio-smallfile-lifecycle-pvc-9          External provisioner is provisioning volume for claim "fio-tests/fio-smallfile-lifecycle-pvc-9"
85m         Normal    Provisioning             persistentvolumeclaim/fio-smallfile-lifecycle-pvc-2          External provisioner is provisioning volume for claim "fio-tests/fio-smallfile-lifecycle-pvc-2"
85m         Normal    Provisioning             persistentvolumeclaim/fio-smallfile-lifecycle-pvc-0          External provisioner is provisioning volume for claim "fio-tests/fio-smallfile-lifecycle-pvc-0"
85m         Normal    ExternalProvisioning     persistentvolumeclaim/fio-smallfile-lifecycle-pvc-3          Waiting for a volume to be created either by the external provisioner 'csi.trident.netapp.io' or manually by the system administrator. If volume creation is delayed, please verify that the provisioner is running and correctly registered.
85m         Normal    Provisioning             persistentvolumeclaim/fio-smallfile-lifecycle-pvc-7          External provisioner is provisioning volume for claim "fio-tests/fio-smallfile-lifecycle-pvc-7"
85m         Normal    Provisioning             persistentvolumeclaim/fio-smallfile-lifecycle-pvc-8          External provisioner is provisioning volume for claim "fio-tests/fio-smallfile-lifecycle-pvc-8"
85m         Normal    Provisioning             persistentvolumeclaim/fio-smallfile-lifecycle-pvc-4          External provisioner is provisioning volume for claim "fio-tests/fio-smallfile-lifecycle-pvc-4"
85m         Normal    ExternalProvisioning     persistentvolumeclaim/fio-smallfile-lifecycle-pvc-8          Waiting for a volume to be created either by the external provisioner 'csi.trident.netapp.io' or manually by the system administrator. If volume creation is delayed, please verify that the provisioner is running and correctly registered.
85m         Normal    ProvisioningSuccess      persistentvolumeclaim/fio-smallfile-lifecycle-pvc-3          provisioned a volume
85m         Normal    ProvisioningSucceeded    persistentvolumeclaim/fio-smallfile-lifecycle-pvc-3          Successfully provisioned volume pvc-655081cc-fc2d-4cd6-8075-cba4c17ed37b
85m         Normal    ProvisioningSucceeded    persistentvolumeclaim/fio-smallfile-lifecycle-pvc-8          Successfully provisioned volume pvc-0f2c76c6-b527-4d31-8820-cc043099cec0
85m         Normal    ProvisioningSuccess      persistentvolumeclaim/fio-smallfile-lifecycle-pvc-8          provisioned a volume
85m         Normal    ExternalProvisioning     persistentvolumeclaim/fio-smallfile-lifecycle-pvc-5          Waiting for a volume to be created either by the external provisioner 'csi.trident.netapp.io' or manually by the system administrator. If volume creation is delayed, please verify that the provisioner is running and correctly registered.
85m         Normal    ExternalProvisioning     persistentvolumeclaim/fio-smallfile-lifecycle-pvc-9          Waiting for a volume to be created either by the external provisioner 'csi.trident.netapp.io' or manually by the system administrator. If volume creation is delayed, please verify that the provisioner is running and correctly registered.
85m         Normal    ExternalProvisioning     persistentvolumeclaim/fio-smallfile-lifecycle-pvc-4          Waiting for a volume to be created either by the external provisioner 'csi.trident.netapp.io' or manually by the system administrator. If volume creation is delayed, please verify that the provisioner is running and correctly registered.
85m         Normal    ProvisioningSuccess      persistentvolumeclaim/fio-smallfile-lifecycle-pvc-9          provisioned a volume
85m         Normal    ProvisioningSucceeded    persistentvolumeclaim/fio-smallfile-lifecycle-pvc-9          Successfully provisioned volume pvc-600ff259-9d00-4607-81eb-2325a268f76f
84m         Normal    ProvisioningSucceeded    persistentvolumeclaim/fio-smallfile-lifecycle-pvc-4          Successfully provisioned volume pvc-5f303ecf-3d4f-4df9-b50c-f7dac8b3f413
84m         Normal    ProvisioningSuccess      persistentvolumeclaim/fio-smallfile-lifecycle-pvc-4          provisioned a volume
84m         Normal    ProvisioningSuccess      persistentvolumeclaim/fio-smallfile-lifecycle-pvc-5          provisioned a volume
84m         Normal    ProvisioningSucceeded    persistentvolumeclaim/fio-smallfile-lifecycle-pvc-5          Successfully provisioned volume pvc-bb6b15e5-907b-4d27-bd35-e97834a0b5ea
84m         Normal    ExternalProvisioning     persistentvolumeclaim/fio-smallfile-lifecycle-pvc-2          Waiting for a volume to be created either by the external provisioner 'csi.trident.netapp.io' or manually by the system administrator. If volume creation is delayed, please verify that the provisioner is running and correctly registered.
84m         Normal    ExternalProvisioning     persistentvolumeclaim/fio-smallfile-lifecycle-pvc-0          Waiting for a volume to be created either by the external provisioner 'csi.trident.netapp.io' or manually by the system administrator. If volume creation is delayed, please verify that the provisioner is running and correctly registered.
84m         Normal    ProvisioningSuccess      persistentvolumeclaim/fio-smallfile-lifecycle-pvc-0          provisioned a volume
84m         Normal    ProvisioningSucceeded    persistentvolumeclaim/fio-smallfile-lifecycle-pvc-0          Successfully provisioned volume pvc-fb1d96da-3669-4cc8-a689-da8f25857312
84m         Normal    ProvisioningSuccess      persistentvolumeclaim/fio-smallfile-lifecycle-pvc-2          provisioned a volume
84m         Normal    ProvisioningSucceeded    persistentvolumeclaim/fio-smallfile-lifecycle-pvc-2          Successfully provisioned volume pvc-410f068c-3a2e-49e4-8903-bb2f68a16087
84m         Normal    ExternalProvisioning     persistentvolumeclaim/fio-smallfile-lifecycle-pvc-7          Waiting for a volume to be created either by the external provisioner 'csi.trident.netapp.io' or manually by the system administrator. If volume creation is delayed, please verify that the provisioner is running and correctly registered.
84m         Normal    ExternalProvisioning     persistentvolumeclaim/fio-smallfile-lifecycle-pvc-6          Waiting for a volume to be created either by the external provisioner 'csi.trident.netapp.io' or manually by the system administrator. If volume creation is delayed, please verify that the provisioner is running and correctly registered.
84m         Normal    ProvisioningSucceeded    persistentvolumeclaim/fio-smallfile-lifecycle-pvc-6          Successfully provisioned volume pvc-deb228cb-82f5-4829-9945-3e62f4a9dead
84m         Normal    ProvisioningSuccess      persistentvolumeclaim/fio-smallfile-lifecycle-pvc-6          provisioned a volume
84m         Normal    SuccessfulAttachVolume   pod/fio-smallfile-lifecycle-3                                AttachVolume.Attach succeeded for volume "pvc-655081cc-fc2d-4cd6-8075-cba4c17ed37b"
84m         Normal    ProvisioningSucceeded    persistentvolumeclaim/fio-smallfile-lifecycle-pvc-7          Successfully provisioned volume pvc-cbd2af23-0467-4c01-a059-a18e9c850055
84m         Normal    ProvisioningSuccess      persistentvolumeclaim/fio-smallfile-lifecycle-pvc-7          provisioned a volume
84m         Normal    Created                  pod/fio-smallfile-lifecycle-3                                Container created
84m         Normal    Started                  pod/fio-smallfile-lifecycle-3                                Container started
84m         Normal    SuccessfulAttachVolume   pod/fio-smallfile-lifecycle-8                                AttachVolume.Attach succeeded for volume "pvc-0f2c76c6-b527-4d31-8820-cc043099cec0"
84m         Normal    Pulled                   pod/fio-smallfile-lifecycle-3                                Container image "rafmoshe2500/fio:3.41" already present on machine and can be accessed by the pod
84m         Normal    AddedInterface           pod/fio-smallfile-lifecycle-3                                Add eth0 [10.130.0.98/23] from ovn-kubernetes
84m         Normal    AddedInterface           pod/fio-smallfile-lifecycle-8                                Add eth0 [10.129.0.218/23] from ovn-kubernetes
84m         Normal    Created                  pod/fio-smallfile-lifecycle-8                                Container created
84m         Normal    Started                  pod/fio-smallfile-lifecycle-8                                Container started
84m         Normal    Pulled                   pod/fio-smallfile-lifecycle-8                                Container image "rafmoshe2500/fio:3.41" already present on machine and can be accessed by the pod
84m         Normal    ExternalProvisioning     persistentvolumeclaim/fio-smallfile-lifecycle-pvc-1          Waiting for a volume to be created either by the external provisioner 'csi.trident.netapp.io' or manually by the system administrator. If volume creation is delayed, please verify that the provisioner is running and correctly registered.
84m         Normal    SuccessfulAttachVolume   pod/fio-smallfile-lifecycle-5                                AttachVolume.Attach succeeded for volume "pvc-bb6b15e5-907b-4d27-bd35-e97834a0b5ea"
84m         Normal    SuccessfulAttachVolume   pod/fio-smallfile-lifecycle-0                                AttachVolume.Attach succeeded for volume "pvc-fb1d96da-3669-4cc8-a689-da8f25857312"
84m         Normal    SuccessfulAttachVolume   pod/fio-smallfile-lifecycle-1                                AttachVolume.Attach succeeded for volume "pvc-e9e4cf6c-173b-46c0-8cbb-9cbc27ffaa14"
84m         Normal    ProvisioningSucceeded    persistentvolumeclaim/fio-smallfile-lifecycle-pvc-1          Successfully provisioned volume pvc-e9e4cf6c-173b-46c0-8cbb-9cbc27ffaa14
84m         Normal    ProvisioningSuccess      persistentvolumeclaim/fio-smallfile-lifecycle-pvc-1          provisioned a volume
84m         Normal    SuccessfulAttachVolume   pod/fio-smallfile-lifecycle-4                                AttachVolume.Attach succeeded for volume "pvc-5f303ecf-3d4f-4df9-b50c-f7dac8b3f413"
84m         Normal    Pulled                   pod/fio-smallfile-lifecycle-4                                Container image "rafmoshe2500/fio:3.41" already present on machine and can be accessed by the pod
84m         Normal    Started                  pod/fio-smallfile-lifecycle-0                                Container started
84m         Normal    Created                  pod/fio-smallfile-lifecycle-0                                Container created
84m         Normal    AddedInterface           pod/fio-smallfile-lifecycle-4                                Add eth0 [10.130.0.99/23] from ovn-kubernetes
84m         Normal    Pulled                   pod/fio-smallfile-lifecycle-0                                Container image "rafmoshe2500/fio:3.41" already present on machine and can be accessed by the pod
84m         Normal    AddedInterface           pod/fio-smallfile-lifecycle-5                                Add eth0 [10.128.0.189/23] from ovn-kubernetes
84m         Normal    AddedInterface           pod/fio-smallfile-lifecycle-0                                Add eth0 [10.129.0.219/23] from ovn-kubernetes
84m         Normal    SuccessfulAttachVolume   pod/fio-smallfile-lifecycle-7                                AttachVolume.Attach succeeded for volume "pvc-cbd2af23-0467-4c01-a059-a18e9c850055"
84m         Normal    AddedInterface           pod/fio-smallfile-lifecycle-6                                Add eth0 [10.129.0.220/23] from ovn-kubernetes
84m         Normal    SuccessfulAttachVolume   pod/fio-smallfile-lifecycle-6                                AttachVolume.Attach succeeded for volume "pvc-deb228cb-82f5-4829-9945-3e62f4a9dead"
84m         Normal    AddedInterface           pod/fio-smallfile-lifecycle-7                                Add eth0 [10.128.0.190/23] from ovn-kubernetes
84m         Normal    Pulled                   pod/fio-smallfile-lifecycle-7                                Container image "rafmoshe2500/fio:3.41" already present on machine and can be accessed by the pod
84m         Normal    Started                  pod/fio-smallfile-lifecycle-5                                Container started
84m         Normal    SuccessfulAttachVolume   pod/fio-smallfile-lifecycle-9                                AttachVolume.Attach succeeded for volume "pvc-600ff259-9d00-4607-81eb-2325a268f76f"
84m         Normal    SuccessfulAttachVolume   pod/fio-smallfile-lifecycle-2                                AttachVolume.Attach succeeded for volume "pvc-410f068c-3a2e-49e4-8903-bb2f68a16087"
84m         Normal    Pulled                   pod/fio-smallfile-lifecycle-9                                Container image "rafmoshe2500/fio:3.41" already present on machine and can be accessed by the pod
84m         Normal    AddedInterface           pod/fio-smallfile-lifecycle-9                                Add eth0 [10.128.0.188/23] from ovn-kubernetes
84m         Normal    Pulled                   pod/fio-smallfile-lifecycle-5                                Container image "rafmoshe2500/fio:3.41" already present on machine and can be accessed by the pod
84m         Normal    AddedInterface           pod/fio-smallfile-lifecycle-2                                Add eth0 [10.130.0.100/23] from ovn-kubernetes
84m         Normal    Created                  pod/fio-smallfile-lifecycle-5                                Container created
84m         Normal    Started                  pod/fio-smallfile-lifecycle-6                                Container started
84m         Normal    Created                  pod/fio-smallfile-lifecycle-9                                Container created
84m         Normal    Created                  pod/fio-smallfile-lifecycle-7                                Container created
84m         Normal    Created                  pod/fio-smallfile-lifecycle-2                                Container created
84m         Normal    Pulled                   pod/fio-smallfile-lifecycle-2                                Container image "rafmoshe2500/fio:3.41" already present on machine and can be accessed by the pod
84m         Normal    Started                  pod/fio-smallfile-lifecycle-2                                Container started
84m         Normal    Started                  pod/fio-smallfile-lifecycle-9                                Container started
84m         Normal    Started                  pod/fio-smallfile-lifecycle-7                                Container started
84m         Normal    Created                  pod/fio-smallfile-lifecycle-4                                Container created
84m         Normal    Pulled                   pod/fio-smallfile-lifecycle-6                                Container image "rafmoshe2500/fio:3.41" already present on machine and can be accessed by the pod
84m         Normal    Started                  pod/fio-smallfile-lifecycle-1                                Container started
84m         Normal    Created                  pod/fio-smallfile-lifecycle-1                                Container created
84m         Normal    Pulled                   pod/fio-smallfile-lifecycle-1                                Container image "rafmoshe2500/fio:3.41" already present on machine and can be accessed by the pod
84m         Normal    Started                  pod/fio-smallfile-lifecycle-4                                Container started
84m         Normal    AddedInterface           pod/fio-smallfile-lifecycle-1                                Add eth0 [10.130.0.101/23] from ovn-kubernetes
84m         Normal    Created                  pod/fio-smallfile-lifecycle-6                                Container created
48m         Normal    Killing                  pod/fio-smallfile-lifecycle-8                                Stopping container fio
48m         Normal    Killing                  pod/fio-smallfile-lifecycle-6                                Stopping container fio
48m         Normal    Killing                  pod/fio-smallfile-lifecycle-3                                Stopping container fio
48m         Normal    Killing                  pod/fio-smallfile-lifecycle-4                                Stopping container fio
48m         Normal    Killing                  pod/fio-smallfile-lifecycle-1                                Stopping container fio
48m         Normal    Killing                  pod/fio-smallfile-lifecycle-0                                Stopping container fio
48m         Normal    Killing                  pod/fio-smallfile-lifecycle-9                                Stopping container fio
48m         Normal    Killing                  pod/fio-smallfile-lifecycle-7                                Stopping container fio
48m         Normal    Killing                  pod/fio-smallfile-lifecycle-5                                Stopping container fio
48m         Normal    Killing                  pod/fio-smallfile-lifecycle-2                                Stopping container fio
47m         Normal    Provisioning             persistentvolumeclaim/fio-test2-10pods-30k-5050-32kb-pvc-0   External provisioner is provisioning volume for claim "fio-tests/fio-test2-10pods-30k-5050-32kb-pvc-0"
47m         Normal    Provisioning             persistentvolumeclaim/fio-test2-10pods-30k-5050-32kb-pvc-1   External provisioner is provisioning volume for claim "fio-tests/fio-test2-10pods-30k-5050-32kb-pvc-1"
47m         Normal    Provisioning             persistentvolumeclaim/fio-test2-10pods-30k-5050-32kb-pvc-3   External provisioner is provisioning volume for claim "fio-tests/fio-test2-10pods-30k-5050-32kb-pvc-3"
47m         Normal    Provisioning             persistentvolumeclaim/fio-test2-10pods-30k-5050-32kb-pvc-2   External provisioner is provisioning volume for claim "fio-tests/fio-test2-10pods-30k-5050-32kb-pvc-2"
47m         Normal    Provisioning             persistentvolumeclaim/fio-test2-10pods-30k-5050-32kb-pvc-4   External provisioner is provisioning volume for claim "fio-tests/fio-test2-10pods-30k-5050-32kb-pvc-4"
47m         Normal    Provisioning             persistentvolumeclaim/fio-test2-10pods-30k-5050-32kb-pvc-8   External provisioner is provisioning volume for claim "fio-tests/fio-test2-10pods-30k-5050-32kb-pvc-8"
47m         Normal    Provisioning             persistentvolumeclaim/fio-test2-10pods-30k-5050-32kb-pvc-9   External provisioner is provisioning volume for claim "fio-tests/fio-test2-10pods-30k-5050-32kb-pvc-9"
47m         Normal    Provisioning             persistentvolumeclaim/fio-test2-10pods-30k-5050-32kb-pvc-6   External provisioner is provisioning volume for claim "fio-tests/fio-test2-10pods-30k-5050-32kb-pvc-6"
47m         Normal    Provisioning             persistentvolumeclaim/fio-test2-10pods-30k-5050-32kb-pvc-7   External provisioner is provisioning volume for claim "fio-tests/fio-test2-10pods-30k-5050-32kb-pvc-7"
47m         Normal    Provisioning             persistentvolumeclaim/fio-test2-10pods-30k-5050-32kb-pvc-5   External provisioner is provisioning volume for claim "fio-tests/fio-test2-10pods-30k-5050-32kb-pvc-5"
47m         Normal    ExternalProvisioning     persistentvolumeclaim/fio-test2-10pods-30k-5050-32kb-pvc-2   Waiting for a volume to be created either by the external provisioner 'csi.trident.netapp.io' or manually by the system administrator. If volume creation is delayed, please verify that the provisioner is running and correctly registered.
47m         Normal    ExternalProvisioning     persistentvolumeclaim/fio-test2-10pods-30k-5050-32kb-pvc-5   Waiting for a volume to be created either by the external provisioner 'csi.trident.netapp.io' or manually by the system administrator. If volume creation is delayed, please verify that the provisioner is running and correctly registered.
47m         Normal    ExternalProvisioning     persistentvolumeclaim/fio-test2-10pods-30k-5050-32kb-pvc-4   Waiting for a volume to be created either by the external provisioner 'csi.trident.netapp.io' or manually by the system administrator. If volume creation is delayed, please verify that the provisioner is running and correctly registered.
47m         Normal    ProvisioningSucceeded    persistentvolumeclaim/fio-test2-10pods-30k-5050-32kb-pvc-2   Successfully provisioned volume pvc-6239c5d5-054a-46fc-8d6b-2056f4d471d9
47m         Normal    ProvisioningSuccess      persistentvolumeclaim/fio-test2-10pods-30k-5050-32kb-pvc-2   provisioned a volume
46m         Normal    ProvisioningSucceeded    persistentvolumeclaim/fio-test2-10pods-30k-5050-32kb-pvc-4   Successfully provisioned volume pvc-48256d73-6d9a-4b73-9eb0-436a53638eb7
46m         Normal    ProvisioningSuccess      persistentvolumeclaim/fio-test2-10pods-30k-5050-32kb-pvc-4   provisioned a volume
46m         Normal    ProvisioningSucceeded    persistentvolumeclaim/fio-test2-10pods-30k-5050-32kb-pvc-5   Successfully provisioned volume pvc-11273b78-496e-44fb-ad61-8886b8561180
46m         Normal    ProvisioningSuccess      persistentvolumeclaim/fio-test2-10pods-30k-5050-32kb-pvc-5   provisioned a volume
46m         Normal    ExternalProvisioning     persistentvolumeclaim/fio-test2-10pods-30k-5050-32kb-pvc-8   Waiting for a volume to be created either by the external provisioner 'csi.trident.netapp.io' or manually by the system administrator. If volume creation is delayed, please verify that the provisioner is running and correctly registered.
46m         Normal    ExternalProvisioning     persistentvolumeclaim/fio-test2-10pods-30k-5050-32kb-pvc-0   Waiting for a volume to be created either by the external provisioner 'csi.trident.netapp.io' or manually by the system administrator. If volume creation is delayed, please verify that the provisioner is running and correctly registered.
46m         Normal    ProvisioningSucceeded    persistentvolumeclaim/fio-test2-10pods-30k-5050-32kb-pvc-8   Successfully provisioned volume pvc-54a0990d-b00d-4f5b-ba11-c8e10b1f7dfd
46m         Normal    ProvisioningSuccess      persistentvolumeclaim/fio-test2-10pods-30k-5050-32kb-pvc-8   provisioned a volume
46m         Normal    ProvisioningSucceeded    persistentvolumeclaim/fio-test2-10pods-30k-5050-32kb-pvc-0   Successfully provisioned volume pvc-226f1b0e-5340-4861-8edf-67711217238c
46m         Normal    ProvisioningSuccess      persistentvolumeclaim/fio-test2-10pods-30k-5050-32kb-pvc-0   provisioned a volume
46m         Normal    ExternalProvisioning     persistentvolumeclaim/fio-test2-10pods-30k-5050-32kb-pvc-6   Waiting for a volume to be created either by the external provisioner 'csi.trident.netapp.io' or manually by the system administrator. If volume creation is delayed, please verify that the provisioner is running and correctly registered.
46m         Normal    ExternalProvisioning     persistentvolumeclaim/fio-test2-10pods-30k-5050-32kb-pvc-7   Waiting for a volume to be created either by the external provisioner 'csi.trident.netapp.io' or manually by the system administrator. If volume creation is delayed, please verify that the provisioner is running and correctly registered.
46m         Normal    ExternalProvisioning     persistentvolumeclaim/fio-test2-10pods-30k-5050-32kb-pvc-3   Waiting for a volume to be created either by the external provisioner 'csi.trident.netapp.io' or manually by the system administrator. If volume creation is delayed, please verify that the provisioner is running and correctly registered.
46m         Normal    ProvisioningSucceeded    persistentvolumeclaim/fio-test2-10pods-30k-5050-32kb-pvc-3   Successfully provisioned volume pvc-36d17130-938b-4f11-a3a6-252c42ac0d75
46m         Normal    ProvisioningSuccess      persistentvolumeclaim/fio-test2-10pods-30k-5050-32kb-pvc-3   provisioned a volume
46m         Normal    ProvisioningSuccess      persistentvolumeclaim/fio-test2-10pods-30k-5050-32kb-pvc-6   provisioned a volume
46m         Normal    ProvisioningSucceeded    persistentvolumeclaim/fio-test2-10pods-30k-5050-32kb-pvc-6   Successfully provisioned volume pvc-59e45520-d059-48b9-b5e3-69c37a2f1645
46m         Normal    ProvisioningSucceeded    persistentvolumeclaim/fio-test2-10pods-30k-5050-32kb-pvc-7   Successfully provisioned volume pvc-6e72926d-4a54-4cdc-b4d6-f8c5b966418a
46m         Normal    ExternalProvisioning     persistentvolumeclaim/fio-test2-10pods-30k-5050-32kb-pvc-1   Waiting for a volume to be created either by the external provisioner 'csi.trident.netapp.io' or manually by the system administrator. If volume creation is delayed, please verify that the provisioner is running and correctly registered.
46m         Normal    ProvisioningSuccess      persistentvolumeclaim/fio-test2-10pods-30k-5050-32kb-pvc-7   provisioned a volume
46m         Normal    ExternalProvisioning     persistentvolumeclaim/fio-test2-10pods-30k-5050-32kb-pvc-9   Waiting for a volume to be created either by the external provisioner 'csi.trident.netapp.io' or manually by the system administrator. If volume creation is delayed, please verify that the provisioner is running and correctly registered.
46m         Normal    ProvisioningSuccess      persistentvolumeclaim/fio-test2-10pods-30k-5050-32kb-pvc-9   provisioned a volume
46m         Normal    ProvisioningSucceeded    persistentvolumeclaim/fio-test2-10pods-30k-5050-32kb-pvc-9   Successfully provisioned volume pvc-5a6486a3-7c80-4b66-ac5d-caf45fe883d3
46m         Normal    ProvisioningSucceeded    persistentvolumeclaim/fio-test2-10pods-30k-5050-32kb-pvc-1   Successfully provisioned volume pvc-5e8d7886-eb4b-4f99-b396-b57a9ff0d377
46m         Normal    ProvisioningSuccess      persistentvolumeclaim/fio-test2-10pods-30k-5050-32kb-pvc-1   provisioned a volume
46m         Normal    SuccessfulAttachVolume   pod/fio-test2-10pods-30k-5050-32kb-6                         AttachVolume.Attach succeeded for volume "pvc-59e45520-d059-48b9-b5e3-69c37a2f1645"
46m         Normal    SuccessfulAttachVolume   pod/fio-test2-10pods-30k-5050-32kb-8                         AttachVolume.Attach succeeded for volume "pvc-54a0990d-b00d-4f5b-ba11-c8e10b1f7dfd"
46m         Normal    SuccessfulAttachVolume   pod/fio-test2-10pods-30k-5050-32kb-3                         AttachVolume.Attach succeeded for volume "pvc-36d17130-938b-4f11-a3a6-252c42ac0d75"
46m         Normal    SuccessfulAttachVolume   pod/fio-test2-10pods-30k-5050-32kb-2                         AttachVolume.Attach succeeded for volume "pvc-6239c5d5-054a-46fc-8d6b-2056f4d471d9"
46m         Normal    SuccessfulAttachVolume   pod/fio-test2-10pods-30k-5050-32kb-4                         AttachVolume.Attach succeeded for volume "pvc-48256d73-6d9a-4b73-9eb0-436a53638eb7"
46m         Normal    SuccessfulAttachVolume   pod/fio-test2-10pods-30k-5050-32kb-9                         AttachVolume.Attach succeeded for volume "pvc-5a6486a3-7c80-4b66-ac5d-caf45fe883d3"
46m         Normal    SuccessfulAttachVolume   pod/fio-test2-10pods-30k-5050-32kb-1                         AttachVolume.Attach succeeded for volume "pvc-5e8d7886-eb4b-4f99-b396-b57a9ff0d377"
46m         Normal    SuccessfulAttachVolume   pod/fio-test2-10pods-30k-5050-32kb-7                         AttachVolume.Attach succeeded for volume "pvc-6e72926d-4a54-4cdc-b4d6-f8c5b966418a"
46m         Normal    Started                  pod/fio-test2-10pods-30k-5050-32kb-3                         Container started
46m         Normal    Created                  pod/fio-test2-10pods-30k-5050-32kb-3                         Container created
46m         Normal    Pulled                   pod/fio-test2-10pods-30k-5050-32kb-8                         Container image "rafmoshe2500/fio:3.41" already present on machine and can be accessed by the pod
46m         Normal    Started                  pod/fio-test2-10pods-30k-5050-32kb-7                         Container started
46m         Normal    Created                  pod/fio-test2-10pods-30k-5050-32kb-7                         Container created
46m         Normal    Pulled                   pod/fio-test2-10pods-30k-5050-32kb-7                         Container image "rafmoshe2500/fio:3.41" already present on machine and can be accessed by the pod
46m         Normal    AddedInterface           pod/fio-test2-10pods-30k-5050-32kb-7                         Add eth0 [10.129.0.223/23] from ovn-kubernetes
46m         Normal    Created                  pod/fio-test2-10pods-30k-5050-32kb-8                         Container created
46m         Normal    Started                  pod/fio-test2-10pods-30k-5050-32kb-6                         Container started
46m         Normal    Created                  pod/fio-test2-10pods-30k-5050-32kb-6                         Container created
46m         Normal    Pulled                   pod/fio-test2-10pods-30k-5050-32kb-6                         Container image "rafmoshe2500/fio:3.41" already present on machine and can be accessed by the pod
46m         Normal    AddedInterface           pod/fio-test2-10pods-30k-5050-32kb-6                         Add eth0 [10.130.0.104/23] from ovn-kubernetes
46m         Normal    SuccessfulAttachVolume   pod/fio-test2-10pods-30k-5050-32kb-0                         AttachVolume.Attach succeeded for volume "pvc-226f1b0e-5340-4861-8edf-67711217238c"
46m         Normal    AddedInterface           pod/fio-test2-10pods-30k-5050-32kb-0                         Add eth0 [10.128.0.192/23] from ovn-kubernetes
46m         Normal    Started                  pod/fio-test2-10pods-30k-5050-32kb-0                         Container started
46m         Normal    Started                  pod/fio-test2-10pods-30k-5050-32kb-8                         Container started
46m         Normal    Created                  pod/fio-test2-10pods-30k-5050-32kb-2                         Container created
46m         Normal    Started                  pod/fio-test2-10pods-30k-5050-32kb-2                         Container started
46m         Normal    AddedInterface           pod/fio-test2-10pods-30k-5050-32kb-3                         Add eth0 [10.129.0.222/23] from ovn-kubernetes
46m         Normal    Pulled                   pod/fio-test2-10pods-30k-5050-32kb-3                         Container image "rafmoshe2500/fio:3.41" already present on machine and can be accessed by the pod
46m         Normal    AddedInterface           pod/fio-test2-10pods-30k-5050-32kb-2                         Add eth0 [10.130.0.102/23] from ovn-kubernetes
46m         Normal    Pulled                   pod/fio-test2-10pods-30k-5050-32kb-2                         Container image "rafmoshe2500/fio:3.41" already present on machine and can be accessed by the pod
46m         Normal    Pulled                   pod/fio-test2-10pods-30k-5050-32kb-0                         Container image "rafmoshe2500/fio:3.41" already present on machine and can be accessed by the pod
46m         Normal    Created                  pod/fio-test2-10pods-30k-5050-32kb-0                         Container created
46m         Normal    AddedInterface           pod/fio-test2-10pods-30k-5050-32kb-4                         Add eth0 [10.129.0.221/23] from ovn-kubernetes
46m         Normal    Pulled                   pod/fio-test2-10pods-30k-5050-32kb-4                         Container image "rafmoshe2500/fio:3.41" already present on machine and can be accessed by the pod
46m         Normal    Created                  pod/fio-test2-10pods-30k-5050-32kb-4                         Container created
46m         Normal    Started                  pod/fio-test2-10pods-30k-5050-32kb-4                         Container started
46m         Normal    AddedInterface           pod/fio-test2-10pods-30k-5050-32kb-8                         Add eth0 [10.130.0.103/23] from ovn-kubernetes
46m         Normal    SuccessfulAttachVolume   pod/fio-test2-10pods-30k-5050-32kb-5                         AttachVolume.Attach succeeded for volume "pvc-11273b78-496e-44fb-ad61-8886b8561180"
46m         Normal    AddedInterface           pod/fio-test2-10pods-30k-5050-32kb-5                         Add eth0 [10.128.0.191/23] from ovn-kubernetes
46m         Normal    Pulled                   pod/fio-test2-10pods-30k-5050-32kb-5                         Container image "rafmoshe2500/fio:3.41" already present on machine and can be accessed by the pod
46m         Normal    Started                  pod/fio-test2-10pods-30k-5050-32kb-5                         Container started
46m         Normal    Created                  pod/fio-test2-10pods-30k-5050-32kb-5                         Container created
46m         Normal    AddedInterface           pod/fio-test2-10pods-30k-5050-32kb-9                         Add eth0 [10.128.0.193/23] from ovn-kubernetes
46m         Normal    Created                  pod/fio-test2-10pods-30k-5050-32kb-9                         Container created
46m         Normal    Started                  pod/fio-test2-10pods-30k-5050-32kb-9                         Container started
46m         Normal    Pulled                   pod/fio-test2-10pods-30k-5050-32kb-9                         Container image "rafmoshe2500/fio:3.41" already present on machine and can be accessed by the pod
45m         Normal    Started                  pod/fio-test2-10pods-30k-5050-32kb-1                         Container started
45m         Normal    Created                  pod/fio-test2-10pods-30k-5050-32kb-1                         Container created
45m         Normal    AddedInterface           pod/fio-test2-10pods-30k-5050-32kb-1                         Add eth0 [10.130.0.105/23] from ovn-kubernetes
45m         Normal    Pulled                   pod/fio-test2-10pods-30k-5050-32kb-1                         Container image "rafmoshe2500/fio:3.41" already present on machine and can be accessed by the pod
31m         Normal    Provisioning             persistentvolumeclaim/fio-test4-10pods-50k-5050-32kb-pvc-8   External provisioner is provisioning volume for claim "fio-tests/fio-test4-10pods-50k-5050-32kb-pvc-8"
31m         Normal    Provisioning             persistentvolumeclaim/fio-test4-10pods-50k-5050-32kb-pvc-2   External provisioner is provisioning volume for claim "fio-tests/fio-test4-10pods-50k-5050-32kb-pvc-2"
31m         Normal    Provisioning             persistentvolumeclaim/fio-test4-10pods-50k-5050-32kb-pvc-9   External provisioner is provisioning volume for claim "fio-tests/fio-test4-10pods-50k-5050-32kb-pvc-9"
31m         Normal    Provisioning             persistentvolumeclaim/fio-test4-10pods-50k-5050-32kb-pvc-6   External provisioner is provisioning volume for claim "fio-tests/fio-test4-10pods-50k-5050-32kb-pvc-6"
31m         Normal    ExternalProvisioning     persistentvolumeclaim/fio-test4-10pods-50k-5050-32kb-pvc-8   Waiting for a volume to be created either by the external provisioner 'csi.trident.netapp.io' or manually by the system administrator. If volume creation is delayed, please verify that the provisioner is running and correctly registered.
31m         Normal    Provisioning             persistentvolumeclaim/fio-test4-10pods-50k-5050-32kb-pvc-1   External provisioner is provisioning volume for claim "fio-tests/fio-test4-10pods-50k-5050-32kb-pvc-1"
31m         Normal    Provisioning             persistentvolumeclaim/fio-test4-10pods-50k-5050-32kb-pvc-4   External provisioner is provisioning volume for claim "fio-tests/fio-test4-10pods-50k-5050-32kb-pvc-4"
31m         Normal    Provisioning             persistentvolumeclaim/fio-test4-10pods-50k-5050-32kb-pvc-0   External provisioner is provisioning volume for claim "fio-tests/fio-test4-10pods-50k-5050-32kb-pvc-0"
31m         Normal    Provisioning             persistentvolumeclaim/fio-test4-10pods-50k-5050-32kb-pvc-5   External provisioner is provisioning volume for claim "fio-tests/fio-test4-10pods-50k-5050-32kb-pvc-5"
31m         Normal    Provisioning             persistentvolumeclaim/fio-test4-10pods-50k-5050-32kb-pvc-7   External provisioner is provisioning volume for claim "fio-tests/fio-test4-10pods-50k-5050-32kb-pvc-7"
31m         Normal    Provisioning             persistentvolumeclaim/fio-test4-10pods-50k-5050-32kb-pvc-3   External provisioner is provisioning volume for claim "fio-tests/fio-test4-10pods-50k-5050-32kb-pvc-3"
31m         Normal    ProvisioningSuccess      persistentvolumeclaim/fio-test4-10pods-50k-5050-32kb-pvc-8   provisioned a volume
31m         Normal    ProvisioningSucceeded    persistentvolumeclaim/fio-test4-10pods-50k-5050-32kb-pvc-8   Successfully provisioned volume pvc-f70c4a28-d3ff-4286-884a-bf72abeec982
31m         Normal    ExternalProvisioning     persistentvolumeclaim/fio-test4-10pods-50k-5050-32kb-pvc-2   Waiting for a volume to be created either by the external provisioner 'csi.trident.netapp.io' or manually by the system administrator. If volume creation is delayed, please verify that the provisioner is running and correctly registered.
31m         Normal    ExternalProvisioning     persistentvolumeclaim/fio-test4-10pods-50k-5050-32kb-pvc-9   Waiting for a volume to be created either by the external provisioner 'csi.trident.netapp.io' or manually by the system administrator. If volume creation is delayed, please verify that the provisioner is running and correctly registered.
30m         Normal    ProvisioningSuccess      persistentvolumeclaim/fio-test4-10pods-50k-5050-32kb-pvc-2   provisioned a volume
30m         Normal    ProvisioningSucceeded    persistentvolumeclaim/fio-test4-10pods-50k-5050-32kb-pvc-2   Successfully provisioned volume pvc-932c2854-0724-4066-be8d-cb79f116fcfc
30m         Normal    ProvisioningSucceeded    persistentvolumeclaim/fio-test4-10pods-50k-5050-32kb-pvc-9   Successfully provisioned volume pvc-b9e7f6e0-cc3b-40b3-8e6c-553deb86eb00
30m         Normal    ProvisioningSuccess      persistentvolumeclaim/fio-test4-10pods-50k-5050-32kb-pvc-9   provisioned a volume
30m         Normal    ExternalProvisioning     persistentvolumeclaim/fio-test4-10pods-50k-5050-32kb-pvc-0   Waiting for a volume to be created either by the external provisioner 'csi.trident.netapp.io' or manually by the system administrator. If volume creation is delayed, please verify that the provisioner is running and correctly registered.
30m         Normal    ExternalProvisioning     persistentvolumeclaim/fio-test4-10pods-50k-5050-32kb-pvc-1   Waiting for a volume to be created either by the external provisioner 'csi.trident.netapp.io' or manually by the system administrator. If volume creation is delayed, please verify that the provisioner is running and correctly registered.
30m         Normal    ExternalProvisioning     persistentvolumeclaim/fio-test4-10pods-50k-5050-32kb-pvc-5   Waiting for a volume to be created either by the external provisioner 'csi.trident.netapp.io' or manually by the system administrator. If volume creation is delayed, please verify that the provisioner is running and correctly registered.
30m         Normal    ProvisioningSucceeded    persistentvolumeclaim/fio-test4-10pods-50k-5050-32kb-pvc-5   Successfully provisioned volume pvc-7909b77e-8df4-41b4-aff8-eb94226b9ab8
30m         Normal    ProvisioningSuccess      persistentvolumeclaim/fio-test4-10pods-50k-5050-32kb-pvc-5   provisioned a volume
30m         Normal    ProvisioningSuccess      persistentvolumeclaim/fio-test4-10pods-50k-5050-32kb-pvc-0   provisioned a volume
30m         Normal    ProvisioningSucceeded    persistentvolumeclaim/fio-test4-10pods-50k-5050-32kb-pvc-0   Successfully provisioned volume pvc-e3d5337d-fa31-4d28-ab8a-b29341d6aa8c
30m         Normal    ProvisioningSucceeded    persistentvolumeclaim/fio-test4-10pods-50k-5050-32kb-pvc-1   Successfully provisioned volume pvc-9e27e26b-662f-40fc-aefb-a16b71f57a1d
30m         Normal    ProvisioningSuccess      persistentvolumeclaim/fio-test4-10pods-50k-5050-32kb-pvc-1   provisioned a volume
30m         Normal    ExternalProvisioning     persistentvolumeclaim/fio-test4-10pods-50k-5050-32kb-pvc-4   Waiting for a volume to be created either by the external provisioner 'csi.trident.netapp.io' or manually by the system administrator. If volume creation is delayed, please verify that the provisioner is running and correctly registered.
30m         Normal    ExternalProvisioning     persistentvolumeclaim/fio-test4-10pods-50k-5050-32kb-pvc-6   Waiting for a volume to be created either by the external provisioner 'csi.trident.netapp.io' or manually by the system administrator. If volume creation is delayed, please verify that the provisioner is running and correctly registered.
30m         Normal    ProvisioningSuccess      persistentvolumeclaim/fio-test4-10pods-50k-5050-32kb-pvc-6   provisioned a volume
30m         Normal    ProvisioningSucceeded    persistentvolumeclaim/fio-test4-10pods-50k-5050-32kb-pvc-6   Successfully provisioned volume pvc-3a0bdadd-3364-4115-b24d-8407ccdc0400
30m         Normal    Created                  pod/fio-test4-10pods-50k-5050-32kb-8                         Container created
30m         Normal    Started                  pod/fio-test4-10pods-50k-5050-32kb-8                         Container started
30m         Normal    SuccessfulAttachVolume   pod/fio-test4-10pods-50k-5050-32kb-8                         AttachVolume.Attach succeeded for volume "pvc-f70c4a28-d3ff-4286-884a-bf72abeec982"
30m         Normal    AddedInterface           pod/fio-test4-10pods-50k-5050-32kb-8                         Add eth0 [10.130.0.106/23] from ovn-kubernetes
30m         Normal    Pulled                   pod/fio-test4-10pods-50k-5050-32kb-8                         Container image "rafmoshe2500/fio:3.41" already present on machine and can be accessed by the pod
30m         Normal    ProvisioningSuccess      persistentvolumeclaim/fio-test4-10pods-50k-5050-32kb-pvc-4   provisioned a volume
30m         Normal    ProvisioningSucceeded    persistentvolumeclaim/fio-test4-10pods-50k-5050-32kb-pvc-4   Successfully provisioned volume pvc-430e1639-47c6-435a-b834-f23603b6bb18
30m         Normal    SuccessfulAttachVolume   pod/fio-test4-10pods-50k-5050-32kb-2                         AttachVolume.Attach succeeded for volume "pvc-932c2854-0724-4066-be8d-cb79f116fcfc"
30m         Normal    Pulled                   pod/fio-test4-10pods-50k-5050-32kb-2                         Container image "rafmoshe2500/fio:3.41" already present on machine and can be accessed by the pod
30m         Normal    AddedInterface           pod/fio-test4-10pods-50k-5050-32kb-2                         Add eth0 [10.129.0.224/23] from ovn-kubernetes
30m         Normal    Created                  pod/fio-test4-10pods-50k-5050-32kb-2                         Container created
30m         Normal    Started                  pod/fio-test4-10pods-50k-5050-32kb-2                         Container started
30m         Normal    ExternalProvisioning     persistentvolumeclaim/fio-test4-10pods-50k-5050-32kb-pvc-7   Waiting for a volume to be created either by the external provisioner 'csi.trident.netapp.io' or manually by the system administrator. If volume creation is delayed, please verify that the provisioner is running and correctly registered.
30m         Normal    ExternalProvisioning     persistentvolumeclaim/fio-test4-10pods-50k-5050-32kb-pvc-3   Waiting for a volume to be created either by the external provisioner 'csi.trident.netapp.io' or manually by the system administrator. If volume creation is delayed, please verify that the provisioner is running and correctly registered.
30m         Normal    ProvisioningSucceeded    persistentvolumeclaim/fio-test4-10pods-50k-5050-32kb-pvc-3   Successfully provisioned volume pvc-98d1ce8f-9118-4ff7-a2e3-4ba9e8bfbd3c
30m         Normal    ProvisioningSuccess      persistentvolumeclaim/fio-test4-10pods-50k-5050-32kb-pvc-3   provisioned a volume
30m         Normal    SuccessfulAttachVolume   pod/fio-test4-10pods-50k-5050-32kb-5                         AttachVolume.Attach succeeded for volume "pvc-7909b77e-8df4-41b4-aff8-eb94226b9ab8"
30m         Normal    SuccessfulAttachVolume   pod/fio-test4-10pods-50k-5050-32kb-0                         AttachVolume.Attach succeeded for volume "pvc-e3d5337d-fa31-4d28-ab8a-b29341d6aa8c"
30m         Normal    SuccessfulAttachVolume   pod/fio-test4-10pods-50k-5050-32kb-1                         AttachVolume.Attach succeeded for volume "pvc-9e27e26b-662f-40fc-aefb-a16b71f57a1d"
30m         Normal    Started                  pod/fio-test4-10pods-50k-5050-32kb-0                         Container started
30m         Normal    Pulled                   pod/fio-test4-10pods-50k-5050-32kb-9                         Container image "rafmoshe2500/fio:3.41" already present on machine and can be accessed by the pod
30m         Normal    SuccessfulAttachVolume   pod/fio-test4-10pods-50k-5050-32kb-9                         AttachVolume.Attach succeeded for volume "pvc-b9e7f6e0-cc3b-40b3-8e6c-553deb86eb00"
30m         Normal    AddedInterface           pod/fio-test4-10pods-50k-5050-32kb-9                         Add eth0 [10.128.0.194/23] from ovn-kubernetes
30m         Normal    Started                  pod/fio-test4-10pods-50k-5050-32kb-5                         Container started
30m         Normal    Created                  pod/fio-test4-10pods-50k-5050-32kb-5                         Container created
30m         Normal    Pulled                   pod/fio-test4-10pods-50k-5050-32kb-5                         Container image "rafmoshe2500/fio:3.41" already present on machine and can be accessed by the pod
30m         Normal    AddedInterface           pod/fio-test4-10pods-50k-5050-32kb-5                         Add eth0 [10.130.0.107/23] from ovn-kubernetes
30m         Normal    AddedInterface           pod/fio-test4-10pods-50k-5050-32kb-0                         Add eth0 [10.129.0.225/23] from ovn-kubernetes
30m         Normal    Started                  pod/fio-test4-10pods-50k-5050-32kb-1                         Container started
30m         Normal    Pulled                   pod/fio-test4-10pods-50k-5050-32kb-0                         Container image "rafmoshe2500/fio:3.41" already present on machine and can be accessed by the pod
30m         Normal    Created                  pod/fio-test4-10pods-50k-5050-32kb-0                         Container created
30m         Normal    Created                  pod/fio-test4-10pods-50k-5050-32kb-9                         Container created
30m         Normal    AddedInterface           pod/fio-test4-10pods-50k-5050-32kb-1                         Add eth0 [10.128.0.195/23] from ovn-kubernetes
30m         Normal    Pulled                   pod/fio-test4-10pods-50k-5050-32kb-1                         Container image "rafmoshe2500/fio:3.41" already present on machine and can be accessed by the pod
30m         Normal    Created                  pod/fio-test4-10pods-50k-5050-32kb-1                         Container created
30m         Normal    Started                  pod/fio-test4-10pods-50k-5050-32kb-9                         Container started
30m         Normal    ProvisioningSucceeded    persistentvolumeclaim/fio-test4-10pods-50k-5050-32kb-pvc-7   Successfully provisioned volume pvc-9088e2e0-f53b-41dc-87cd-634102c9860b
30m         Normal    ProvisioningSuccess      persistentvolumeclaim/fio-test4-10pods-50k-5050-32kb-pvc-7   provisioned a volume
30m         Normal    Started                  pod/fio-test4-10pods-50k-5050-32kb-3                         Container started
30m         Normal    Created                  pod/fio-test4-10pods-50k-5050-32kb-3                         Container created
30m         Normal    Pulled                   pod/fio-test4-10pods-50k-5050-32kb-3                         Container image "rafmoshe2500/fio:3.41" already present on machine and can be accessed by the pod
30m         Normal    AddedInterface           pod/fio-test4-10pods-50k-5050-32kb-3                         Add eth0 [10.128.0.196/23] from ovn-kubernetes
30m         Normal    SuccessfulAttachVolume   pod/fio-test4-10pods-50k-5050-32kb-3                         AttachVolume.Attach succeeded for volume "pvc-98d1ce8f-9118-4ff7-a2e3-4ba9e8bfbd3c"
30m         Normal    SuccessfulAttachVolume   pod/fio-test4-10pods-50k-5050-32kb-4                         AttachVolume.Attach succeeded for volume "pvc-430e1639-47c6-435a-b834-f23603b6bb18"
30m         Normal    SuccessfulAttachVolume   pod/fio-test4-10pods-50k-5050-32kb-7                         AttachVolume.Attach succeeded for volume "pvc-9088e2e0-f53b-41dc-87cd-634102c9860b"
30m         Normal    SuccessfulAttachVolume   pod/fio-test4-10pods-50k-5050-32kb-6                         AttachVolume.Attach succeeded for volume "pvc-3a0bdadd-3364-4115-b24d-8407ccdc0400"
30m         Normal    Started                  pod/fio-test4-10pods-50k-5050-32kb-4                         Container started
30m         Normal    Pulled                   pod/fio-test4-10pods-50k-5050-32kb-6                         Container image "rafmoshe2500/fio:3.41" already present on machine and can be accessed by the pod
30m         Normal    AddedInterface           pod/fio-test4-10pods-50k-5050-32kb-4                         Add eth0 [10.129.0.226/23] from ovn-kubernetes
30m         Normal    Pulled                   pod/fio-test4-10pods-50k-5050-32kb-4                         Container image "rafmoshe2500/fio:3.41" already present on machine and can be accessed by the pod
30m         Normal    Created                  pod/fio-test4-10pods-50k-5050-32kb-4                         Container created
30m         Normal    AddedInterface           pod/fio-test4-10pods-50k-5050-32kb-6                         Add eth0 [10.130.0.108/23] from ovn-kubernetes
30m         Normal    Created                  pod/fio-test4-10pods-50k-5050-32kb-6                         Container created
30m         Normal    Started                  pod/fio-test4-10pods-50k-5050-32kb-6                         Container started
29m         Normal    AddedInterface           pod/fio-test4-10pods-50k-5050-32kb-7                         Add eth0 [10.130.0.109/23] from ovn-kubernetes
29m         Normal    Pulled                   pod/fio-test4-10pods-50k-5050-32kb-7                         Container image "rafmoshe2500/fio:3.41" already present on machine and can be accessed by the pod
29m         Normal    Started                  pod/fio-test4-10pods-50k-5050-32kb-7                         Container started
29m         Normal    Created                  pod/fio-test4-10pods-50k-5050-32kb-7                         Container created
14m         Normal    Provisioning             persistentvolumeclaim/fio-test7-1pod-max-write-4kb-pvc-0     External provisioner is provisioning volume for claim "fio-tests/fio-test7-1pod-max-write-4kb-pvc-0"
14m         Normal    ExternalProvisioning     persistentvolumeclaim/fio-test7-1pod-max-write-4kb-pvc-0     Waiting for a volume to be created either by the external provisioner 'csi.trident.netapp.io' or manually by the system administrator. If volume creation is delayed, please verify that the provisioner is running and correctly registered.
14m         Normal    ProvisioningSuccess      persistentvolumeclaim/fio-test7-1pod-max-write-4kb-pvc-0     provisioned a volume
14m         Normal    ProvisioningSucceeded    persistentvolumeclaim/fio-test7-1pod-max-write-4kb-pvc-0     Successfully provisioned volume pvc-80d36184-d8e4-430b-812a-3633abea8817
14m         Normal    SuccessfulAttachVolume   pod/fio-test7-1pod-max-write-4kb-0                           AttachVolume.Attach succeeded for volume "pvc-80d36184-d8e4-430b-812a-3633abea8817"
13m         Normal    AddedInterface           pod/fio-test7-1pod-max-write-4kb-0                           Add eth0 [10.130.0.110/23] from ovn-kubernetes
13m         Normal    Pulled                   pod/fio-test7-1pod-max-write-4kb-0                           Container image "rafmoshe2500/fio:3.41" already present on machine and can be accessed by the pod
13m         Normal    Created                  pod/fio-test7-1pod-max-write-4kb-0                           Container created
13m         Normal    Started                  pod/fio-test7-1pod-max-write-4kb-0                           Container started
